Workbook

Sheet ยอดขายปีที่แล้ว
A1: ยอดขายรายคลัง|สาขา 1/1/2568 - 31/1/2568
A2: # | B2: คลัง|สาขา | C2: จำนวนรายการ | D2: ยอดขาย(บาท) | E2: ยอดขาย(%)
A3: 1 | B3: คลังสินค้า Yuedpao Online | C3: 94517 | D3: 34973870 | E3: 33.28%
A4: 2 | B4: Yuedpao สาขา Central เวสต์เกต | C4: 4515 | D4: 2340834 | E4: 2.23%
A5: 3 | B5: Yuedpao สาขา Central พัทยา | C5: 4034 | D5: 2137785.5 | E5: 2.03%
A6: 4 | B6: Yuedpao สาขา Future Park Rangsit ชั้น 3 | C6: 4452 | D6: 1933578.5 | E6: 1.84%
A7: 5 | B7: Yuedpao สาขา Central ลาดพร้าว | C7: 3900 | D7: 1928388.5 | E7: 1.83%
A8: 6 | B8: Yuedpao สาขา Future Park Rangsit (Flagship store) | C8: 3699 | D8: 1915738 | E8: 1.82%
A9: 7 | B9: Yuedpao สาขา Fashion Island | C9: 3730 | D9: 1859514 | E9: 1.77%
A10: 8 | B10: Yuedpao สาขา Central ขอนแก่น | C10: 3682 | D10: 1608958 | E10: 1.53%
A11: 9 | B11: Yuedpao สาขา Central หาดใหญ่ | C11: 3464 | D11: 1564677 | E11: 1.49%
A12: 10 | B12: Yuedpao สาขา Robinson บ่อวิน | C12: 3409 | D12: 1542797 | E12: 1.47%
A13: 11 | B13: Yuedpao สาขา Central อุบลราชธานี | C13: 3099 | D13: 1487646.7 | E13: 1.42%
A14: 12 | B14: Yuedpao สาขา Central สุราษฎร์ธานี | C14: 3187 | D14: 1417349.5 | E14: 1.35%
... A85: 83 | B85: คลังสินค้ารับคืน Yuedpao Online | C85: -1084 | D85: -378239.62 | E85: -0.36%
B87: Exported by | C87: janjoncj@gmail.com
B88: Date Time | C88: 2/2/2026 13:57+07:00

Sheet ยอดขายเดือนที่เแล้ว
A1: ยอดขายรายคลัง|สาขา 1/12/2568 - 31/12/2568
A2: # | B2: คลัง|สาขา | C2: จำนวนรายการ | D2: ยอดขาย(บาท) | E2: ยอดขาย(%)
A3: 1 | B3: คลังสินค้า Yuedpao Online | C3: 207728 | D3: 70453462 | E3: 38.69%
A4: 2 | B4: Yuedpao สาขา Central หาดใหญ่ | C4: 9742 | D4: 3891251.5 | E4: 2.14%
A5: 3 | B5: Yuedpao สาขา Central เวสต์เกต | C5: 5959 | D5: 3114555 | E5: 1.71%
A6: 4 | B6: Yuedpao สาขา Future Park Rangsit (Flagship store) | C6: 5547 | D6: 2831377 | E6: 1.55%
A7: 5 | B7: Yuedpao สาขา Fashion Island | C7: 5336 | D7: 2819691.5 | E7: 1.55%
A8: 6 | B8: Yuedpao สาขา Central ปิ่นเกล้า | C8: 5117 | D8: 2386873.4 | E8: 1.31%
A9: 7 | B9: Yuedpao สาขา Central ลาดพร้าว | C9: 4592 | D9: 2359471 | E9: 1.3%
A10: 8 | B10: Yuedpao สาขา Future Park Rangsit ชั้น 3 | C10: 4452 | D10: 2268063.5 | E10: 1.25%
A11: 9 | B11: Yuedpao สาขา Robinson บ่อวิน | C11: 4756 | D11: 2256219 | E11: 1.24%
A12: 10 | B12: Yuedpao สาขา Central กระบี่ | C12: 4650 | D12: 2149267.3 | E12: 1.18%
A13: 11 | B13: Yuedpao สาขา The Mall บางกะปิ | C13: 4253 | D13: 2082965 | E13: 1.14%
A14: 12 | B14: Yuedpao สาขา Central อุบลราชธานี | C14: 4261 | D14: 2062091.3 | E14: 1.13%
... A113: 111 | B113: คลังสินค้ารับคืน Yuedpao Online | C113: -5747 | D113: -1715382.2 | E113: -0.94%
B115: Exported by | C115: janjoncj@gmail.com
B116: Date Time | C116: 2/2/2026 14:12+07:00

Sheet ยอดขายปัจจุบัน
A1: ยอดขายรายคลัง|สาขา 1/1/2569 - 31/1/2569
A2: # | B2: คลัง|สาขา | C2: จำนวนรายการ | D2: ยอดขาย(บาท) | E2: ยอดขาย(%)
A3: 1 | B3: คลังสินค้า Yuedpao Online | C3: 188503 | D3: 63725463 | E3: 42.53% | H3: In Vat | I3: Ex Vat
A4: 2 | B4: Yuedpao สาขา Central หาดใหญ่ | C4: 7663 | D4: 2719550.5 | E4: 1.82% | F4: Yuedpao สาขา Central ระยอง | G4: {=_xlfn.XLOOKUP(F4,B:B,C:D,0,0)} -> 2400 | H4: 1198422 | I4: =H4*100/107 -> 1120020.6
A5: 3 | B5: Yuedpao สาขา Future Park Rangsit (Flagship store) | C5: 4325 | D5: 2162196 | E5: 1.44% | F5: Yuedpao สาขา Mega บางนา | G5: {=_xlfn.XLOOKUP(F5,B:B,C:D,0,0)} -> 1779 | H5: 1027144 | I5: =H5*100/107 -> 959947.66
A6: 4 | B6: Yuedpao สาขา Future Park Rangsit ชั้น 3 | C6: 4199 | D6: 2122760 | E6: 1.42% | F6: Yuedpao สาขา MAYA เชียงใหม่ | G6: {=_xlfn.XLOOKUP(F6,B:B,C:D,0,0)} -> 3837 | H6: 1474698 | I6: =H6*100/107 -> 1378222.4
A7: 5 | B7: Yuedpao สาขา Central ลาดพร้าว | C7: 4026 | D7: 2076830.5 | E7: 1.39% | F7: Yuedpao สาขา The Mall โคราช | G7: {=_xlfn.XLOOKUP(F7,B:B,C:D,0,0)} -> 1822 | H7: 872878 | I7: =H7*100/107 -> 815773.83
A8: 6 | B8: Yuedpao สาขา Central เวสต์เกต | C8: 4036 | D8: 2064026 | E8: 1.38% | F8: Yuedpao สาขา SIAM SQUARE | G8: {=_xlfn.XLOOKUP(F8,B:B,C:D,0,0)} -> 1716 | H8: 945055.2 | I8: =H8*100/107 -> 883229.16
A9: 7 | B9: Yuedpao สาขา Central กระบี่ | C9: 3948 | D9: 1911703.5 | E9: 1.28% | F9: Yuedpao สาขา Robinson บุรีรัมย์ | G9: {=_xlfn.XLOOKUP(F9,B:B,C:D,0,0)} -> 1257 | H9: 629096 | I9: =H9*100/107 -> 587940.19
A10: 8 | B10: Yuedpao สาขา Fashion Island | C10: 3704 | D10: 1883097.5 | E10: 1.26% | F10: Yuedpao สาขา Central โคราช | G10: {=_xlfn.XLOOKUP(F10,B:B,C:D,0,0)} -> 1273 | H10: 620565 | I10: =H10*100/107 -> 579967.29
A11: 9 | B11: Yuedpao สาขา Central อุบลราชธานี | C11: 3517 | D11: 1740017.5 | E11: 1.16% | G11: {=_xlfn.XLOOKUP(F11,B:B,C:D,0,0)} -> 0 | H11: 0 | I11: =H11*100/107 -> 0
A12: 10 | B12: Yuedpao สาขา Central ปิ่นเกล้า | C12: 3590 | D12: 1658515.5 | E12: 1.11% | F12: Yuedpao สาขา Robinson ชลบุรี | G12: {=_xlfn.XLOOKUP(F12,B:B,C:D,0,0)} -> 2002 | H12: 907039 | I12: =H12*100/107 -> 847700
A13: 11 | B13: Yuedpao สาขา Central สุราษฎร์ธานี | C13: 3420 | D13: 1657555 | E13: 1.11% | F13: Yuedpao สาขา Central พัทยา | G13: {=_xlfn.XLOOKUP(F13,B:B,C:D,0,0)} -> 1489 | H13: 836250 | I13: =H13*100/107 -> 781542.06
A14: 12 | B14: Yuedpao สาขา The Mall บางแค | C14: 3186 | D14: 1587012.4 | E14: 1.06% | F14: Yuedpao สาขา Robinson แม่สอด | G14: {=_xlfn.XLOOKUP(F14,B:B,C:D,0,0)} -> 1396 | H14: 734037.5 | I14: =H14*100/107 -> 686016.36
A15: 13 | B15: Yuedpao สาขา Central ขอนแก่น | C15: 3365 | D15: 1577378.5 | E15: 1.05% | F15: Yuedpao สาขา Future Park Rangsit ชั้น 3 | G15: {=_xlfn.XLOOKUP(F15,B:B,C:D,0,0)} -> 4199 | H15: 2122760 | I15: =H15*100/107 -> 1983887.9
A16: 14 | B16: Yuedpao สาขา The Mall บางกะปิ | C16: 3231 | D16: 1485188 | E16: 0.99% | F16: Yuedpao สาขา Central ปิ่นเกล้า | G16: {=_xlfn.XLOOKUP(F16,B:B,C:D,0,0)} -> 3590 | H16: 1658515.5 | I16: =H16*100/107 -> 1550014.5
A17: 15 | B17: Yuedpao สาขา MAYA เชียงใหม่ | C17: 3837 | D17: 1474698 | E17: 0.98% | F17: Yuedpao สาขา Central Festival เชียงใหม่ | G17: {=_xlfn.XLOOKUP(F17,B:B,C:D,0,0)} -> 2564 | H17: 1272433.8 | I17: =H17*100/107 -> 1189190.5
A18: 16 | B18: Yuedpao สาขา Central พระราม 2 | C18: 2867 | D18: 1396841.5 | E18: 0.93% | F18: Yuedpao สาขา Big C อำนาจเจริญ | G18: {=_xlfn.XLOOKUP(F18,B:B,C:D,0,0)} -> 954 | H18: 469734.5 | I18: =H18*100/107 -> 439004.21
A19: 17 | B19: Yuedpao สาขา Central ภูเก็ต | C19: 2847 | D19: 1394894 | E19: 0.93% | F19: Yuedpao สาขา I am China Town | G19: {=_xlfn.XLOOKUP(F19,B:B,C:D,0,0)} -> 725 | H19: 335396 | I19: =H19*100/107 -> 313454.21
A20: 18 | B20: Yuedpao สาขา Central นครศรีธรรมราช | C20: 2931 | D20: 1379264.5 | E20: 0.92% | F20: Yuedpao สาขา Sermthai Complex มหาสารคาม | G20: {=_xlfn.XLOOKUP(F20,B:B,C:D,0,0)} -> 1435 | H20: 658331 | I20: =H20*100/107 -> 615262.62
A21: 19 | B21: Yuedpao สาขา Robinson ถลาง ภูเก็ต | C21: 2504 | D21: 1373114 | E21: 0.92% | F21: Yuedpao สาขา Robinson กำแพงเพชร | G21: {=_xlfn.XLOOKUP(F21,B:B,C:D,0,0)} -> 0 | I21: =H21*100/107 -> 0
A22: 20 | B22: Yuedpao สาขา Central พิษณุโลก | C22: 2723 | D22: 1352797.5 | E22: 0.9%
A23: 21 | B23: Yuedpao สาขา Robinson ปราจีนบุรี | C23: 2556 | D23: 1349094.5 | E23: 0.9%
A24: 22 | B24: Yuedpao สาขา Robinson บ่อวิน | C24: 2968 | D24: 1343990.5 | E24: 0.9%
A25: 23 | B25: Yuedpao สาขา Central นครปฐม | C25: 2694 | D25: 1274168 | E25: 0.85%
A26: 24 | B26: Yuedpao สาขา Central Festival เชียงใหม่ | C26: 2564 | D26: 1272433.8 | E26: 0.85%
A27: 25 | B27: Yuedpao สาขา Central ระยอง | C27: 2400 | D27: 1198422 | E27: 0.8%
A28: 26 | B28: Yuedpao สาขา The Mall งามวงศ์วาน | C28: 2662 | D28: 1184036 | E28: 0.79%
A29: 27 | B29: Yuedpao สาขา Robinson ฉะเชิงเทรา | C29: 2359 | D29: 1162332 | E29: 0.78%
A30: 28 | B30: Yuedpao สาขา Seacon Square ศรีนครินทร์ | C30: 2525 | D30: 1161926 | E30: 0.78%
A31: 29 | B31: Yuedpao สาขา Central อยุธยา | C31: 2394 | D31: 1156083 | E31: 0.77%
A32: 30 | B32: Yuedpao สาขา Robinson สระบุรี | C32: 2327 | D32: 1112640 | E32: 0.74%
A33: 31 | B33: Yuedpao สาขา Central ศาลายา | C33: 2317 | D33: 1100317 | E33: 0.73%
... A107: 105 | B107: คลังสินค้ารับคืน Yuedpao Online | C107: -3871 | D107: -1288412 | E107: -0.86%
B109: Exported by | C109: janjoncj@gmail.com
B110: Date Time | C110: 1/2/2026 19:57+07:00

Sheet Report
B1: TARGET +V7% | C1: TARGET | D1: TARGET | E1: 01-31 JAN 2026 | H1: AVE SALE / INV | I1: SALE INV Standard | J1: DIFT | K1: AVE SALE / DAY | L1: % TARGET | M1: Sale Estimate | N1: ขาดอีก ต่อวัน | X1: MIX SALE GROUP AREA | Y1: MIX SALE ALL GROUP | Z1: เปรียบเทียบรายปี | AE1: เปรียบเทียบรายเดือน | AJ1: เปรียบเทียบรายสัปดาห์ | AQ1: REMARK | AS1: SHOP | AT1: SALE OUT ESTIMATE | AY1: SALE OUT ESTIMATE +50%
A2: SHOP | B2: 1 | C2: 1 | D2: TO DAY | E2: ก่อนหัก VAT | F2: หลังหัก VAT | G2: IVN. | N2: คงเหลือ | O2: คงเหลือ/วัน | P2: achieve 100% | Q2: AVL Sale | R2: Estimate | S2: Achieve | T2: คงเหลือ 110 | U2: achieve 110% | V2: คงเหลือ 120 | W2: achieve 120% | Z2: 2023 | AA2: 2024 | AB2: 2025 | AC2: DIFT | AE2: SALE +7% | AF2: DEC'2025 | AG2: JAN'2026 | AH2: DIFT | AJ2: 29-04 | AK2: 05-11 | AL2: 12-18 | AM2: 19-25 | AN2: 26-01 | AO2: DIFT | AT2: Target | AU2: ยอดขาย | AV2: ยอดขายเฉลี่ยนต่อวัน | AW2: Sale Estimate | AX2: %Target | AY2: ยอดขายเฉลี่ยนต่อวัน | AZ2: Sale Estimate | BA2: %Target
A3: Yuedpao สาขา Mega บางนา | B3: =(C3*7)/100+C3 -> 1102100 | C3: =_xlfn.XLOOKUP(A3,'Target ปี 2025'!B:B,'Target ปี 2025'!C:C,0,0) -> 1030000 | D3: =C3/30 -> 34333.333 | E3: =_xlfn.XLOOKUP(A3,ยอดขายปัจจุบัน!B:B,ยอดขายปัจจุบัน!D:D,0,0) -> 1027144 | F3: =E3*100/107 -> 959947.66 | G3: =_xlfn.XLOOKUP(A3,ยอดขายปัจจุบัน!B:B,ยอดขายปัจจุบัน!C:C,0,0) -> 1779 | H3: =E3/G3 -> 577.37156 | I3: 450 | J3: =(H3-I3)/H3 -> 0.22060587 | K3: =(E3-C3)/$E$36 -> -2856 | L3: =F3/C3 -> 0.93198802 | N3: =C3-F3 -> 70052.336 | O3: =N3/$E$36 -> 70052.336 | P3: =SUM(N3/$E$36) -> 70052.336 | Q3: =E3/$D$36 -> 34238.133 | R3: =Q3*22 -> 753238.93 | S3: =R3/C3 -> 0.73129994 | T3: =(C3-F3)*110% -> 77057.57 | U3: =T3/$E$36 -> 77057.57 | V3: =(C3-F3)*120% -> 84062.804 | W3: =SUM(V3/$E$36) -> 84062.804 | X3: =E3/$E$21 -> 0.065164372 | Y3: =E3/$H$36 -> #DIV/0! | Z3: =_xlfn.XLOOKUP(A3,ยอดขายปีที่แล้ว!B:B,ยอดขายปีที่แล้ว!D:D,0,0) -> 1003312.5 | AA3: =Z3*100/107 -> 937675.23 | AB3: =F3 -> 959947.66 | AC3: =AB3-AA3 -> 22272.43 | AD3: =(AB3-AA3)/AA3 -> 0.023752819 | AE3: =_xlfn.XLOOKUP(A3,ยอดขายเดือนที่เแล้ว!B:B,ยอดขายเดือนที่เแล้ว!D:D,0,0) -> 1239588.5 | AF3: =AE3*100/107 -> 1158493.9 | AG3: =F3 -> 959947.66 | AH3: =AG3-AF3 -> -198546.26 | AI3: =(AG3-AF3)/AF3 -> -0.17138308 | AJ3: 382075 | AK3: 196313.5 | AL3: 212647.5 | AM3: 232849 | AO3: =AM3-AL3 -> 20201.5 | AP3: =(AM3-AL3)/AL3 -> 0.094999941 | AS3: =A3 -> Yuedpao สาขา Mega บางนา | AT3: =C3 -> 1030000 | AU3: =F3 -> 959947.66 | AV3: =AU3/$D$36 -> 31998.255 | AW3: =(AV3*$E$36)+AU3 -> 991945.92 | AX3: =AW3/AT3 -> 0.96305429 | AY3: =(AV3*50%)+AV3 -> 47997.383 | AZ3: =(AY3*$E$36)+AU3 -> 1007945 | BA3: =AZ3/AT3 -> 0.97858742
A4: Yuedpao สาขา The Mall โคราช | B4: =(C4*7)/100+C4 -> 749000 | C4: =_xlfn.XLOOKUP(A4,'Target ปี 2025'!B:B,'Target ปี 2025'!C:C,0,0) -> 700000 | D4: =C4/30 -> 23333.333 | E4: =_xlfn.XLOOKUP(A4,ยอดขายปัจจุบัน!B:B,ยอดขายปัจจุบัน!D:D,0,0) -> 872878 | F4: =E4*100/107 -> 815773.83 | G4: =_xlfn.XLOOKUP(A4,ยอดขายปัจจุบัน!B:B,ยอดขายปัจจุบัน!C:C,0,0) -> 1822 | H4: =E4/G4 -> 479.07684 | I4: 450 | J4: =(H4-I4)/H4 -> 0.060693476 | K4: =(E4-C4)/$E$36 -> 172878 | L4: =F4/C4 -> 1.1653912 | N4: =C4-F4 -> -115773.83 | O4: =N4/$E$36 -> -115773.83 | P4: =SUM(N4/$E$36) -> -115773.83 | Q4: =E4/$D$36 -> 29095.933 | R4: =Q4*22 -> 640110.53 | S4: =R4/C4 -> 0.91444362 | T4: =(C4-F4)*110% -> -127351.21 | U4: =T4/$E$36 -> -127351.21 | V4: =(C4-F4)*120% -> -138928.6 | W4: =SUM(V4/$E$36) -> -138928.6 | X4: =E4/$E$21 -> 0.055377383 | Y4: =E4/$H$36 -> #DIV/0! | Z4: =_xlfn.XLOOKUP(A4,ยอดขายปีที่แล้ว!B:B,ยอดขายปีที่แล้ว!D:D,0,0) -> 684843 | AA4: =Z4*100/107 -> 640040.19 | AB4: =F4 -> 815773.83 | AC4: =AB4-AA4 -> 175733.64 | AD4: =(AB4-AA4)/AA4 -> 0.27456658 | AE4: =_xlfn.XLOOKUP(A4,ยอดขายเดือนที่เแล้ว!B:B,ยอดขายเดือนที่เแล้ว!D:D,0,0) -> 1097035 | AF4: =AE4*100/107 -> 1025266.4 | AG4: =F4 -> 815773.83 | AH4: =AG4-AF4 -> -209492.52 | AI4: =(AG4-AF4)/AF4 -> -0.20432985 | AJ4: 632943 | AK4: 207761 | AL4: 177134 | AM4: 161178 | AO4: =AM4-AL4 -> -15956 | AP4: =(AM4-AL4)/AL4 -> -0.090078697 | AS4: =A4 -> Yuedpao สาขา The Mall โคราช | AT4: =C4 -> 700000 | AU4: =F4 -> 815773.83 | AV4: =AU4/$D$36 -> 27192.461 | AW4: =(AV4*$E$36)+AU4 -> 842966.29 | AX4: =AW4/AT4 -> 1.2042376 | AY4: =(AV4*50%)+AV4 -> 40788.692 | AZ4: =(AY4*$E$36)+AU4 -> 856562.52 | BA4: =AZ4/AT4 -> 1.2236607
A5: Yuedpao สาขา SIAM SQUARE | B5: =(C5*7)/100+C5 -> 1177000 | C5: =_xlfn.XLOOKUP(A5,'Target ปี 2025'!B:B,'Target ปี 2025'!C:C,0,0) -> 1100000 | D5: =C5/30 -> 36666.667 | E5: =_xlfn.XLOOKUP(A5,ยอดขายปัจจุบัน!B:B,ยอดขายปัจจุบัน!D:D,0,0) -> 945055.2 | F5: =E5*100/107 -> 883229.16 | G5: =_xlfn.XLOOKUP(A5,ยอดขายปัจจุบัน!B:B,ยอดขายปัจจุบัน!C:C,0,0) -> 1716 | H5: =E5/G5 -> 550.73147 | I5: 450 | J5: =(H5-I5)/H5 -> 0.18290487 | K5: =(E5-C5)/$E$36 -> -154944.8 | L5: =F5/C5 -> 0.8029356 | N5: =C5-F5 -> 216770.84 | O5: =N5/$E$36 -> 216770.84 | P5: =SUM(N5/$E$36) -> 216770.84 | Q5: =E5/$D$36 -> 31501.84 | R5: =Q5*22 -> 693040.48 | S5: =R5/C5 -> 0.6300368 | T5: =(C5-F5)*110% -> 238447.93 | U5: =T5/$E$36 -> 238447.93 | V5: =(C5-F5)*120% -> 260125.01 | W5: =SUM(V5/$E$36) -> 260125.01 | X5: =E5/$E$21 -> 0.05995647 | Y5: =E5/$H$36 -> #DIV/0! | Z5: =_xlfn.XLOOKUP(A5,ยอดขายปีที่แล้ว!B:B,ยอดขายปีที่แล้ว!D:D,0,0) -> 1083013 | AA5: =Z5*100/107 -> 1012161.7 | AB5: =F5 -> 883229.16 | AC5: =AB5-AA5 -> -128932.52 | AD5: =(AB5-AA5)/AA5 -> -0.12738333 | AE5: =_xlfn.XLOOKUP(A5,ยอดขายเดือนที่เแล้ว!B:B,ยอดขายเดือนที่เแล้ว!D:D,0,0) -> 1192927.1 | AF5: =AE5*100/107 -> 1114885.1 | AG5: =F5 -> 883229.16 | AH5: =AG5-AF5 -> -231655.98 | AI5: =(AG5-AF5)/AF5 -> -0.20778462 | AJ5: 399075 | AK5: 208332 | AL5: 233542 | AM5: 191692.2 | AO5: =AM5-AL5 -> -41849.8 | AP5: =(AM5-AL5)/AL5 -> -0.17919603 | AS5: =A5 -> Yuedpao สาขา SIAM SQUARE | AT5: =C5 -> 1100000 | AU5: =F5 -> 883229.16 | AV5: =AU5/$D$36 -> 29440.972 | AW5: =(AV5*$E$36)+AU5 -> 912670.13 | AX5: =AW5/AT5 -> 0.82970012 | AY5: =(AV5*50%)+AV5 -> 44161.458 | AZ5: =(AY5*$E$36)+AU5 -> 927390.62 | BA5: =AZ5/AT5 -> 0.84308238
A6: Yuedpao สาขา Central ระยอง | B6: =(C6*7)/100+C6 -> 1284000 | C6: =_xlfn.XLOOKUP(A6,'Target ปี 2025'!B:B,'Target ปี 2025'!C:C,0,0) -> 1200000 | D6: =C6/30 -> 40000 | E6: =_xlfn.XLOOKUP(A6,ยอดขายปัจจุบัน!B:B,ยอดขายปัจจุบัน!D:D,0,0) -> 1198422 | F6: =E6*100/107 -> 1120020.6 | G6: =_xlfn.XLOOKUP(A6,ยอดขายปัจจุบัน!B:B,ยอดขายปัจจุบัน!C:C,0,0) -> 2400 | H6: =E6/G6 -> 499.3425 | I6: 450 | J6: =(H6-I6)/H6 -> 0.098814942 | K6: =(E6-C6)/$E$36 -> -1578 | L6: =F6/C6 -> 0.93335047 | N6: =C6-F6 -> 79979.439 | O6: =N6/$E$36 -> 79979.439 | P6: =SUM(N6/$E$36) -> 79979.439 | Q6: =E6/$D$36 -> 39947.4 | R6: =Q6*22 -> 878842.8 | S6: =R6/C6 -> 0.732369 | T6: =(C6-F6)*110% -> 87977.383 | U6: =T6/$E$36 -> 87977.383 | V6: =(C6-F6)*120% -> 95975.327 | W6: =SUM(V6/$E$36) -> 95975.327 | X6: =E6/$E$21 -> 0.076030641 | Y6: =E6/$H$36 -> #DIV/0! | Z6: =_xlfn.XLOOKUP(A6,ยอดขายปีที่แล้ว!B:B,ยอดขายปีที่แล้ว!D:D,0,0) -> 1137899 | AA6: =Z6*100/107 -> 1063457 | AB6: =F6 -> 1120020.6 | AC6: =AB6-AA6 -> 56563.551 | AD6: =(AB6-AA6)/AA6 -> 0.053188376 | AE6: =_xlfn.XLOOKUP(A6,ยอดขายเดือนที่เแล้ว!B:B,ยอดขายเดือนที่เแล้ว!D:D,0,0) -> 1712255 | AF6: =AE6*100/107 -> 1600238.3 | AG6: =F6 -> 1120020.6 | AH6: =AG6-AF6 -> -480217.76 | AI6: =(AG6-AF6)/AF6 -> -0.3000914 | AJ6: 330227 | AK6: 257684 | AL6: 236828 | AM6: 242839 | AO6: =AM6-AL6 -> 6011 | AP6: =(AM6-AL6)/AL6 -> 0.025381289 | AS6: =A6 -> Yuedpao สาขา Central ระยอง | AT6: =C6 -> 1200000 | AU6: =F6 -> 1120020.6 | AV6: =AU6/$D$36 -> 37334.019 | AW6: =(AV6*$E$36)+AU6 -> 1157354.6 | AX6: =AW6/AT6 -> 0.96446215 | AY6: =(AV6*50%)+AV6 -> 56001.028 | AZ6: =(AY6*$E$36)+AU6 -> 1176021.6 | BA6: =AZ6/AT6 -> 0.98001799
A7: Yuedpao สาขา Central โคราช | B7: =(C7*7)/100+C7 -> 642000 | C7: =_xlfn.XLOOKUP(A7,'Target ปี 2025'!B:B,'Target ปี 2025'!C:C,0,0) -> 600000 | D7: =C7/30 -> 20000 | E7: =_xlfn.XLOOKUP(A7,ยอดขายปัจจุบัน!B:B,ยอดขายปัจจุบัน!D:D,0,0) -> 620565 | F7: =E7*100/107 -> 579967.29 | G7: =_xlfn.XLOOKUP(A7,ยอดขายปัจจุบัน!B:B,ยอดขายปัจจุบัน!C:C,0,0) -> 1273 | H7: =E7/G7 -> 487.48233 | I7: 450 | J7: =(H7-I7)/H7 -> 0.076889609 | K7: =(E7-C7)/$E$36 -> 20565 | L7: =F7/C7 -> 0.96661215 | N7: =C7-F7 -> 20032.71 | O7: =N7/$E$36 -> 20032.71 | P7: =SUM(N7/$E$36) -> 20032.71 | Q7: =E7/$D$36 -> 20685.5 | R7: =Q7*22 -> 455081 | S7: =R7/C7 -> 0.75846833 | T7: =(C7-F7)*110% -> 22035.981 | U7: =T7/$E$36 -> 22035.981 | V7: =(C7-F7)*120% -> 24039.252 | W7: =SUM(V7/$E$36) -> 24039.252 | X7: =E7/$E$21 -> 0.039370068 | Y7: =E7/$H$36 -> #DIV/0! | Z7: =_xlfn.XLOOKUP(A7,ยอดขายปีที่แล้ว!B:B,ยอดขายปีที่แล้ว!D:D,0,0) -> 451737 | AA7: =Z7*100/107 -> 422184.11 | AB7: =F7 -> 579967.29 | AC7: =AB7-AA7 -> 157783.18 | AD7: =(AB7-AA7)/AA7 -> 0.37373073 | AE7: =_xlfn.XLOOKUP(A7,ยอดขายเดือนที่เแล้ว!B:B,ยอดขายเดือนที่เแล้ว!D:D,0,0) -> 832486 | AF7: =AE7*100/107 -> 778024.3 | AG7: =F7 -> 579967.29 | AH7: =AG7-AF7 -> -198057.01 | AI7: =(AG7-AF7)/AF7 -> -0.25456404 | AJ7: 470816 | AK7: 102180 | AL7: 148342 | AM7: 117474 | AO7: =AM7-AL7 -> -30868 | AP7: =(AM7-AL7)/AL7 -> -0.20808672 | AS7: =A7 -> Yuedpao สาขา Central โคราช | AT7: =C7 -> 600000 | AU7: =F7 -> 579967.29 | AV7: =AU7/$D$36 -> 19332.243 | AW7: =(AV7*$E$36)+AU7 -> 599299.53 | AX7: =AW7/AT7 -> 0.99883255 | AY7: =(AV7*50%)+AV7 -> 28998.364 | AZ7: =(AY7*$E$36)+AU7 -> 608965.65 | BA7: =AZ7/AT7 -> 1.0149428
A8: Yuedpao สาขา Robinson บุรีรัมย์ | B8: =(C8*7)/100+C8 -> 535000 | C8: =_xlfn.XLOOKUP(A8,'Target ปี 2025'!B:B,'Target ปี 2025'!C:C,0,0) -> 500000 | D8: =C8/30 -> 16666.667 | E8: =_xlfn.XLOOKUP(A8,ยอดขายปัจจุบัน!B:B,ยอดขายปัจจุบัน!D:D,0,0) -> 629096 | F8: =E8*100/107 -> 587940.19 | G8: =_xlfn.XLOOKUP(A8,ยอดขายปัจจุบัน!B:B,ยอดขายปัจจุบัน!C:C,0,0) -> 1257 | H8: =E8/G8 -> 500.47414 | I8: 330 | J8: =(H8-I8)/H8 -> 0.34062528 | K8: =(E8-C8)/$E$36 -> 129096 | L8: =F8/C8 -> 1.1758804 | N8: =C8-F8 -> -87940.187 | O8: =N8/$E$36 -> -87940.187 | P8: =SUM(N8/$E$36) -> -87940.187 | Q8: =E8/$D$36 -> 20969.867 | R8: =Q8*22 -> 461337.07 | S8: =R8/C8 -> 0.92267413 | T8: =(C8-F8)*110% -> -96734.206 | U8: =T8/$E$36 -> -96734.206 | V8: =(C8-F8)*120% -> -105528.22 | W8: =SUM(V8/$E$36) -> -105528.22 | X8: =E8/$E$21 -> 0.039911294 | Y8: =E8/$H$36 -> #DIV/0! | Z8: =_xlfn.XLOOKUP(A8,ยอดขายปีที่แล้ว!B:B,ยอดขายปีที่แล้ว!D:D,0,0) -> 452762 | AA8: =Z8*100/107 -> 423142.06 | AB8: =F8 -> 587940.19 | AC8: =AB8-AA8 -> 164798.13 | AD8: =(AB8-AA8)/AA8 -> 0.3894629 | AE8: =_xlfn.XLOOKUP(A8,ยอดขายเดือนที่เแล้ว!B:B,ยอดขายเดือนที่เแล้ว!D:D,0,0) -> 787019 | AF8: =AE8*100/107 -> 735531.78 | AG8: =F8 -> 587940.19 | AH8: =AG8-AF8 -> -147591.59 | AI8: =(AG8-AF8)/AF8 -> -0.2006597 | AJ8: 309246 | AK8: 118227 | AL8: 108099 | AM8: 133687 | AO8: =AM8-AL8 -> 25588 | AP8: =(AM8-AL8)/AL8 -> 0.23670894 | AS8: =A8 -> Yuedpao สาขา Robinson บุรีรัมย์ | AT8: =C8 -> 500000 | AU8: =F8 -> 587940.19 | AV8: =AU8/$D$36 -> 19598.006 | AW8: =(AV8*$E$36)+AU8 -> 607538.19 | AX8: =AW8/AT8 -> 1.2150764 | AY8: =(AV8*50%)+AV8 -> 29397.009 | AZ8: =(AY8*$E$36)+AU8 -> 617337.2 | BA8: =AZ8/AT8 -> 1.2346744
A9: Yuedpao สาขา MAYA เชียงใหม่ | B9: =(C9*7)/100+C9 -> 1284000 | C9: =_xlfn.XLOOKUP(A9,'Target ปี 2025'!B:B,'Target ปี 2025'!C:C,0,0) -> 1200000 | D9: =C9/30 -> 40000 | E9: =_xlfn.XLOOKUP(A9,ยอดขายปัจจุบัน!B:B,ยอดขายปัจจุบัน!D:D,0,0) -> 1474698 | F9: =E9*100/107 -> 1378222.4 | G9: =_xlfn.XLOOKUP(A9,ยอดขายปัจจุบัน!B:B,ยอดขายปัจจุบัน!C:C,0,0) -> 3837 | H9: =E9/G9 -> 384.3362 | I9: 450 | J9: =(H9-I9)/H9 -> -0.1708499 | K9: =(E9-C9)/$E$36 -> 274698 | L9: =F9/C9 -> 1.1485187 | N9: =C9-F9 -> -178222.43 | O9: =N9/$E$36 -> -178222.43 | P9: =SUM(N9/$E$36) -> -178222.43 | Q9: =E9/$D$36 -> 49156.6 | R9: =Q9*22 -> 1081445.2 | S9: =R9/C9 -> 0.90120433 | T9: =(C9-F9)*110% -> -196044.67 | U9: =T9/$E$36 -> -196044.67 | V9: =(C9-F9)*120% -> -213866.92 | W9: =SUM(V9/$E$36) -> -213866.92 | X9: =E9/$E$21 -> 0.093558225 | Y9: =E9/$H$36 -> #DIV/0! | Z9: =_xlfn.XLOOKUP(A9,ยอดขายปีที่แล้ว!B:B,ยอดขายปีที่แล้ว!D:D,0,0) -> 1137207 | AA9: =Z9*100/107 -> 1062810.3 | AB9: =F9 -> 1378222.4 | AC9: =AB9-AA9 -> 315412.15 | AD9: =(AB9-AA9)/AA9 -> 0.29677183 | AE9: =_xlfn.XLOOKUP(A9,ยอดขายเดือนที่เแล้ว!B:B,ยอดขายเดือนที่เแล้ว!D:D,0,0) -> 1689429 | AF9: =AE9*100/107 -> 1578905.6 | AG9: =F9 -> 1378222.4 | AH9: =AG9-AF9 -> -200683.18 | AI9: =(AG9-AF9)/AF9 -> -0.12710271 | AJ9: 139836 | AK9: 338620 | AL9: 344156 | AM9: 296966 | AO9: =AM9-AL9 -> -47190 | AP9: =(AM9-AL9)/AL9 -> -0.13711805 | AS9: =A9 -> Yuedpao สาขา MAYA เชียงใหม่ | AT9: =C9 -> 1200000 | AU9: =F9 -> 1378222.4 | AV9: =AU9/$D$36 -> 45940.748 | AW9: =(AV9*$E$36)+AU9 -> 1424163.2 | AX9: =AW9/AT9 -> 1.1868026 | AY9: =(AV9*50%)+AV9 -> 68911.121 | AZ9: =(AY9*$E$36)+AU9 -> 1447133.6 | BA9: =AZ9/AT9 -> 1.2059446
A10: Exchange Store | AS10: Exchange Store
A11: Yuedpao สาขา Future Park Rangsit ชั้น 3 | B11: =(C11*7)/100+C11 -> 2354000 | C11: =_xlfn.XLOOKUP(A11,'Target ปี 2025'!B:B,'Target ปี 2025'!C:C,0,0) -> 2200000 | D11: =C11/30 -> 73333.333 | E11: =_xlfn.XLOOKUP(A11,ยอดขายปัจจุบัน!B:B,ยอดขายปัจจุบัน!D:D,0,0) -> 2122760 | F11: =E11*100/107 -> 1983887.9 | G11: =_xlfn.XLOOKUP(A11,ยอดขายปัจจุบัน!B:B,ยอดขายปัจจุบัน!C:C,0,0) -> 4199 | H11: =E11/G11 -> 505.53941 | I11: 400 | J11: =(H11-I11)/H11 -> 0.20876595 | K11: =(E11-C11)/$E$36 -> -77240 | L11: =F11/C11 -> 0.9017672 | N11: =C11-F11 -> 216112.15 | O11: =N11/$E$36 -> 216112.15 | P11: =SUM(N11/$E$36) -> 216112.15 | Q11: =E11/$D$36 -> 70758.667 | R11: =Q11*22 -> 1556690.7 | S11: =R11/C11 -> 0.70758667 | T11: =(C11-F11)*110% -> 237723.36 | U11: =T11/$E$36 -> 237723.36 | V11: =(C11-F11)*120% -> 259334.58 | W11: =SUM(V11/$E$36) -> 259334.58 | X11: =E11/$E$21 -> 0.13467277 | Y11: =E11/$H$36 -> #DIV/0! | Z11: =_xlfn.XLOOKUP(A11,ยอดขายปีที่แล้ว!B:B,ยอดขายปีที่แล้ว!D:D,0,0) -> 1933578.5 | AA11: =Z11*100/107 -> 1807082.7 | AB11: =F11 -> 1983887.9 | AC11: =AB11-AA11 -> 176805.14 | AD11: =(AB11-AA11)/AA11 -> 0.097840093 | AE11: =_xlfn.XLOOKUP(A11,ยอดขายเดือนที่เแล้ว!B:B,ยอดขายเดือนที่เแล้ว!D:D,0,0) -> 2268063.5 | AF11: =AE11*100/107 -> 2119685.5 | AG11: =F11 -> 1983887.9 | AH11: =AG11-AF11 -> -135797.66 | AI11: =(AG11-AF11)/AF11 -> -0.064065005 | AJ11: 439323 | AK11: 476202 | AL11: 468528 | AM11: 403010 | AO11: =AM11-AL11 -> -65518 | AP11: =(AM11-AL11)/AL11 -> -0.13983796 | AQ11: REROCATE 16 DEC 2025 | AS11: =A11 -> Yuedpao สาขา Future Park Rangsit ชั้น 3 | AT11: =C11 -> 2200000 | AU11: =F11 -> 1983887.9 | AV11: =AU11/$D$36 -> 66129.595 | AW11: =(AV11*$E$36)+AU11 -> 2050017.4 | AX11: =AW11/AT11 -> 0.93182611 | AY11: =(AV11*50%)+AV11 -> 99194.393 | AZ11: =(AY11*$E$36)+AU11 -> 2083082.2 | BA11: =AZ11/AT11 -> 0.94685556
A12: Yuedpao สาขา Central Festival เชียงใหม่ | B12: =(C12*7)/100+C12 -> 1498000 | C12: =_xlfn.XLOOKUP(A12,'Target ปี 2025'!B:B,'Target ปี 2025'!C:C,0,0) -> 1400000 | D12: =C12/30 -> 46666.667 | E12: =_xlfn.XLOOKUP(A12,ยอดขายปัจจุบัน!B:B,ยอดขายปัจจุบัน!D:D,0,0) -> 1272433.8 | F12: =E12*100/107 -> 1189190.5 | G12: =_xlfn.XLOOKUP(A12,ยอดขายปัจจุบัน!B:B,ยอดขายปัจจุบัน!C:C,0,0) -> 2564 | H12: =E12/G12 -> 496.26903 | I12: 401 | J12: =(H12-I12)/H12 -> 0.19197054 | K12: =(E12-C12)/$E$36 -> -127566.2 | L12: =F12/C12 -> 0.84942176 | N12: =C12-F12 -> 210809.53 | O12: =N12/$E$36 -> 210809.53 | P12: =SUM(N12/$E$36) -> 210809.53 | Q12: =E12/$D$36 -> 42414.46 | R12: =Q12*22 -> 933118.12 | S12: =R12/C12 -> 0.66651294 | T12: =(C12-F12)*110% -> 231890.49 | U12: =T12/$E$36 -> 231890.49 | V12: =(C12-F12)*120% -> 252971.44 | W12: =SUM(V12/$E$36) -> 252971.44 | X12: =E12/$E$21 -> 0.08072612 | Y12: =E12/$H$36 -> #DIV/0! | Z12: =_xlfn.XLOOKUP(A12,ยอดขายปีที่แล้ว!B:B,ยอดขายปีที่แล้ว!D:D,0,0) -> 963741.5 | AA12: =Z12*100/107 -> 900692.99 | AB12: =F12 -> 1189190.5 | AC12: =AB12-AA12 -> 288497.48 | AD12: =(AB12-AA12)/AA12 -> 0.32030612 | AE12: =_xlfn.XLOOKUP(A12,ยอดขายเดือนที่เแล้ว!B:B,ยอดขายเดือนที่เแล้ว!D:D,0,0) -> 1582157.1 | AF12: =AE12*100/107 -> 1478651.5 | AG12: =F12 -> 1189190.5 | AH12: =AG12-AF12 -> -289461.03 | AI12: =(AG12-AF12)/AF12 -> -0.19576014 | AJ12: 439324 | AK12: 273810 | AL12: 240234 | AM12: 265538 | AO12: =AM12-AL12 -> 25304 | AP12: =(AM12-AL12)/AL12 -> 0.10533064 | AQ12: REROCATE 01 DEC 2024 | AS12: =A12 -> Yuedpao สาขา Central Festival เชียงใหม่ | AT12: =C12 -> 1400000 | AU12: =F12 -> 1189190.5 | AV12: =AU12/$D$36 -> 39639.682 | AW12: =(AV12*$E$36)+AU12 -> 1228830.1 | AX12: =AW12/AT12 -> 0.87773582 | AY12: =(AV12*50%)+AV12 -> 59459.523 | AZ12: =(AY12*$E$36)+AU12 -> 1248650 | BA12: =AZ12/AT12 -> 0.89189285
A13: Yuedpao สาขา Central พัทยา | B13: =(C13*7)/100+C13 -> 749000 | C13: =_xlfn.XLOOKUP(A13,'Target ปี 2025'!B:B,'Target ปี 2025'!C:C,0,0) -> 700000 | D13: =C13/30 -> 23333.333 | E13: =_xlfn.XLOOKUP(A13,ยอดขายปัจจุบัน!B:B,ยอดขายปัจจุบัน!D:D,0,0) -> 836250 | F13: =E13*100/107 -> 781542.06 | G13: =_xlfn.XLOOKUP(A13,ยอดขายปัจจุบัน!B:B,ยอดขายปัจจุบัน!C:C,0,0) -> 1489 | H13: =E13/G13 -> 561.61854 | I13: 401 | J13: =(H13-I13)/H13 -> 0.28599223 | K13: =(E13-C13)/$E$36 -> 136250 | L13: =F13/C13 -> 1.1164887 | N13: =C13-F13 -> -81542.056 | O13: =N13/$E$36 -> -81542.056 | P13: =SUM(N13/$E$36) -> -81542.056 | Q13: =E13/$D$36 -> 27875 | R13: =Q13*22 -> 613250 | S13: =R13/C13 -> 0.87607143 | T13: =(C13-F13)*110% -> -89696.262 | U13: =T13/$E$36 -> -89696.262 | V13: =(C13-F13)*120% -> -97850.467 | W13: =SUM(V13/$E$36) -> -97850.467 | X13: =E13/$E$21 -> 0.053053619 | Y13: =E13/$H$36 -> #DIV/0! | Z13: =_xlfn.XLOOKUP(A13,ยอดขายปีที่แล้ว!B:B,ยอดขายปีที่แล้ว!D:D,0,0) -> 2137785.5 | AA13: =Z13*100/107 -> 1997930.4 | AB13: =F13 -> 781542.06 | AC13: =AB13-AA13 -> -1216388.3 | AD13: =(AB13-AA13)/AA13 -> -0.60882418 | AE13: =_xlfn.XLOOKUP(A13,ยอดขายเดือนที่เแล้ว!B:B,ยอดขายเดือนที่เแล้ว!D:D,0,0) -> 945210 | AF13: =AE13*100/107 -> 883373.83 | AG13: =F13 -> 781542.06 | AH13: =AG13-AF13 -> -101831.78 | AI13: =(AG13-AF13)/AF13 -> -0.11527597 | AJ13: 439324 | AK13: 195820 | AL13: 148398 | AM13: 145714 | AO13: =AM13-AL13 -> -2684 | AP13: =(AM13-AL13)/AL13 -> -0.018086497 | AQ13: REROCATE 05 FEB 2024 | AS13: =A13 -> Yuedpao สาขา Central พัทยา | AT13: =C13 -> 700000 | AU13: =F13 -> 781542.06 | AV13: =AU13/$D$36 -> 26051.402 | AW13: =(AV13*$E$36)+AU13 -> 807593.46 | AX13: =AW13/AT13 -> 1.1537049 | AY13: =(AV13*50%)+AV13 -> 39077.103 | AZ13: =(AY13*$E$36)+AU13 -> 820619.16 | BA13: =AZ13/AT13 -> 1.1723131
A14: Yuedpao สาขา Central ปิ่นเกล้า | B14: =(C14*7)/100+C14 -> 1819000 | C14: =_xlfn.XLOOKUP(A14,'Target ปี 2025'!B:B,'Target ปี 2025'!C:C,0,0) -> 1700000 | D14: =C14/30 -> 56666.667 | E14: =_xlfn.XLOOKUP(A14,ยอดขายปัจจุบัน!B:B,ยอดขายปัจจุบัน!D:D,0,0) -> 1658515.5 | F14: =E14*100/107 -> 1550014.5 | G14: =_xlfn.XLOOKUP(A14,ยอดขายปัจจุบัน!B:B,ยอดขายปัจจุบัน!C:C,0,0) -> 3590 | H14: =E14/G14 -> 461.98203 | I14: 450 | J14: =(H14-I14)/H14 -> 0.025936146 | K14: =(E14-C14)/$E$36 -> -41484.5 | L14: =F14/C14 -> 0.91177323 | N14: =C14-F14 -> 149985.51 | O14: =N14/$E$36 -> 149985.51 | P14: =SUM(N14/$E$36) -> 149985.51 | Q14: =E14/$D$36 -> 55283.85 | R14: =Q14*22 -> 1216244.7 | S14: =R14/C14 -> 0.71543806 | T14: =(C14-F14)*110% -> 164984.07 | U14: =T14/$E$36 -> 164984.07 | V14: =(C14-F14)*120% -> 179982.62 | W14: =SUM(V14/$E$36) -> 179982.62 | X14: =E14/$E$21 -> 0.10522003 | Y14: =E14/$H$36 -> #DIV/0! | Z14: =_xlfn.XLOOKUP(A14,ยอดขายปีที่แล้ว!B:B,ยอดขายปีที่แล้ว!D:D,0,0) -> 991008.02 | AA14: =Z14*100/107 -> 926175.72 | AB14: =F14 -> 1550014.5 | AC14: =AB14-AA14 -> 623838.77 | AD14: =(AB14-AA14)/AA14 -> 0.67356416 | AE14: =_xlfn.XLOOKUP(A14,ยอดขายเดือนที่เแล้ว!B:B,ยอดขายเดือนที่เแล้ว!D:D,0,0) -> 2386873.4 | AF14: =AE14*100/107 -> 2230722.8 | AG14: =F14 -> 1550014.5 | AH14: =AG14-AF14 -> -680708.32 | AI14: =(AG14-AF14)/AF14 -> -0.30515146 | AJ14: 589947.8 | AK14: 331944 | AL14: 340478 | AM14: 329846.5 | AO14: =AM14-AL14 -> -10631.5 | AP14: =(AM14-AL14)/AL14 -> -0.031225219 | AQ14: REROCATE 01 DEC 2024 | AS14: =A14 -> Yuedpao สาขา Central ปิ่นเกล้า | AT14: =C14 -> 1700000 | AU14: =F14 -> 1550014.5 | AV14: =AU14/$D$36 -> 51667.15 | AW14: =(AV14*$E$36)+AU14 -> 1601681.6 | AX14: =AW14/AT14 -> 0.94216567 | AY14: =(AV14*50%)+AV14 -> 77500.724 | AZ14: =(AY14*$E$36)+AU14 -> 1627515.2 | BA14: =AZ14/AT14 -> 0.95736189
A15: Yuedpao สาขา I am China Town | B15: =(C15*7)/100+C15 -> 428000 | C15: =_xlfn.XLOOKUP(A15,'Target ปี 2025'!B:B,'Target ปี 2025'!C:C,0,0) -> 400000 | D15: =C15/30 -> 13333.333 | E15: =_xlfn.XLOOKUP(A15,ยอดขายปัจจุบัน!B:B,ยอดขายปัจจุบัน!D:D,0,0) -> 335396 | F15: =E15*100/107 -> 313454.21 | G15: =_xlfn.XLOOKUP(A15,ยอดขายปัจจุบัน!B:B,ยอดขายปัจจุบัน!C:C,0,0) -> 725 | H15: =E15/G15 -> 462.61517 | I15: 430 | J15: =(H15-I15)/H15 -> 0.070501735 | K15: =(E15-C15)/$E$36 -> -64604 | L15: =F15/C15 -> 0.78363551 | N15: =C15-F15 -> 86545.794 | O15: =N15/$E$36 -> 86545.794 | P15: =SUM(N15/$E$36) -> 86545.794 | Q15: =E15/$D$36 -> 11179.867 | R15: =Q15*22 -> 245957.07 | S15: =R15/C15 -> 0.61489267 | T15: =(C15-F15)*110% -> 95200.374 | U15: =T15/$E$36 -> 95200.374 | V15: =(C15-F15)*120% -> 103854.95 | W15: =SUM(V15/$E$36) -> 103854.95 | X15: =E15/$E$21 -> 0.021278292 | Y15: =E15/$H$36 -> #DIV/0! | Z15: =_xlfn.XLOOKUP(A15,ยอดขายปีที่แล้ว!B:B,ยอดขายปีที่แล้ว!D:D,0,0) -> 0 | AA15: =Z15*100/107 -> 0 | AB15: =F15 -> 313454.21 | AC15: =AB15-AA15 -> 313454.21 | AD15: =(AB15-AA15)/AA15 -> #DIV/0! | AE15: =_xlfn.XLOOKUP(A15,ยอดขายเดือนที่เแล้ว!B:B,ยอดขายเดือนที่เแล้ว!D:D,0,0) -> 331919 | AF15: =AE15*100/107 -> 310204.67 | AG15: =F15 -> 313454.21 | AH15: =AG15-AF15 -> 3249.5327 | AI15: =(AG15-AF15)/AF15 -> 0.010475447 | AJ15: 747249 | AK15: 74933 | AL15: 64776 | AM15: 60525 | AO15: =AM15-AL15 -> -4251 | AP15: =(AM15-AL15)/AL15 -> -0.065626158 | AQ15: OPEN 01 JUN 2024 | AS15: =A15 -> Yuedpao สาขา I am China Town | AT15: =C15 -> 400000 | AU15: =F15 -> 313454.21 | AV15: =AU15/$D$36 -> 10448.474 | AW15: =(AV15*$E$36)+AU15 -> 323902.68 | AX15: =AW15/AT15 -> 0.8097567 | AY15: =(AV15*50%)+AV15 -> 15672.71 | AZ15: =(AY15*$E$36)+AU15 -> 329126.92 | BA15: =AZ15/AT15 -> 0.82281729
A16: Yuedpao สาขา Robinson ชลบุรี | B16: =(C16*7)/100+C16 -> 1016500 | C16: =_xlfn.XLOOKUP(A16,'Target ปี 2025'!B:B,'Target ปี 2025'!C:C,0,0) -> 950000 | D16: =C16/30 -> 31666.667 | E16: =_xlfn.XLOOKUP(A16,ยอดขายปัจจุบัน!B:B,ยอดขายปัจจุบัน!D:D,0,0) -> 907039 | F16: =E16*100/107 -> 847700 | G16: =_xlfn.XLOOKUP(A16,ยอดขายปัจจุบัน!B:B,ยอดขายปัจจุบัน!C:C,0,0) -> 2002 | H16: =E16/G16 -> 453.06643 | I16: 430 | J16: =(H16-I16)/H16 -> 0.050911813 | K16: =(E16-C16)/$E$36 -> -42961 | L16: =F16/C16 -> 0.89231579 | N16: =C16-F16 -> 102300 | O16: =N16/$E$36 -> 102300 | P16: =SUM(N16/$E$36) -> 102300 | Q16: =E16/$D$36 -> 30234.633 | R16: =Q16*22 -> 665161.93 | S16: =R16/C16 -> 0.70017046 | T16: =(C16-F16)*110% -> 112530 | U16: =T16/$E$36 -> 112530 | V16: =(C16-F16)*120% -> 122760 | W16: =SUM(V16/$E$36) -> 122760 | X16: =E16/$E$21 -> 0.057544635 | Y16: =E16/$H$36 -> #DIV/0! | Z16: =_xlfn.XLOOKUP(A16,ยอดขายปีที่แล้ว!B:B,ยอดขายปีที่แล้ว!D:D,0,0) -> 0 | AA16: =Z16*100/107 -> 0 | AB16: =F16 -> 847700 | AC16: =AB16-AA16 -> 847700 | AD16: =(AB16-AA16)/AA16 -> #DIV/0! | AE16: =_xlfn.XLOOKUP(A16,ยอดขายเดือนที่เแล้ว!B:B,ยอดขายเดือนที่เแล้ว!D:D,0,0) -> 1409862 | AF16: =AE16*100/107 -> 1317628 | AG16: =F16 -> 847700 | AH16: =AG16-AF16 -> -469928.04 | AI16: =(AG16-AF16)/AF16 -> -0.35664696 | AJ16: 307762 | AK16: 187964 | AL16: 202371 | AM16: 170906 | AO16: =AM16-AL16 -> -31465 | AP16: =(AM16-AL16)/AL16 -> -0.15548176 | AQ16: OPEN 01 AUN 2024 | AS16: =A16 -> Yuedpao สาขา Robinson ชลบุรี | AT16: =C16 -> 950000 | AU16: =F16 -> 847700 | AV16: =AU16/$D$36 -> 28256.667 | AW16: =(AV16*$E$36)+AU16 -> 875956.67 | AX16: =AW16/AT16 -> 0.92205965 | AY16: =(AV16*50%)+AV16 -> 42385 | AZ16: =(AY16*$E$36)+AU16 -> 890085 | BA16: =AZ16/AT16 -> 0.93693158
A17: Yuedpao สาขา Big C อำนาจเจริญ | B17: =(C17*7)/100+C17 -> 588500 | C17: =_xlfn.XLOOKUP(A17,'Target ปี 2025'!B:B,'Target ปี 2025'!C:C,0,0) -> 550000 | D17: =C17/30 -> 18333.333 | E17: =_xlfn.XLOOKUP(A17,ยอดขายปัจจุบัน!B:B,ยอดขายปัจจุบัน!D:D,0,0) -> 469734.5 | F17: =E17*100/107 -> 439004.21 | G17: =_xlfn.XLOOKUP(A17,ยอดขายปัจจุบัน!B:B,ยอดขายปัจจุบัน!C:C,0,0) -> 954 | H17: =E17/G17 -> 492.38417 | I17: 431 | J17: =(H17-I17)/H17 -> 0.12466723 | K17: =(E17-C17)/$E$36 -> -80265.5 | L17: =F17/C17 -> 0.79818946 | N17: =C17-F17 -> 110995.79 | O17: =N17/$E$36 -> 110995.79 | P17: =SUM(N17/$E$36) -> 110995.79 | Q17: =E17/$D$36 -> 15657.817 | R17: =Q17*22 -> 344471.97 | S17: =R17/C17 -> 0.62631267 | T17: =(C17-F17)*110% -> 122095.37 | U17: =T17/$E$36 -> 122095.37 | V17: =(C17-F17)*120% -> 133194.95 | W17: =SUM(V17/$E$36) -> 133194.95 | X17: =E17/$E$21 -> 0.029801034 | Y17: =E17/$H$36 -> #DIV/0! | Z17: =_xlfn.XLOOKUP(A17,ยอดขายปีที่แล้ว!B:B,ยอดขายปีที่แล้ว!D:D,0,0) -> 0 | AA17: =Z17*100/107 -> 0 | AB17: =F17 -> 439004.21 | AC17: =AB17-AA17 -> 439004.21 | AD17: =(AB17-AA17)/AA17 -> #DIV/0! | AE17: =_xlfn.XLOOKUP(A17,ยอดขายเดือนที่เแล้ว!B:B,ยอดขายเดือนที่เแล้ว!D:D,0,0) -> 640349 | AF17: =AE17*100/107 -> 598457.01 | AG17: =F17 -> 439004.21 | AH17: =AG17-AF17 -> -159452.8 | AI17: =(AG17-AF17)/AF17 -> -0.26643986 | AJ17: 307762 | AK17: 99750 | AL17: 102699.5 | AM17: 84775 | AO17: =AM17-AL17 -> -17924.5 | AP17: =(AM17-AL17)/AL17 -> -0.17453347 | AQ17: OPEN 15 NOV 2024 | AS17: =A17 -> Yuedpao สาขา Big C อำนาจเจริญ | AT17: =C17 -> 550000 | AU17: =F17 -> 439004.21 | AV17: =AU17/$D$36 -> 14633.474 | AW17: =(AV17*$E$36)+AU17 -> 453637.68 | AX17: =AW17/AT17 -> 0.82479578 | AY17: =(AV17*50%)+AV17 -> 21950.21 | AZ17: =(AY17*$E$36)+AU17 -> 460954.42 | BA17: =AZ17/AT17 -> 0.83809894
A18: Yuedpao สาขา Robinson แม่สอด | B18: =(C18*7)/100+C18 -> 1016500 | C18: =_xlfn.XLOOKUP(A18,'Target ปี 2025'!B:B,'Target ปี 2025'!C:C,0,0) -> 950000 | D18: =C18/30 -> 31666.667 | E18: =_xlfn.XLOOKUP(A18,ยอดขายปัจจุบัน!B:B,ยอดขายปัจจุบัน!D:D,0,0) -> 734037.5 | F18: =E18*100/107 -> 686016.36 | G18: =_xlfn.XLOOKUP(A18,ยอดขายปัจจุบัน!B:B,ยอดขายปัจจุบัน!C:C,0,0) -> 1396 | H18: =E18/G18 -> 525.81483 | I18: 432 | J18: =(H18-I18)/H18 -> 0.178418 | K18: =(E18-C18)/$E$36 -> -215962.5 | L18: =F18/C18 -> 0.72212248 | N18: =C18-F18 -> 263983.64 | O18: =N18/$E$36 -> 263983.64 | P18: =SUM(N18/$E$36) -> 263983.64 | Q18: =E18/$D$36 -> 24467.917 | R18: =Q18*22 -> 538294.17 | S18: =R18/C18 -> 0.56662544 | T18: =(C18-F18)*110% -> 290382.01 | U18: =T18/$E$36 -> 290382.01 | V18: =(C18-F18)*120% -> 316780.37 | W18: =SUM(V18/$E$36) -> 316780.37 | X18: =E18/$E$21 -> 0.046569023 | Y18: =E18/$H$36 -> #DIV/0! | Z18: =_xlfn.XLOOKUP(A18,ยอดขายปีที่แล้ว!B:B,ยอดขายปีที่แล้ว!D:D,0,0) -> 0 | AA18: =Z18*100/107 -> 0 | AB18: =F18 -> 686016.36 | AC18: =AB18-AA18 -> 686016.36 | AD18: =(AB18-AA18)/AA18 -> #DIV/0! | AE18: =_xlfn.XLOOKUP(A18,ยอดขายเดือนที่เแล้ว!B:B,ยอดขายเดือนที่เแล้ว!D:D,0,0) -> 1098700 | AF18: =AE18*100/107 -> 1026822.4 | AG18: =F18 -> 686016.36 | AH18: =AG18-AF18 -> -340806.07 | AI18: =(AG18-AF18)/AF18 -> -0.33190361 | AJ18: 307762 | AK18: 206538 | AL18: 147083 | AM18: 131920 | AO18: =AM18-AL18 -> -15163 | AP18: =(AM18-AL18)/AL18 -> -0.10309145 | AQ18: OPEN 01 NOV 2024 | AS18: =A18 -> Yuedpao สาขา Robinson แม่สอด | AT18: =C18 -> 950000 | AU18: =F18 -> 686016.36 | AV18: =AU18/$D$36 -> 22867.212 | AW18: =(AV18*$E$36)+AU18 -> 708883.57 | AX18: =AW18/AT18 -> 0.74619323 | AY18: =(AV18*50%)+AV18 -> 34300.818 | AZ18: =(AY18*$E$36)+AU18 -> 720317.17 | BA18: =AZ18/AT18 -> 0.7582286
A19: Yuedpao สาขา Sermthai Complex มหาสารคาม | B19: =(C19*7)/100+C19 -> 856000 | C19: =_xlfn.XLOOKUP(A19,'Target ปี 2025'!B:B,'Target ปี 2025'!C:C,0,0) -> 800000 | D19: =C19/30 -> 26666.667 | E19: =_xlfn.XLOOKUP(A19,ยอดขายปัจจุบัน!B:B,ยอดขายปัจจุบัน!D:D,0,0) -> 658331 | F19: =E19*100/107 -> 615262.62 | G19: =_xlfn.XLOOKUP(A19,ยอดขายปัจจุบัน!B:B,ยอดขายปัจจุบัน!C:C,0,0) -> 1435 | H19: =E19/G19 -> 458.76725 | I19: 433 | J19: =(H19-I19)/H19 -> 0.056166275 | K19: =(E19-C19)/$E$36 -> -141669 | L19: =F19/C19 -> 0.76907827 | N19: =C19-F19 -> 184737.38 | O19: =N19/$E$36 -> 184737.38 | P19: =SUM(N19/$E$36) -> 184737.38 | Q19: =E19/$D$36 -> 21944.367 | R19: =Q19*22 -> 482776.07 | S19: =R19/C19 -> 0.60347008 | T19: =(C19-F19)*110% -> 203211.12 | U19: =T19/$E$36 -> 203211.12 | V19: =(C19-F19)*120% -> 221684.86 | W19: =SUM(V19/$E$36) -> 221684.86 | X19: =E19/$E$21 -> 0.041766029 | Y19: =E19/$H$36 -> #DIV/0! | Z19: =_xlfn.XLOOKUP(A19,ยอดขายปีที่แล้ว!B:B,ยอดขายปีที่แล้ว!D:D,0,0) -> 0 | AA19: =Z19*100/107 -> 0 | AB19: =F19 -> 615262.62 | AC19: =AB19-AA19 -> 615262.62 | AD19: =(AB19-AA19)/AA19 -> #DIV/0! | AE19: =_xlfn.XLOOKUP(A19,ยอดขายเดือนที่เแล้ว!B:B,ยอดขายเดือนที่เแล้ว!D:D,0,0) -> 489052.4 | AF19: =AE19*100/107 -> 457058.32 | AG19: =F19 -> 615262.62 | AH19: =AG19-AF19 -> 158204.3 | AI19: =(AG19-AF19)/AF19 -> 0.34613592 | AJ19: 307762 | AK19: 131404 | AL19: 141031 | AM19: 115539 | AO19: =AM19-AL19 -> -25492 | AP19: =(AM19-AL19)/AL19 -> -0.18075459 | AQ19: OPEN 20 DEC 2024 | AS19: =A19 -> Yuedpao สาขา Sermthai Complex มหาสารคาม | AT19: =C19 -> 800000 | AU19: =F19 -> 615262.62 | AV19: =AU19/$D$36 -> 20508.754 | AW19: =(AV19*$E$36)+AU19 -> 635771.37 | AX19: =AW19/AT19 -> 0.79471421 | AY19: =(AV19*50%)+AV19 -> 30763.131 | AZ19: =(AY19*$E$36)+AU19 -> 646025.75 | BA19: =AZ19/AT19 -> 0.80753218
A20: TOTAL SAME STORE | C20: =SUM(C3:C19) -> 15980000 | D20: =SUM(D3:D16) -> 456000 | E20: =SUM(E3:E19) -> 15762356 | F20: =SUM(F3:F19) -> 14731173 | G20: =SUM(G3:G16) -> 28653 | H20: =E20/G20 -> 550.11187 | I20: 419 | J20: =(H20-I20)/H20 -> 0.23833674 | K20: =(E20-C20)/$E$36 -> -217644.5 | L20: =F20/C20 -> 0.92185065 | N20: =SUM(N3:N16) -> 689109.81 | O20: =SUM(O3:O15) -> 586809.81 | P20: =SUM(N20/$E$36) -> 689109.81 | Q20: =SUM(Q3:Q9) -> 225595.27 | R20: =SUM(R3:R9) -> 4963096 | S20: =SUM(S3:S9) -> 5.5904962 | T20: =SUM(T3:T9) -> 5388.7664 | U20: =SUM(U3:U9) -> 5388.7664 | V20: =SUM(V3:V9) -> 5878.6542 | W20: =SUM(W3:W9) -> 5878.6542 | X20: =E20/$E$20 -> 1 | Y20: =SUM(Y3:Y9) -> #DIV/0! | Z20: =SUM(Z3:Z9) -> 5950773.5 | AA20: =SUM(AA3:AA9) -> 5561470.6 | AB20: =SUM(AB3:AB9) -> 6325101.1 | AC20: =AB20-AA20 -> 763630.56 | AD20: =(AB20-AA20)/AA20 -> 0.13730731 | AE20: =SUM(AE3:AE9) -> 8550739.6 | AF20: =SUM(AF3:AF9) -> 7991345.4 | AG20: =SUM(AG3:AG9) -> 6325101.1 | AH20: =AG20-AF20 -> -1666244.3 | AI20: =(AG20-AF20)/AF20 -> -0.2085061 | AJ20: =SUM(AJ3:AJ9) -> 2664218 | AK20: =SUM(AK3:AK9) -> 1429117.5 | AL20: =SUM(AL3:AL9) -> 1460748.5 | AM20: =SUM(AM3:AM9) -> 1376685.2 | AN20: =SUM(AN3:AN9) -> 0 | AO20: =AM20-AL20 -> -84063.3 | AP20: =(AM20-AL20)/AL20 -> -0.057548099 | AS20: ยอดรวม | AT20: =SUM(AT3:AT16) -> 13680000 | AU20: =SUM(AU3:AU16) -> 12990890 | AV20: =AU20/$D$36 -> 433029.67 | AW20: =(AV20*$E$36)+AU20 -> 13423920 | AX20: =AW20/AT20 -> 0.98128069 | AY20: =(AV20*50%)+AV20 -> 649544.51 | AZ20: =(AY20*$E$36)+AU20 -> 13640435 | BA20: =AZ20/AT20 -> 0.9971078
A21: TOTAL ALL STORE | B21: =SUM(B3:B15) -> 13621100 | C21: =SUM(C3:C19) -> 15980000 | D21: =C21/31 -> 515483.87 | E21: =SUM(E3:E19) -> 15762356 | F21: =SUM(F3:F19) -> 14731173 | G21: =SUM(G3:G16) -> 28653 | H21: =E21/G21 -> 550.11187 | I21: 419 | J21: =(H21-I21)/H21 -> 0.23833674 | K21: =(E21-C21)/$E$36 -> -217644.5 | L21: =F21/C21 -> 0.92185065 | N21: =SUM(N3:N16) -> 689109.81 | O21: =N21/$E$36 -> 689109.81 | P21: =SUM(N21/$E$36) -> 689109.81 | Q21: =E21/$D$36 -> 525411.85 | R21: =Q21*22 -> 11559061 | S21: =R21/C21 -> 0.72334548 | T21: =SUM(T3:T15) -> 645490.79 | U21: =T21/$E$36 -> 645490.79 | V21: =SUM(V3:V15) -> 704171.78 | W21: =SUM(V21/$E$36) -> 704171.78 | X21: =E21/$E$21 -> 1 | Y21: =E21/H36 -> #DIV/0! | Z21: =SUM(Z2:Z20) -> 17929684 | AA21: =SUM(AA3:AA19) -> 11193352 | AB21: =SUM(AB3:AB19) -> 14731173 | AC21: =AB21-AA21 -> 3537821 | AD21: =(AB21-AA21)/AA21 -> 0.31606447 | AE21: =SUM(AE3:AE16) -> 17474825 | AF21: =SUM(AF3:AF19) -> 18413950 | AG21: =SUM(AG3:AG19) -> 14731173 | AH21: =AG21-AF21 -> -3682776.2 | AI21: =(AG21-AF21)/AF21 -> -0.19999925 | AJ21: =SUM(AJ3:AJ19) -> 6550433.8 | AK21: =SUM(AK3:AK19) -> 3407482.5 | AL21: =SUM(AL3:AL15) -> 2723162.5 | AM21: =SUM(AM3:AM15) -> 2581318.7 | AN21: =SUM(AN3:AN15) -> 0 | AO21: =AM21-AL21 -> -141843.8 | AP21: =(AM21-AL21)/AL21 -> -0.052087894 | AW21: =(AW20*7)/100+AW20 -> 14363594
E23: =SUM(E21-C21) -> -217644.5 | F23: =SUM(F21-C21) -> -1248826.6 | K23: ขาดอีก | L23: =SUM(L21-100%) -> -0.078149351
C26: =C21-F21 -> 1248826.6 | I26: =SUM(I3:I15) -> 5112 | J26: =I26/15 -> 340.8
W28: Yuedpao สาขา Fashion Island
W29: Yuedpao สาขา SIAM SQUARE
W30: Yuedpao สาขา Central Festival เชียงใหม่
W31: Yuedpao สาขา Central อุบลราชธานี
W32: Yuedpao สาขา Central เชียงใหม่แอร์พอร์ต
W33: Yuedpao สาขา The Mall บางกะปิ
D34: แก้ไขตัวเลข | H34: แก้ไขตัวเลข | W34: Yuedpao สาขา จตุจักรโครงการ 28
D35: วันนี้ | E35: วันคงเหลือ | H35: ยอดขายรวมทั้งหมด | W35: Yuedpao สาขา Central เชียงราย
D36: 30 | E36: =31-D36 -> 1 | W36: Yuedpao สาขา จตุจักรโครงการ 22 ริมถนน
W37: Yuedpao สาขา Central รามอินทรา
W38: Yuedpao สาขา Central นครสวรรค์
W39: Yuedpao สาขา จตุจักรโครงการ 6
W40: Yuedpao สาขา BTS สยาม
W41: Yuedpao สาขา BTS หมอชิต
W42: Yuedpao สาขา Robinson บุรีรัมย์
A43: สาขา | C43: TARGET | D43: SALE OUT
A44: Yuedpao สาขา Mega บางนา | C44: =C3 -> 1030000 | D44: =E3 -> 1027144
...

Sheet Target ปี 2025
A1: NO | B1: SHOP | C1: TARGET DEC'2025
A2: 1 | B2: Yuedpao สาขา Central หาดใหญ่ | C2: 2600000
A3: 2 | B3: Yuedpao สาขา Central เวสต์เกต | C3: 2500000
A4: 3 | B4: Yuedpao สาขา Future Park Rangsit (Flagship store) | C4: 2100000
A5: 4 | B5: Yuedpao สาขา Fashion Island | C5: 2000000
A6: 5 | B6: Yuedpao สาขา Central ปิ่นเกล้า | C6: 1700000
A7: 6 | B7: Yuedpao สาขา Central ลาดพร้าว | C7: 2000000
A8: 7 | B8: Yuedpao สาขา Future Park Rangsit ชั้น 3 | C8: 2200000
A9: 8 | B9: Yuedpao สาขา Robinson บ่อวิน | C9: 1600000
A10: 9 | B10: Yuedpao สาขา Central กระบี่ | C10: 2300000
A11: 10 | B11: Yuedpao สาขา The Mall บางกะปิ | C11: 1400000
A12: 11 | B12: Yuedpao สาขา Central อุบลราชธานี | C12: 1550000
A13: 12 | B13: Yuedpao สาขา Central พระราม 2 | C13: 1300000
... A81: 80 | B81: Yuedpao สาขา BTS หมอชิต | C81: 300000
