Workbook

Sheet ยอดขายปีที่แล้ว
A1: ยอดขายรายคลัง|สาขา 1/2/2568 - 28/2/2568
A2: # | B2: คลัง|สาขา | C2: จำนวนรายการ | D2: ยอดขาย(บาท) | E2: ยอดขาย(%)
A3: 1 | B3: คลังสินค้า Yuedpao Online | C3: 112874 | D3: 39059198 | E3: 38.46%
A4: 2 | B4: Yuedpao สาขา Central เวสต์เกต | C4: 3618 | D4: 1825624.5 | E4: 1.8%
A5: 3 | B5: Yuedpao สาขา Central ลาดพร้าว | C5: 3489 | D5: 1698672 | E5: 1.67%
A6: 4 | B6: Yuedpao สาขา Future Park Rangsit ชั้น 3 | C6: 4052 | D6: 1688582.5 | E6: 1.66%
A7: 5 | B7: Yuedpao สาขา Fashion Island | C7: 3373 | D7: 1687356.5 | E7: 1.66%
A8: 6 | B8: Yuedpao สาขา Future Park Rangsit (Flagship store) | C8: 3210 | D8: 1624899.8 | E8: 1.6%
A9: 7 | B9: Yuedpao สาขา Central ขอนแก่น | C9: 3469 | D9: 1420659 | E9: 1.4%
A10: 8 | B10: Yuedpao สาขา Central พระราม 2 | C10: 3515 | D10: 1401769.2 | E10: 1.38%
A11: 9 | B11: Yuedpao สาขา Central หาดใหญ่ | C11: 3229 | D11: 1396363 | E11: 1.37%
A12: 10 | B12: Yuedpao สาขา The Mall บางกะปิ | C12: 2930 | D12: 1305153 | E12: 1.29%
A13: 11 | B13: Yuedpao สาขา Robinson บ่อวิน | C13: 2943 | D13: 1288663.5 | E13: 1.27%
A14: 12 | B14: Yuedpao สาขา Central สุราษฎร์ธานี | C14: 2960 | D14: 1262257.5 | E14: 1.24%
... A90: 88 | B90: คลังสินค้ารับคืน Yuedpao Online | C90: -1400 | D90: -417422.22 | E90: -0.41%
B92: Exported by | C92: janjoncj@gmail.com
B93: Date Time | C93: 4/3/2026 10:21+07:00

Sheet ยอดขายเดือนที่เแล้ว
A1: ยอดขายรายคลัง|สาขา 1/1/2569 - 31/1/2569
A2: # | B2: คลัง|สาขา | C2: จำนวนรายการ | D2: ยอดขาย(บาท) | E2: ยอดขาย(%)
A3: 1 | B3: คลังสินค้า Yuedpao Online | C3: 188622 | D3: 63798576 | E3: 42.5%
A4: 2 | B4: Yuedpao สาขา Central หาดใหญ่ | C4: 7663 | D4: 2719550.5 | E4: 1.81%
A5: 3 | B5: Yuedpao สาขา Future Park Rangsit (Flagship store) | C5: 4325 | D5: 2162196 | E5: 1.44%
A6: 4 | B6: Yuedpao สาขา Future Park Rangsit ชั้น 3 | C6: 4199 | D6: 2122760 | E6: 1.41%
A7: 5 | B7: Yuedpao สาขา Central ลาดพร้าว | C7: 4026 | D7: 2076950.5 | E7: 1.38%
A8: 6 | B8: Yuedpao สาขา Central เวสต์เกต | C8: 4036 | D8: 2064026 | E8: 1.38%
A9: 7 | B9: Yuedpao สาขา Central กระบี่ | C9: 3948 | D9: 1911703.5 | E9: 1.27%
A10: 8 | B10: Yuedpao สาขา Fashion Island | C10: 3704 | D10: 1883097.5 | E10: 1.25%
A11: 9 | B11: Yuedpao สาขา Central อุบลราชธานี | C11: 3517 | D11: 1740017.5 | E11: 1.16%
A12: 10 | B12: Yuedpao สาขา Central ปิ่นเกล้า | C12: 3590 | D12: 1658515.5 | E12: 1.1%
A13: 11 | B13: Yuedpao สาขา Central สุราษฎร์ธานี | C13: 3420 | D13: 1657555 | E13: 1.1%
A14: 12 | B14: Yuedpao สาขา The Mall บางแค | C14: 3186 | D14: 1587012.4 | E14: 1.06%
... A107: 105 | B107: คลังสินค้ารับคืน Yuedpao Online | C107: -3882 | D107: -1292284 | E107: -0.86%
B109: Exported by | C109: janjoncj@gmail.com
B110: Date Time | C110: 4/3/2026 10:19+07:00

Sheet ยอดขายปัจจุบัน
A1: ยอดขายรายคลัง|สาขา 1/2/2569 - 28/2/2569
A2: # | B2: คลัง|สาขา | C2: จำนวนรายการ | D2: ยอดขาย(บาท) | E2: ยอดขาย(%)
A3: 1 | B3: คลังสินค้า Yuedpao Online | C3: 250418 | D3: 84857273 | E3: 49.33% | H3: In Vat | I3: Ex Vat
A4: 2 | B4: Yuedpao สาขา Central หาดใหญ่ | C4: 6282 | D4: 2519620 | E4: 1.46% | F4: Yuedpao สาขา Central ระยอง | G4: {=_xlfn.XLOOKUP(F4,B:B,C:D,0,0)} -> 2478 | H4: 1286829.5 | I4: =H4*100/107 -> 1202644.4
A5: 3 | B5: Yuedpao สาขา Future Park Rangsit (Flagship store) | C5: 4120 | D5: 2127079.4 | E5: 1.24% | F5: Yuedpao สาขา Mega บางนา | G5: {=_xlfn.XLOOKUP(F5,B:B,C:D,0,0)} -> 1843 | H5: 982007.5 | I5: =H5*100/107 -> 917764.02
A6: 4 | B6: Yuedpao สาขา Central ลาดพร้าว | C6: 4333 | D6: 2090030.8 | E6: 1.21% | F6: Yuedpao สาขา MAYA เชียงใหม่ | G6: {=_xlfn.XLOOKUP(F6,B:B,C:D,0,0)} -> 3197 | H6: 1221787.5 | I6: =H6*100/107 -> 1141857.5
A7: 5 | B7: Yuedpao สาขา Central เวสต์เกต | C7: 3774 | D7: 2022108 | E7: 1.18% | F7: Yuedpao สาขา The Mall โคราช | G7: {=_xlfn.XLOOKUP(F7,B:B,C:D,0,0)} -> 1662 | H7: 784810.5 | I7: =H7*100/107 -> 733467.76
A8: 6 | B8: Yuedpao สาขา Central กระบี่ | C8: 3704 | D8: 1847713.5 | E8: 1.07% | F8: Yuedpao สาขา SIAM SQUARE | G8: {=_xlfn.XLOOKUP(F8,B:B,C:D,0,0)} -> 1757 | H8: 973986.2 | I8: =H8*100/107 -> 910267.48
A9: 7 | B9: Yuedpao สาขา Future Park Rangsit ชั้น 3 | C9: 3688 | D9: 1807232 | E9: 1.05% | F9: Yuedpao สาขา Robinson บุรีรัมย์ | G9: {=_xlfn.XLOOKUP(F9,B:B,C:D,0,0)} -> 1183 | H9: 575938 | I9: =H9*100/107 -> 538259.81
A10: 8 | B10: Yuedpao สาขา Fashion Island | C10: 3464 | D10: 1799497.9 | E10: 1.05% | F10: Yuedpao สาขา Central โคราช | G10: {=_xlfn.XLOOKUP(F10,B:B,C:D,0,0)} -> 1315 | H10: 610704.5 | I10: =H10*100/107 -> 570751.87
A11: 9 | B11: Yuedpao สาขา Central ปิ่นเกล้า | C11: 3737 | D11: 1737483.5 | E11: 1.01% | G11: {=_xlfn.XLOOKUP(F11,B:B,C:D,0,0)} -> 0 | H11: 0 | I11: =H11*100/107 -> 0
A12: 10 | B12: Yuedpao สาขา Central อุบลราชธานี | C12: 3263 | D12: 1668654 | E12: 0.97% | F12: Yuedpao สาขา Robinson ชลบุรี | G12: {=_xlfn.XLOOKUP(F12,B:B,C:D,0,0)} -> 2013 | H12: 920696.51 | I12: =H12*100/107 -> 860464.03
A13: 11 | B13: Yuedpao สาขา Central ขอนแก่น | C13: 3640 | D13: 1664499.2 | E13: 0.97% | F13: Yuedpao สาขา Central พัทยา | G13: {=_xlfn.XLOOKUP(F13,B:B,C:D,0,0)} -> 1252 | H13: 691868 | I13: =H13*100/107 -> 646605.61
A14: 12 | B14: Yuedpao สาขา The Mall บางแค | C14: 3162 | D14: 1579229.6 | E14: 0.92% | F14: Yuedpao สาขา Robinson แม่สอด | G14: {=_xlfn.XLOOKUP(F14,B:B,C:D,0,0)} -> 1408 | H14: 770581 | I14: =H14*100/107 -> 720169.16
A15: 13 | B15: Yuedpao สาขา The Mall บางกะปิ | C15: 3361 | D15: 1557003 | E15: 0.91% | F15: Yuedpao สาขา Future Park Rangsit ชั้น 3 | G15: {=_xlfn.XLOOKUP(F15,B:B,C:D,0,0)} -> 3688 | H15: 1807232 | I15: =H15*100/107 -> 1689001.9
A16: 14 | B16: Yuedpao สาขา Central สุราษฎร์ธานี | C16: 3265 | D16: 1549871.5 | E16: 0.9% | F16: Yuedpao สาขา Central ปิ่นเกล้า | G16: {=_xlfn.XLOOKUP(F16,B:B,C:D,0,0)} -> 3737 | H16: 1737483.5 | I16: =H16*100/107 -> 1623816.4
A17: 15 | B17: Yuedpao สาขา Robinson บ่อวิน | C17: 3229 | D17: 1527520 | E17: 0.89% | F17: Yuedpao สาขา Central Festival เชียงใหม่ | G17: {=_xlfn.XLOOKUP(F17,B:B,C:D,0,0)} -> 2259 | H17: 1159000.5 | I17: =H17*100/107 -> 1083178
A18: 16 | B18: Yuedpao สาขา Central พระราม 2 | C18: 3038 | D18: 1484213 | E18: 0.86% | F18: Yuedpao สาขา Big C อำนาจเจริญ | G18: {=_xlfn.XLOOKUP(F18,B:B,C:D,0,0)} -> 742 | H18: 384029.5 | I18: =H18*100/107 -> 358906.07
A19: 17 | B19: Yuedpao สาขา Central พิษณุโลก | C19: 2781 | D19: 1403772 | E19: 0.82% | F19: Yuedpao สาขา I am China Town | G19: {=_xlfn.XLOOKUP(F19,B:B,C:D,0,0)} -> 870 | H19: 396760.54 | I19: =H19*100/107 -> 370804.24
A20: 18 | B20: Yuedpao สาขา Robinson ถลาง ภูเก็ต | C20: 2630 | D20: 1391086 | E20: 0.81% | F20: Yuedpao สาขา Sermthai Complex มหาสารคาม | G20: {=_xlfn.XLOOKUP(F20,B:B,C:D,0,0)} -> 1705 | H20: 780394 | I20: =H20*100/107 -> 729340.19
A21: 19 | B21: Yuedpao สาขา Central ภูเก็ต | C21: 2689 | D21: 1363201.5 | E21: 0.79% | F21: Yuedpao สาขา Robinson กำแพงเพชร | G21: {=_xlfn.XLOOKUP(F21,B:B,C:D,0,0)} -> 0 | I21: =H21*100/107 -> 0
A22: 20 | B22: Yuedpao สาขา Central นครปฐม | C22: 2954 | D22: 1355399 | E22: 0.79%
A23: 21 | B23: Yuedpao สาขา Robinson ปราจีนบุรี | C23: 2576 | D23: 1329973 | E23: 0.77%
A24: 22 | B24: Yuedpao สาขา Central นครศรีธรรมราช | C24: 3017 | D24: 1324828 | E24: 0.77%
A25: 23 | B25: Yuedpao สาขา Central ระยอง | C25: 2478 | D25: 1286829.5 | E25: 0.75%
A26: 24 | B26: Yuedpao สาขา Central ศาลายา | C26: 2503 | D26: 1222613 | E26: 0.71%
A27: 25 | B27: Yuedpao สาขา MAYA เชียงใหม่ | C27: 3197 | D27: 1221787.5 | E27: 0.71%
A28: 26 | B28: Yuedpao สาขา Seacon Square ศรีนครินทร์ | C28: 2574 | D28: 1204375.5 | E28: 0.7%
A29: 27 | B29: Yuedpao สาขา Robinson ฉะเชิงเทรา | C29: 2256 | D29: 1199059 | E29: 0.7%
A30: 28 | B30: Yuedpao สาขา Robinson สระบุรี | C30: 2460 | D30: 1196967.3 | E30: 0.7%
A31: 29 | B31: Yuedpao สาขา Central อยุธยา | C31: 2414 | D31: 1180213.5 | E31: 0.69%
A32: 30 | B32: คลังลูกค้าส่ง Yuedpao | C32: 53 | D32: 1174800 | E32: 0.68%
A33: 31 | B33: Yuedpao สาขา Central Festival เชียงใหม่ | C33: 2259 | D33: 1159000.5 | E33: 0.67%
... A112: 110 | B112: คลังสินค้ารับคืน Yuedpao Online | C112: -4778 | D112: -1543509.5 | E112: -0.9%
B114: Exported by | C114: janjoncj@gmail.com
B115: Date Time | C115: 4/3/2026 10:17+07:00

Sheet year
B2: Performance group area
B3: KPI | C3: TARGET | D3: ปี 2025
D4: JAN | H4: FEB | L4: MAR | P4: APR | T4: MAY | X4: JUN | AB4: JUL | AF4: AUG | AJ4: SEP | AN4: OCT | AR4: NOV | AV4: DEC
D5: Ex.V7% | E5: %Target | F5: YoY | G5: Mom | H5: Ex.V7% | I5: %Target | J5: YoY | K5: Mom | L5: Ex.V7% | M5: %Target | N5: YoY | O5: Mom | P5: Ex.V7% | Q5: %Target | R5: YoY | S5: Mom | T5: Ex.V7% | U5: %Target | V5: YoY | W5: Mom | X5: Ex.V7% | Y5: %Target | Z5: YoY | AA5: Mom | AB5: Ex.V7% | AC5: %Target | AD5: YoY | AE5: Mom | AF5: Ex.V7% | AG5: %Target | AH5: YoY | AI5: Mom | AJ5: Ex.V7% | AK5: %Target | AL5: YoY | AM5: Mom | AN5: Ex.V7% | AO5: %Target | AP5: YoY | AQ5: Mom | AR5: Ex.V7% | AS5: %Target | AT5: YoY | AU5: Mom | AV5: Ex.V7% | AW5: %Target | AX5: YoY | AY5: Mom
B6: SALE OUT
B7: ALV SALE DAY | C7: 750000
B8: WEEK DAY | C8: 800000
B9: WEEK END | C9: 1000000
B10: ALV SALE | C10: 419
B11: STK HOLDING | C11: 1.00
B12: SURVAY | C12: 0.1
B13: MEMBER | C13: 0.1
B14: COMPLAIN | C14: 0
B15: CONVERSION | C15: 0.35
B16: INTERACTION | C16: 0.75
B17: GREETING | C17: 0.95
B18: ON TIME GREETING | C18: 0.7
B19: MANPOWER

Sheet Performance
B2: Performance group area
B3: KPI | C3: TARGET | D3: =Report!E1 -> 01-28 FEB 2026 | F3: ACHIEVE | G3: เปรียบเทียบปี | H3: เปรียบเทียบเดือน | J3: เปรียบเทียบสัปดาห์
D4: In Vat7% | E4: Ex Vat7%
B5: SALE OUT | C5: =Report!C21 -> 14900000 | D5: =Report!E21 -> 15084109 | E5: =Report!F21 -> 14097298 | F5: =E5/C5 -> 0.94612741 | G5: =Report!AD21 -> 0.66875025 | H5: =Report!AI21 -> -0.043029498 | J5: =Report!AP21 -> 0.10990775
B6: SALE OUT ESTIMATE | C6: =C5 -> 14900000 | D6: =Report!AW21 -> 13618716 | E6: =Report!AW20 -> 12727772 | F6: =Report!AX20 -> 1.0141651 | G6: =Report!AD20 -> 0.26563624 | H6: =Report!AI20 -> -0.049025037 | J6: =Report!AP20 -> 0.096931463
B7: ALV SALE DAY | C7: =C5/22 -> 677272.73 | D7: =E5/22 -> 640786.29 | F7: =D7/C7 -> 0.94612741
B8: WEEK DAY | C8: 600000 | D8: ='Week day&Week end'!AD21 -> 436239.44 | F8: =D8/C8 -> 0.72706573
B9: WEEK END | C9: 1000000 | D9: ='Week day&Week end'!AB21 -> 794895.07 | F9: =D9/C9 -> 0.79489507
B10: ALV SALE | C10: 423 | D10: =Report!H21 -> 491.79579 | F10: =Report!J21 -> 0.1398869
B11: STK HOLDING | C11: ='STK-เดือน.'!D20 -> 16295000 | D11: ='STK-เดือน.'!F20 -> 23804152 | F11: ='STK-เดือน.'!H20 -> 1.4608255
B12: SURVAY | C12: 0.1 | D12: ='Survay Member '!E21 -> 2956 | F12: ='Survay Member '!G21 -> 0.10558651
B13: MEMBER | C13: 0.1 | D13: ='Survay Member '!I21 -> 0 | F13: ='Survay Member '!K21 -> 0
B14: COMPLAIN | D14: 0 | H14: WoW | J14: MoM
B15: CONVERSION | C15: 0.35 | D15: 0.3116 | F15: =D15-C15 -> -0.0384 | H15: 0.3252 | I15: +1.57% | J15: 0.2917 | K15: =D15-J15 -> 0.0199
B16: INTERACTION | C16: 0.75 | D16: 0.7823 | F16: =D16-C16 -> 0.0323 | H16: 0.8186 | I16: +3.94% | J16: 0.7941 | K16: =D16-J16 -> -0.0118
B17: GREETING | C17: 0.95 | D17: 0.9199 | F17: =D17-C17 -> -0.0301 | H17: 0.9384 | I17: +2.54% | J17: 0.9336 | K17: =D17-J17 -> -0.0137
B18: ON TIME GREETING | C18: 0.7 | D18: 0.6599 | F18: =D18-C18 -> -0.0401 | H18: 0.6958 | I18: +4.92% | J18: 0.6948 | K18: =D18-J18 -> -0.0349
B19: MANPOWER | C19: 16/47 | D19: =MANPOWER!G20 -> 42 | F19: =D19/47 -> 0.89361702

Sheet Report
B1: TARGET +V7% | C1: TARGET | D1: TARGET | E1: 01-28 FEB 2026 | H1: AVE SALE / INV | I1: SALE INV Standard | J1: DIFT | K1: AVE SALE / DAY | L1: % TARGET | M1: Sale Estimate | N1: ขาดอีก ต่อวัน | X1: MIX SALE GROUP AREA | Y1: MIX SALE ALL GROUP | Z1: เปรียบเทียบรายปี | AE1: เปรียบเทียบรายเดือน | AJ1: เปรียบเทียบรายสัปดาห์ | AQ1: REMARK | AS1: SHOP | AT1: SALE OUT ESTIMATE | AY1: SALE OUT ESTIMATE +50%
A2: SHOP | B2: 1 | C2: 1 | D2: TO DAY | E2: ก่อนหัก VAT | F2: หลังหัก VAT | G2: IVN. | N2: คงเหลือ | O2: คงเหลือ/วัน | P2: achieve 100% | Q2: AVL Sale | R2: Estimate | S2: Achieve | T2: คงเหลือ 110 | U2: achieve 110% | V2: คงเหลือ 120 | W2: achieve 120% | Z2: 2023 | AA2: 2024 | AB2: 2025 | AC2: DIFT | AE2: SALE +7% | AF2: JAN'2026 | AG2: FEB'2026 | AH2: DIFT | AJ2: 26-01 | AK2: 02-08 | AL2: 09-15 | AM2: 16-22 | AN2: 23-01 | AO2: DIFT | AT2: Target | AU2: ยอดขาย | AV2: ยอดขายเฉลี่ยนต่อวัน | AW2: Sale Estimate | AX2: %Target | AY2: ยอดขายเฉลี่ยนต่อวัน | AZ2: Sale Estimate | BA2: %Target
A3: Yuedpao สาขา Mega บางนา | B3: =(C3*7)/100+C3 -> 963000 | C3: =_xlfn.XLOOKUP(A3,'Target ปี 2026'!B:B,'Target ปี 2026'!C:C,0,0) -> 900000 | D3: =C3/30 -> 30000 | E3: =_xlfn.XLOOKUP(A3,ยอดขายปัจจุบัน!B:B,ยอดขายปัจจุบัน!D:D,0,0) -> 982007.5 | F3: =E3*100/107 -> 917764.02 | G3: =_xlfn.XLOOKUP(A3,ยอดขายปัจจุบัน!B:B,ยอดขายปัจจุบัน!C:C,0,0) -> 1843 | H3: =E3/G3 -> 532.83098 | I3: 450 | J3: =(H3-I3)/H3 -> 0.15545452 | K3: =(E3-C3)/$E$36 -> 82007.5 | L3: =F3/C3 -> 1.0197378 | N3: =C3-F3 -> -17764.019 | O3: =N3/$E$36 -> -17764.019 | P3: =SUM(N3/$E$36) -> -17764.019 | Q3: =E3/$D$36 -> 35071.696 | R3: =Q3*22 -> 771577.32 | S3: =R3/C3 -> 0.85730813 | T3: =(C3-F3)*110% -> -19540.421 | U3: =T3/$E$36 -> -19540.421 | V3: =(C3-F3)*120% -> -21316.822 | W3: =SUM(V3/$E$36) -> -21316.822 | X3: =E3/$E$21 -> 0.065102121 | Y3: =E3/$H$36 -> #DIV/0! | Z3: =_xlfn.XLOOKUP(A3,ยอดขายปีที่แล้ว!B:B,ยอดขายปีที่แล้ว!D:D,0,0) -> 881171 | AA3: =Z3*100/107 -> 823524.3 | AB3: =F3 -> 917764.02 | AC3: =AB3-AA3 -> 94239.72 | AD3: =(AB3-AA3)/AA3 -> 0.11443466 | AE3: =_xlfn.XLOOKUP(A3,ยอดขายเดือนที่เแล้ว!B:B,ยอดขายเดือนที่เแล้ว!D:D,0,0) -> 1027144 | AF3: =AE3*100/107 -> 959947.66 | AG3: =F3 -> 917764.02 | AH3: =AG3-AF3 -> -42183.645 | AI3: =(AG3-AF3)/AF3 -> -0.043943692 | AJ3: 202720 | AK3: 221497 | AL3: 252707.5 | AM3: 269601 | AN3: 262322 | AO3: =AN3-AM3 -> -7279 | AP3: =(AN3-AM3)/AM3 -> -0.026999158 | AS3: =A3 -> Yuedpao สาขา Mega บางนา | AT3: =C3 -> 900000 | AU3: =F3 -> 917764.02 | AV3: =AU3/$D$36 -> 32777.286 | AW3: =(AV3*$E$36)+AU3 -> 950541.31 | AX3: =AW3/AT3 -> 1.056157 | AY3: =(AV3*50%)+AV3 -> 49165.93 | AZ3: =(AY3*$E$36)+AU3 -> 966929.95 | BA3: =AZ3/AT3 -> 1.0743666
A4: Yuedpao สาขา The Mall โคราช | B4: =(C4*7)/100+C4 -> 802500 | C4: =_xlfn.XLOOKUP(A4,'Target ปี 2026'!B:B,'Target ปี 2026'!C:C,0,0) -> 750000 | D4: =C4/30 -> 25000 | E4: =_xlfn.XLOOKUP(A4,ยอดขายปัจจุบัน!B:B,ยอดขายปัจจุบัน!D:D,0,0) -> 784810.5 | F4: =E4*100/107 -> 733467.76 | G4: =_xlfn.XLOOKUP(A4,ยอดขายปัจจุบัน!B:B,ยอดขายปัจจุบัน!C:C,0,0) -> 1662 | H4: =E4/G4 -> 472.20848 | I4: 450 | J4: =(H4-I4)/H4 -> 0.047031099 | K4: =(E4-C4)/$E$36 -> 34810.5 | L4: =F4/C4 -> 0.97795701 | N4: =C4-F4 -> 16532.243 | O4: =N4/$E$36 -> 16532.243 | P4: =SUM(N4/$E$36) -> 16532.243 | Q4: =E4/$D$36 -> 28028.946 | R4: =Q4*22 -> 616636.82 | S4: =R4/C4 -> 0.82218243 | T4: =(C4-F4)*110% -> 18185.467 | U4: =T4/$E$36 -> 18185.467 | V4: =(C4-F4)*120% -> 19838.692 | W4: =SUM(V4/$E$36) -> 19838.692 | X4: =E4/$E$21 -> 0.052028959 | Y4: =E4/$H$36 -> #DIV/0! | Z4: =_xlfn.XLOOKUP(A4,ยอดขายปีที่แล้ว!B:B,ยอดขายปีที่แล้ว!D:D,0,0) -> 661468 | AA4: =Z4*100/107 -> 618194.39 | AB4: =F4 -> 733467.76 | AC4: =AB4-AA4 -> 115273.36 | AD4: =(AB4-AA4)/AA4 -> 0.18646783 | AE4: =_xlfn.XLOOKUP(A4,ยอดขายเดือนที่เแล้ว!B:B,ยอดขายเดือนที่เแล้ว!D:D,0,0) -> 872878 | AF4: =AE4*100/107 -> 815773.83 | AG4: =F4 -> 733467.76 | AH4: =AG4-AF4 -> -82306.075 | AI4: =(AG4-AF4)/AF4 -> -0.10089325 | AJ4: 146290 | AK4: 171833 | AL4: 221080 | AM4: 189544 | AN4: 218411.5 | AO4: =AN4-AM4 -> 28867.5 | AP4: =(AN4-AM4)/AM4 -> 0.15229973 | AS4: =A4 -> Yuedpao สาขา The Mall โคราช | AT4: =C4 -> 750000 | AU4: =F4 -> 733467.76 | AV4: =AU4/$D$36 -> 26195.277 | AW4: =(AV4*$E$36)+AU4 -> 759663.03 | AX4: =AW4/AT4 -> 1.012884 | AY4: =(AV4*50%)+AV4 -> 39292.916 | AZ4: =(AY4*$E$36)+AU4 -> 772760.67 | BA4: =AZ4/AT4 -> 1.0303476
A5: Yuedpao สาขา SIAM SQUARE | B5: =(C5*7)/100+C5 -> 1016500 | C5: =_xlfn.XLOOKUP(A5,'Target ปี 2026'!B:B,'Target ปี 2026'!C:C,0,0) -> 950000 | D5: =C5/30 -> 31666.667 | E5: =_xlfn.XLOOKUP(A5,ยอดขายปัจจุบัน!B:B,ยอดขายปัจจุบัน!D:D,0,0) -> 973986.2 | F5: =E5*100/107 -> 910267.48 | G5: =_xlfn.XLOOKUP(A5,ยอดขายปัจจุบัน!B:B,ยอดขายปัจจุบัน!C:C,0,0) -> 1757 | H5: =E5/G5 -> 554.34616 | I5: 450 | J5: =(H5-I5)/H5 -> 0.18823285 | K5: =(E5-C5)/$E$36 -> 23986.2 | L5: =F5/C5 -> 0.95817629 | N5: =C5-F5 -> 39732.523 | O5: =N5/$E$36 -> 39732.523 | P5: =SUM(N5/$E$36) -> 39732.523 | Q5: =E5/$D$36 -> 34785.221 | R5: =Q5*22 -> 765274.87 | S5: =R5/C5 -> 0.8055525 | T5: =(C5-F5)*110% -> 43705.776 | U5: =T5/$E$36 -> 43705.776 | V5: =(C5-F5)*120% -> 47679.028 | W5: =SUM(V5/$E$36) -> 47679.028 | X5: =E5/$E$21 -> 0.064570349 | Y5: =E5/$H$36 -> #DIV/0! | Z5: =_xlfn.XLOOKUP(A5,ยอดขายปีที่แล้ว!B:B,ยอดขายปีที่แล้ว!D:D,0,0) -> 872143.25 | AA5: =Z5*100/107 -> 815087.15 | AB5: =F5 -> 910267.48 | AC5: =AB5-AA5 -> 95180.327 | AD5: =(AB5-AA5)/AA5 -> 0.11677319 | AE5: =_xlfn.XLOOKUP(A5,ยอดขายเดือนที่เแล้ว!B:B,ยอดขายเดือนที่เแล้ว!D:D,0,0) -> 945055.2 | AF5: =AE5*100/107 -> 883229.16 | AG5: =F5 -> 910267.48 | AH5: =AG5-AF5 -> 27038.318 | AI5: =(AG5-AF5)/AF5 -> 0.030613027 | AJ5: 182451 | AK5: 211906 | AL5: 239408 | AM5: 256643.2 | AN5: 263920 | AO5: =AN5-AM5 -> 7276.8 | AP5: =(AN5-AM5)/AM5 -> 0.028353761 | AS5: =A5 -> Yuedpao สาขา SIAM SQUARE | AT5: =C5 -> 950000 | AU5: =F5 -> 910267.48 | AV5: =AU5/$D$36 -> 32509.553 | AW5: =(AV5*$E$36)+AU5 -> 942777.03 | AX5: =AW5/AT5 -> 0.99239687 | AY5: =(AV5*50%)+AV5 -> 48764.329 | AZ5: =(AY5*$E$36)+AU5 -> 959031.81 | BA5: =AZ5/AT5 -> 1.0095072
A6: Yuedpao สาขา Central ระยอง | B6: =(C6*7)/100+C6 -> 1070000 | C6: =_xlfn.XLOOKUP(A6,'Target ปี 2026'!B:B,'Target ปี 2026'!C:C,0,0) -> 1000000 | D6: =C6/30 -> 33333.333 | E6: =_xlfn.XLOOKUP(A6,ยอดขายปัจจุบัน!B:B,ยอดขายปัจจุบัน!D:D,0,0) -> 1286829.5 | F6: =E6*100/107 -> 1202644.4 | G6: =_xlfn.XLOOKUP(A6,ยอดขายปัจจุบัน!B:B,ยอดขายปัจจุบัน!C:C,0,0) -> 2478 | H6: =E6/G6 -> 519.30165 | I6: 450 | J6: =(H6-I6)/H6 -> 0.13345163 | K6: =(E6-C6)/$E$36 -> 286829.5 | L6: =F6/C6 -> 1.2026444 | N6: =C6-F6 -> -202644.39 | O6: =N6/$E$36 -> -202644.39 | P6: =SUM(N6/$E$36) -> -202644.39 | Q6: =E6/$D$36 -> 45958.196 | R6: =Q6*22 -> 1011080.3 | S6: =R6/C6 -> 1.0110803 | T6: =(C6-F6)*110% -> -222908.83 | U6: =T6/$E$36 -> -222908.83 | V6: =(C6-F6)*120% -> -243173.27 | W6: =SUM(V6/$E$36) -> -243173.27 | X6: =E6/$E$21 -> 0.085310274 | Y6: =E6/$H$36 -> #DIV/0! | Z6: =_xlfn.XLOOKUP(A6,ยอดขายปีที่แล้ว!B:B,ยอดขายปีที่แล้ว!D:D,0,0) -> 978405 | AA6: =Z6*100/107 -> 914397.2 | AB6: =F6 -> 1202644.4 | AC6: =AB6-AA6 -> 288247.2 | AD6: =(AB6-AA6)/AA6 -> 0.31523193 | AE6: =_xlfn.XLOOKUP(A6,ยอดขายเดือนที่เแล้ว!B:B,ยอดขายเดือนที่เแล้ว!D:D,0,0) -> 1198422 | AF6: =AE6*100/107 -> 1120020.6 | AG6: =F6 -> 1202644.4 | AH6: =AG6-AF6 -> 82623.832 | AI6: =(AG6-AF6)/AF6 -> 0.073769924 | AJ6: 277084 | AK6: 301335 | AL6: 299940.5 | AM6: 337207 | AN6: 360601 | AO6: =AN6-AM6 -> 23394 | AP6: =(AN6-AM6)/AM6 -> 0.069375784 | AS6: =A6 -> Yuedpao สาขา Central ระยอง | AT6: =C6 -> 1000000 | AU6: =F6 -> 1202644.4 | AV6: =AU6/$D$36 -> 42951.585 | AW6: =(AV6*$E$36)+AU6 -> 1245596 | AX6: =AW6/AT6 -> 1.245596 | AY6: =(AV6*50%)+AV6 -> 64427.378 | AZ6: =(AY6*$E$36)+AU6 -> 1267071.8 | BA6: =AZ6/AT6 -> 1.2670718
A7: Yuedpao สาขา Central โคราช | B7: =(C7*7)/100+C7 -> 535000 | C7: =_xlfn.XLOOKUP(A7,'Target ปี 2026'!B:B,'Target ปี 2026'!C:C,0,0) -> 500000 | D7: =C7/30 -> 16666.667 | E7: =_xlfn.XLOOKUP(A7,ยอดขายปัจจุบัน!B:B,ยอดขายปัจจุบัน!D:D,0,0) -> 610704.5 | F7: =E7*100/107 -> 570751.87 | G7: =_xlfn.XLOOKUP(A7,ยอดขายปัจจุบัน!B:B,ยอดขายปัจจุบัน!C:C,0,0) -> 1315 | H7: =E7/G7 -> 464.41407 | I7: 450 | J7: =(H7-I7)/H7 -> 0.031037106 | K7: =(E7-C7)/$E$36 -> 110704.5 | L7: =F7/C7 -> 1.1415037 | N7: =C7-F7 -> -70751.869 | O7: =N7/$E$36 -> -70751.869 | P7: =SUM(N7/$E$36) -> -70751.869 | Q7: =E7/$D$36 -> 21810.875 | R7: =Q7*22 -> 479839.25 | S7: =R7/C7 -> 0.9596785 | T7: =(C7-F7)*110% -> -77827.056 | U7: =T7/$E$36 -> -77827.056 | V7: =(C7-F7)*120% -> -84902.243 | W7: =SUM(V7/$E$36) -> -84902.243 | X7: =E7/$E$21 -> 0.040486613 | Y7: =E7/$H$36 -> #DIV/0! | Z7: =_xlfn.XLOOKUP(A7,ยอดขายปีที่แล้ว!B:B,ยอดขายปีที่แล้ว!D:D,0,0) -> 374592 | AA7: =Z7*100/107 -> 350085.98 | AB7: =F7 -> 570751.87 | AC7: =AB7-AA7 -> 220665.89 | AD7: =(AB7-AA7)/AA7 -> 0.63031912 | AE7: =_xlfn.XLOOKUP(A7,ยอดขายเดือนที่เแล้ว!B:B,ยอดขายเดือนที่เแล้ว!D:D,0,0) -> 620565 | AF7: =AE7*100/107 -> 579967.29 | AG7: =F7 -> 570751.87 | AH7: =AG7-AF7 -> -9215.4206 | AI7: =(AG7-AF7)/AF7 -> -0.015889552 | AJ7: 122494 | AK7: 134410.5 | AL7: 167744 | AM7: 143604 | AN7: 165756 | AO7: =AN7-AM7 -> 22152 | AP7: =(AN7-AM7)/AM7 -> 0.15425754 | AS7: =A7 -> Yuedpao สาขา Central โคราช | AT7: =C7 -> 500000 | AU7: =F7 -> 570751.87 | AV7: =AU7/$D$36 -> 20383.995 | AW7: =(AV7*$E$36)+AU7 -> 591135.86 | AX7: =AW7/AT7 -> 1.1822717 | AY7: =(AV7*50%)+AV7 -> 30575.993 | AZ7: =(AY7*$E$36)+AU7 -> 601327.86 | BA7: =AZ7/AT7 -> 1.2026557
A8: Yuedpao สาขา Robinson บุรีรัมย์ | B8: =(C8*7)/100+C8 -> 535000 | C8: =_xlfn.XLOOKUP(A8,'Target ปี 2026'!B:B,'Target ปี 2026'!C:C,0,0) -> 500000 | D8: =C8/30 -> 16666.667 | E8: =_xlfn.XLOOKUP(A8,ยอดขายปัจจุบัน!B:B,ยอดขายปัจจุบัน!D:D,0,0) -> 575938 | F8: =E8*100/107 -> 538259.81 | G8: =_xlfn.XLOOKUP(A8,ยอดขายปัจจุบัน!B:B,ยอดขายปัจจุบัน!C:C,0,0) -> 1183 | H8: =E8/G8 -> 486.84531 | I8: 330 | J8: =(H8-I8)/H8 -> 0.32216662 | K8: =(E8-C8)/$E$36 -> 75938 | L8: =F8/C8 -> 1.0765196 | N8: =C8-F8 -> -38259.813 | O8: =N8/$E$36 -> -38259.813 | P8: =SUM(N8/$E$36) -> -38259.813 | Q8: =E8/$D$36 -> 20569.214 | R8: =Q8*22 -> 452522.71 | S8: =R8/C8 -> 0.90504543 | T8: =(C8-F8)*110% -> -42085.794 | U8: =T8/$E$36 -> -42085.794 | V8: =(C8-F8)*120% -> -45911.776 | W8: =SUM(V8/$E$36) -> -45911.776 | X8: =E8/$E$21 -> 0.038181771 | Y8: =E8/$H$36 -> #DIV/0! | Z8: =_xlfn.XLOOKUP(A8,ยอดขายปีที่แล้ว!B:B,ยอดขายปีที่แล้ว!D:D,0,0) -> 365093 | AA8: =Z8*100/107 -> 341208.41 | AB8: =F8 -> 538259.81 | AC8: =AB8-AA8 -> 197051.4 | AD8: =(AB8-AA8)/AA8 -> 0.57751039 | AE8: =_xlfn.XLOOKUP(A8,ยอดขายเดือนที่เแล้ว!B:B,ยอดขายเดือนที่เแล้ว!D:D,0,0) -> 629096 | AF8: =AE8*100/107 -> 587940.19 | AG8: =F8 -> 538259.81 | AH8: =AG8-AF8 -> -49680.374 | AI8: =(AG8-AF8)/AF8 -> -0.084499027 | AJ8: 97709 | AK8: 121420 | AL8: 158253 | AM8: 125354 | AN8: 187814 | AO8: =AN8-AM8 -> 62460 | AP8: =(AN8-AM8)/AM8 -> 0.4982689 | AS8: =A8 -> Yuedpao สาขา Robinson บุรีรัมย์ | AT8: =C8 -> 500000 | AU8: =F8 -> 538259.81 | AV8: =AU8/$D$36 -> 19223.565 | AW8: =(AV8*$E$36)+AU8 -> 557483.38 | AX8: =AW8/AT8 -> 1.1149668 | AY8: =(AV8*50%)+AV8 -> 28835.347 | AZ8: =(AY8*$E$36)+AU8 -> 567095.16 | BA8: =AZ8/AT8 -> 1.1341903
A9: Yuedpao สาขา MAYA เชียงใหม่ | B9: =(C9*7)/100+C9 -> 1070000 | C9: =_xlfn.XLOOKUP(A9,'Target ปี 2026'!B:B,'Target ปี 2026'!C:C,0,0) -> 1000000 | D9: =C9/30 -> 33333.333 | E9: =_xlfn.XLOOKUP(A9,ยอดขายปัจจุบัน!B:B,ยอดขายปัจจุบัน!D:D,0,0) -> 1221787.5 | F9: =E9*100/107 -> 1141857.5 | G9: =_xlfn.XLOOKUP(A9,ยอดขายปัจจุบัน!B:B,ยอดขายปัจจุบัน!C:C,0,0) -> 3197 | H9: =E9/G9 -> 382.16688 | I9: 450 | J9: =(H9-I9)/H9 -> -0.17749609 | K9: =(E9-C9)/$E$36 -> 221787.5 | L9: =F9/C9 -> 1.1418575 | N9: =C9-F9 -> -141857.48 | O9: =N9/$E$36 -> -141857.48 | P9: =SUM(N9/$E$36) -> -141857.48 | Q9: =E9/$D$36 -> 43635.268 | R9: =Q9*22 -> 959975.89 | S9: =R9/C9 -> 0.95997589 | T9: =(C9-F9)*110% -> -156043.22 | U9: =T9/$E$36 -> -156043.22 | V9: =(C9-F9)*120% -> -170228.97 | W9: =SUM(V9/$E$36) -> -170228.97 | X9: =E9/$E$21 -> 0.080998319 | Y9: =E9/$H$36 -> #DIV/0! | Z9: =_xlfn.XLOOKUP(A9,ยอดขายปีที่แล้ว!B:B,ยอดขายปีที่แล้ว!D:D,0,0) -> 952367.5 | AA9: =Z9*100/107 -> 890063.08 | AB9: =F9 -> 1141857.5 | AC9: =AB9-AA9 -> 251794.39 | AD9: =(AB9-AA9)/AA9 -> 0.282895 | AE9: =_xlfn.XLOOKUP(A9,ยอดขายเดือนที่เแล้ว!B:B,ยอดขายเดือนที่เแล้ว!D:D,0,0) -> 1474698 | AF9: =AE9*100/107 -> 1378222.4 | AG9: =F9 -> 1141857.5 | AH9: =AG9-AF9 -> -236364.95 | AI9: =(AG9-AF9)/AF9 -> -0.17149986 | AJ9: 303023 | AK9: 259680 | AL9: 312872 | AM9: 311095.5 | AN9: 332518 | AO9: =AN9-AM9 -> 21422.5 | AP9: =(AN9-AM9)/AM9 -> 0.068861491 | AS9: =A9 -> Yuedpao สาขา MAYA เชียงใหม่ | AT9: =C9 -> 1000000 | AU9: =F9 -> 1141857.5 | AV9: =AU9/$D$36 -> 40780.624 | AW9: =(AV9*$E$36)+AU9 -> 1182638.1 | AX9: =AW9/AT9 -> 1.1826381 | AY9: =(AV9*50%)+AV9 -> 61170.936 | AZ9: =(AY9*$E$36)+AU9 -> 1203028.4 | BA9: =AZ9/AT9 -> 1.2030284
A10: Exchange Store | AS10: Exchange Store
A11: Yuedpao สาขา Future Park Rangsit ชั้น 3 | B11: =(C11*7)/100+C11 -> 2354000 | C11: =_xlfn.XLOOKUP(A11,'Target ปี 2026'!B:B,'Target ปี 2026'!C:C,0,0) -> 2200000 | D11: =C11/30 -> 73333.333 | E11: =_xlfn.XLOOKUP(A11,ยอดขายปัจจุบัน!B:B,ยอดขายปัจจุบัน!D:D,0,0) -> 1807232 | F11: =E11*100/107 -> 1689001.9 | G11: =_xlfn.XLOOKUP(A11,ยอดขายปัจจุบัน!B:B,ยอดขายปัจจุบัน!C:C,0,0) -> 3688 | H11: =E11/G11 -> 490.03037 | I11: 400 | J11: =(H11-I11)/H11 -> 0.18372406 | K11: =(E11-C11)/$E$36 -> -392768 | L11: =F11/C11 -> 0.76772812 | N11: =C11-F11 -> 510998.13 | O11: =N11/$E$36 -> 510998.13 | P11: =SUM(N11/$E$36) -> 510998.13 | Q11: =E11/$D$36 -> 64544 | R11: =Q11*22 -> 1419968 | S11: =R11/C11 -> 0.64544 | T11: =(C11-F11)*110% -> 562097.94 | U11: =T11/$E$36 -> 562097.94 | V11: =(C11-F11)*120% -> 613197.76 | W11: =SUM(V11/$E$36) -> 613197.76 | X11: =E11/$E$21 -> 0.11981032 | Y11: =E11/$H$36 -> #DIV/0! | Z11: =_xlfn.XLOOKUP(A11,ยอดขายปีที่แล้ว!B:B,ยอดขายปีที่แล้ว!D:D,0,0) -> 1688582.5 | AA11: =Z11*100/107 -> 1578114.5 | AB11: =F11 -> 1689001.9 | AC11: =AB11-AA11 -> 110887.38 | AD11: =(AB11-AA11)/AA11 -> 0.070265741 | AE11: =_xlfn.XLOOKUP(A11,ยอดขายเดือนที่เแล้ว!B:B,ยอดขายเดือนที่เแล้ว!D:D,0,0) -> 2122760 | AF11: =AE11*100/107 -> 1983887.9 | AG11: =F11 -> 1689001.9 | AH11: =AG11-AF11 -> -294885.98 | AI11: =(AG11-AF11)/AF11 -> -0.14864045 | AJ11: 470624 | AK11: 398494 | AL11: 455916 | AM11: 445861 | AN11: 528581 | AO11: =AN11-AM11 -> 82720 | AP11: =(AN11-AM11)/AM11 -> 0.18552867 | AQ11: REROCATE 16 DEC 2025 | AS11: =A11 -> Yuedpao สาขา Future Park Rangsit ชั้น 3 | AT11: =C11 -> 2200000 | AU11: =F11 -> 1689001.9 | AV11: =AU11/$D$36 -> 60321.495 | AW11: =(AV11*$E$36)+AU11 -> 1749323.4 | AX11: =AW11/AT11 -> 0.79514698 | AY11: =(AV11*50%)+AV11 -> 90482.243 | AZ11: =(AY11*$E$36)+AU11 -> 1779484.1 | BA11: =AZ11/AT11 -> 0.80885641
A12: Yuedpao สาขา Central Festival เชียงใหม่ | B12: =(C12*7)/100+C12 -> 1284000 | C12: =_xlfn.XLOOKUP(A12,'Target ปี 2026'!B:B,'Target ปี 2026'!C:C,0,0) -> 1200000 | D12: =C12/30 -> 40000 | E12: =_xlfn.XLOOKUP(A12,ยอดขายปัจจุบัน!B:B,ยอดขายปัจจุบัน!D:D,0,0) -> 1159000.5 | F12: =E12*100/107 -> 1083178 | G12: =_xlfn.XLOOKUP(A12,ยอดขายปัจจุบัน!B:B,ยอดขายปัจจุบัน!C:C,0,0) -> 2259 | H12: =E12/G12 -> 513.0591 | I12: 401 | J12: =(H12-I12)/H12 -> 0.21841362 | K12: =(E12-C12)/$E$36 -> -40999.5 | L12: =F12/C12 -> 0.90264836 | N12: =C12-F12 -> 116821.96 | O12: =N12/$E$36 -> 116821.96 | P12: =SUM(N12/$E$36) -> 116821.96 | Q12: =E12/$D$36 -> 41392.875 | R12: =Q12*22 -> 910643.25 | S12: =R12/C12 -> 0.75886937 | T12: =(C12-F12)*110% -> 128504.16 | U12: =T12/$E$36 -> 128504.16 | V12: =(C12-F12)*120% -> 140186.36 | W12: =SUM(V12/$E$36) -> 140186.36 | X12: =E12/$E$21 -> 0.07683586 | Y12: =E12/$H$36 -> #DIV/0! | Z12: =_xlfn.XLOOKUP(A12,ยอดขายปีที่แล้ว!B:B,ยอดขายปีที่แล้ว!D:D,0,0) -> 914076 | AA12: =Z12*100/107 -> 854276.64 | AB12: =F12 -> 1083178 | AC12: =AB12-AA12 -> 228901.4 | AD12: =(AB12-AA12)/AA12 -> 0.26794763 | AE12: =_xlfn.XLOOKUP(A12,ยอดขายเดือนที่เแล้ว!B:B,ยอดขายเดือนที่เแล้ว!D:D,0,0) -> 1272433.8 | AF12: =AE12*100/107 -> 1189190.5 | AG12: =F12 -> 1083178 | AH12: =AG12-AF12 -> -106012.43 | AI12: =(AG12-AF12)/AF12 -> -0.08914672 | AJ12: 276515 | AK12: 225547.5 | AL12: 307428 | AM12: 309561 | AN12: 312550 | AO12: =AN12-AM12 -> 2989 | AP12: =(AN12-AM12)/AM12 -> 0.0096556091 | AQ12: REROCATE 01 DEC 2024 | AS12: =A12 -> Yuedpao สาขา Central Festival เชียงใหม่ | AT12: =C12 -> 1200000 | AU12: =F12 -> 1083178 | AV12: =AU12/$D$36 -> 38684.93 | AW12: =(AV12*$E$36)+AU12 -> 1121863 | AX12: =AW12/AT12 -> 0.93488581 | AY12: =(AV12*50%)+AV12 -> 58027.395 | AZ12: =(AY12*$E$36)+AU12 -> 1141205.4 | BA12: =AZ12/AT12 -> 0.95100453
A13: Yuedpao สาขา Central พัทยา | B13: =(C13*7)/100+C13 -> 642000 | C13: =_xlfn.XLOOKUP(A13,'Target ปี 2026'!B:B,'Target ปี 2026'!C:C,0,0) -> 600000 | D13: =C13/30 -> 20000 | E13: =_xlfn.XLOOKUP(A13,ยอดขายปัจจุบัน!B:B,ยอดขายปัจจุบัน!D:D,0,0) -> 691868 | F13: =E13*100/107 -> 646605.61 | G13: =_xlfn.XLOOKUP(A13,ยอดขายปัจจุบัน!B:B,ยอดขายปัจจุบัน!C:C,0,0) -> 1252 | H13: =E13/G13 -> 552.61022 | I13: 401 | J13: =(H13-I13)/H13 -> 0.27435291 | K13: =(E13-C13)/$E$36 -> 91868 | L13: =F13/C13 -> 1.077676 | N13: =C13-F13 -> -46605.607 | O13: =N13/$E$36 -> -46605.607 | P13: =SUM(N13/$E$36) -> -46605.607 | Q13: =E13/$D$36 -> 24709.571 | R13: =Q13*22 -> 543610.57 | S13: =R13/C13 -> 0.90601762 | T13: =(C13-F13)*110% -> -51266.168 | U13: =T13/$E$36 -> -51266.168 | V13: =(C13-F13)*120% -> -55926.729 | W13: =SUM(V13/$E$36) -> -55926.729 | X13: =E13/$E$21 -> 0.045867342 | Y13: =E13/$H$36 -> #DIV/0! | Z13: =_xlfn.XLOOKUP(A13,ยอดขายปีที่แล้ว!B:B,ยอดขายปีที่แล้ว!D:D,0,0) -> 483471 | AA13: =Z13*100/107 -> 451842.06 | AB13: =F13 -> 646605.61 | AC13: =AB13-AA13 -> 194763.55 | AD13: =(AB13-AA13)/AA13 -> 0.43104343 | AE13: =_xlfn.XLOOKUP(A13,ยอดขายเดือนที่เแล้ว!B:B,ยอดขายเดือนที่เแล้ว!D:D,0,0) -> 836250 | AF13: =AE13*100/107 -> 781542.06 | AG13: =F13 -> 646605.61 | AH13: =AG13-AF13 -> -134936.45 | AI13: =(AG13-AF13)/AF13 -> -0.17265411 | AJ13: 180426 | AK13: 154830 | AL13: 175702 | AM13: 154950 | AN13: 216852 | AO13: =AN13-AM13 -> 61902 | AP13: =(AN13-AM13)/AM13 -> 0.39949661 | AQ13: REROCATE 05 FEB 2024 | AS13: =A13 -> Yuedpao สาขา Central พัทยา | AT13: =C13 -> 600000 | AU13: =F13 -> 646605.61 | AV13: =AU13/$D$36 -> 23093.057 | AW13: =(AV13*$E$36)+AU13 -> 669698.66 | AX13: =AW13/AT13 -> 1.1161644 | AY13: =(AV13*50%)+AV13 -> 34639.586 | AZ13: =(AY13*$E$36)+AU13 -> 681245.19 | BA13: =AZ13/AT13 -> 1.1354087
A14: Yuedpao สาขา Central ปิ่นเกล้า | B14: =(C14*7)/100+C14 -> 1926000 | C14: =_xlfn.XLOOKUP(A14,'Target ปี 2026'!B:B,'Target ปี 2026'!C:C,0,0) -> 1800000 | D14: =C14/30 -> 60000 | E14: =_xlfn.XLOOKUP(A14,ยอดขายปัจจุบัน!B:B,ยอดขายปัจจุบัน!D:D,0,0) -> 1737483.5 | F14: =E14*100/107 -> 1623816.4 | G14: =_xlfn.XLOOKUP(A14,ยอดขายปัจจุบัน!B:B,ยอดขายปัจจุบัน!C:C,0,0) -> 3737 | H14: =E14/G14 -> 464.94073 | I14: 450 | J14: =(H14-I14)/H14 -> 0.032134694 | K14: =(E14-C14)/$E$36 -> -62516.5 | L14: =F14/C14 -> 0.9021202 | N14: =C14-F14 -> 176183.64 | O14: =N14/$E$36 -> 176183.64 | P14: =SUM(N14/$E$36) -> 176183.64 | Q14: =E14/$D$36 -> 62052.982 | R14: =Q14*22 -> 1365165.6 | S14: =R14/C14 -> 0.75842534 | T14: =(C14-F14)*110% -> 193802.01 | U14: =T14/$E$36 -> 193802.01 | V14: =(C14-F14)*120% -> 211420.37 | W14: =SUM(V14/$E$36) -> 211420.37 | X14: =E14/$E$21 -> 0.11518635 | Y14: =E14/$H$36 -> #DIV/0! | Z14: =_xlfn.XLOOKUP(A14,ยอดขายปีที่แล้ว!B:B,ยอดขายปีที่แล้ว!D:D,0,0) -> 867796 | AA14: =Z14*100/107 -> 811024.3 | AB14: =F14 -> 1623816.4 | AC14: =AB14-AA14 -> 812792.06 | AD14: =(AB14-AA14)/AA14 -> 1.0021797 | AE14: =_xlfn.XLOOKUP(A14,ยอดขายเดือนที่เแล้ว!B:B,ยอดขายเดือนที่เแล้ว!D:D,0,0) -> 1658515.5 | AF14: =AE14*100/107 -> 1550014.5 | AG14: =F14 -> 1623816.4 | AH14: =AG14-AF14 -> 73801.869 | AI14: =(AG14-AF14)/AF14 -> 0.047613664 | AJ14: 374127 | AK14: 385121.5 | AL14: 441054 | AM14: 421319 | AN14: 495445 | AO14: =AN14-AM14 -> 74126 | AP14: =(AN14-AM14)/AM14 -> 0.17593795 | AQ14: REROCATE 01 DEC 2024 | AS14: =A14 -> Yuedpao สาขา Central ปิ่นเกล้า | AT14: =C14 -> 1800000 | AU14: =F14 -> 1623816.4 | AV14: =AU14/$D$36 -> 57993.441 | AW14: =(AV14*$E$36)+AU14 -> 1681809.8 | AX14: =AW14/AT14 -> 0.93433878 | AY14: =(AV14*50%)+AV14 -> 86990.162 | AZ14: =(AY14*$E$36)+AU14 -> 1710806.5 | BA14: =AZ14/AT14 -> 0.95044807
A15: Yuedpao สาขา I am China Town | B15: =(C15*7)/100+C15 -> 374500 | C15: =_xlfn.XLOOKUP(A15,'Target ปี 2026'!B:B,'Target ปี 2026'!C:C,0,0) -> 350000 | D15: =C15/30 -> 11666.667 | E15: =_xlfn.XLOOKUP(A15,ยอดขายปัจจุบัน!B:B,ยอดขายปัจจุบัน!D:D,0,0) -> 396760.54 | F15: =E15*100/107 -> 370804.24 | G15: =_xlfn.XLOOKUP(A15,ยอดขายปัจจุบัน!B:B,ยอดขายปัจจุบัน!C:C,0,0) -> 870 | H15: =E15/G15 -> 456.0466 | I15: 430 | J15: =(H15-I15)/H15 -> 0.057113895 | K15: =(E15-C15)/$E$36 -> 46760.54 | L15: =F15/C15 -> 1.0594407 | N15: =C15-F15 -> -20804.243 | O15: =N15/$E$36 -> -20804.243 | P15: =SUM(N15/$E$36) -> -20804.243 | Q15: =E15/$D$36 -> 14170.019 | R15: =Q15*22 -> 311740.42 | S15: =R15/C15 -> 0.89068693 | T15: =(C15-F15)*110% -> -22884.667 | U15: =T15/$E$36 -> -22884.667 | V15: =(C15-F15)*120% -> -24965.092 | W15: =SUM(V15/$E$36) -> -24965.092 | X15: =E15/$E$21 -> 0.026303213 | Y15: =E15/$H$36 -> #DIV/0! | Z15: =_xlfn.XLOOKUP(A15,ยอดขายปีที่แล้ว!B:B,ยอดขายปีที่แล้ว!D:D,0,0) -> 0 | AA15: =Z15*100/107 -> 0 | AB15: =F15 -> 370804.24 | AC15: =AB15-AA15 -> 370804.24 | AD15: =(AB15-AA15)/AA15 -> #DIV/0! | AE15: =_xlfn.XLOOKUP(A15,ยอดขายเดือนที่เแล้ว!B:B,ยอดขายเดือนที่เแล้ว!D:D,0,0) -> 335396 | AF15: =AE15*100/107 -> 313454.21 | AG15: =F15 -> 370804.24 | AH15: =AG15-AF15 -> 57350.037 | AI15: =(AG15-AF15)/AF15 -> 0.18296145 | AJ15: 77675 | AK15: 78116 | AL15: 112553.54 | AM15: 124986 | AN15: 84540 | AO15: =AN15-AM15 -> -40446 | AP15: =(AN15-AM15)/AM15 -> -0.32360424 | AQ15: OPEN 01 JUN 2024 | AS15: =A15 -> Yuedpao สาขา I am China Town | AT15: =C15 -> 350000 | AU15: =F15 -> 370804.24 | AV15: =AU15/$D$36 -> 13243.009 | AW15: =(AV15*$E$36)+AU15 -> 384047.25 | AX15: =AW15/AT15 -> 1.0972779 | AY15: =(AV15*50%)+AV15 -> 19864.513 | AZ15: =(AY15*$E$36)+AU15 -> 390668.76 | BA15: =AZ15/AT15 -> 1.1161964
A16: Yuedpao สาขา Robinson ชลบุรี | B16: =(C16*7)/100+C16 -> 856000 | C16: =_xlfn.XLOOKUP(A16,'Target ปี 2026'!B:B,'Target ปี 2026'!C:C,0,0) -> 800000 | D16: =C16/30 -> 26666.667 | E16: =_xlfn.XLOOKUP(A16,ยอดขายปัจจุบัน!B:B,ยอดขายปัจจุบัน!D:D,0,0) -> 920696.51 | F16: =E16*100/107 -> 860464.03 | G16: =_xlfn.XLOOKUP(A16,ยอดขายปัจจุบัน!B:B,ยอดขายปัจจุบัน!C:C,0,0) -> 2013 | H16: =E16/G16 -> 457.37532 | I16: 430 | J16: =(H16-I16)/H16 -> 0.059853067 | K16: =(E16-C16)/$E$36 -> 120696.51 | L16: =F16/C16 -> 1.07558 | N16: =C16-F16 -> -60464.028 | O16: =N16/$E$36 -> -60464.028 | P16: =SUM(N16/$E$36) -> -60464.028 | Q16: =E16/$D$36 -> 32882.018 | R16: =Q16*22 -> 723404.4 | S16: =R16/C16 -> 0.9042555 | T16: =(C16-F16)*110% -> -66510.431 | U16: =T16/$E$36 -> -66510.431 | V16: =(C16-F16)*120% -> -72556.834 | W16: =SUM(V16/$E$36) -> -72556.834 | X16: =E16/$E$21 -> 0.061037513 | Y16: =E16/$H$36 -> #DIV/0! | Z16: =_xlfn.XLOOKUP(A16,ยอดขายปีที่แล้ว!B:B,ยอดขายปีที่แล้ว!D:D,0,0) -> 0 | AA16: =Z16*100/107 -> 0 | AB16: =F16 -> 860464.03 | AC16: =AB16-AA16 -> 860464.03 | AD16: =(AB16-AA16)/AA16 -> #DIV/0! | AE16: =_xlfn.XLOOKUP(A16,ยอดขายเดือนที่เแล้ว!B:B,ยอดขายเดือนที่เแล้ว!D:D,0,0) -> 907039 | AF16: =AE16*100/107 -> 847700 | AG16: =F16 -> 860464.03 | AH16: =AG16-AF16 -> 12764.028 | AI16: =(AG16-AF16)/AF16 -> 0.015057247 | AJ16: 184083 | AK16: 224899 | AL16: 255300 | AM16: 221141.51 | AN16: 230972 | AO16: =AN16-AM16 -> 9830.49 | AP16: =(AN16-AM16)/AM16 -> 0.044453391 | AQ16: OPEN 01 AUN 2024 | AS16: =A16 -> Yuedpao สาขา Robinson ชลบุรี | AT16: =C16 -> 800000 | AU16: =F16 -> 860464.03 | AV16: =AU16/$D$36 -> 30730.858 | AW16: =(AV16*$E$36)+AU16 -> 891194.89 | AX16: =AW16/AT16 -> 1.1139936 | AY16: =(AV16*50%)+AV16 -> 46096.287 | AZ16: =(AY16*$E$36)+AU16 -> 906560.32 | BA16: =AZ16/AT16 -> 1.1332004
A17: Yuedpao สาขา Big C อำนาจเจริญ | B17: =(C17*7)/100+C17 -> 588500 | C17: =_xlfn.XLOOKUP(A17,'Target ปี 2026'!B:B,'Target ปี 2026'!C:C,0,0) -> 550000 | D17: =C17/30 -> 18333.333 | E17: =_xlfn.XLOOKUP(A17,ยอดขายปัจจุบัน!B:B,ยอดขายปัจจุบัน!D:D,0,0) -> 384029.5 | F17: =E17*100/107 -> 358906.07 | G17: =_xlfn.XLOOKUP(A17,ยอดขายปัจจุบัน!B:B,ยอดขายปัจจุบัน!C:C,0,0) -> 742 | H17: =E17/G17 -> 517.55997 | I17: 431 | J17: =(H17-I17)/H17 -> 0.16724627 | K17: =(E17-C17)/$E$36 -> -165970.5 | L17: =F17/C17 -> 0.6525565 | N17: =C17-F17 -> 191093.93 | O17: =N17/$E$36 -> 191093.93 | P17: =SUM(N17/$E$36) -> 191093.93 | Q17: =E17/$D$36 -> 13715.339 | R17: =Q17*22 -> 301737.46 | S17: =R17/C17 -> 0.54861357 | T17: =(C17-F17)*110% -> 210203.32 | U17: =T17/$E$36 -> 210203.32 | V17: =(C17-F17)*120% -> 229312.71 | W17: =SUM(V17/$E$36) -> 229312.71 | X17: =E17/$E$21 -> 0.02545921 | Y17: =E17/$H$36 -> #DIV/0! | Z17: =_xlfn.XLOOKUP(A17,ยอดขายปีที่แล้ว!B:B,ยอดขายปีที่แล้ว!D:D,0,0) -> 0 | AA17: =Z17*100/107 -> 0 | AB17: =F17 -> 358906.07 | AC17: =AB17-AA17 -> 358906.07 | AD17: =(AB17-AA17)/AA17 -> #DIV/0! | AE17: =_xlfn.XLOOKUP(A17,ยอดขายเดือนที่เแล้ว!B:B,ยอดขายเดือนที่เแล้ว!D:D,0,0) -> 469734.5 | AF17: =AE17*100/107 -> 439004.21 | AG17: =F17 -> 358906.07 | AH17: =AG17-AF17 -> -80098.131 | AI17: =(AG17-AF17)/AF17 -> -0.18245413 | AJ17: 80623 | AK17: 106515 | AL17: 109432 | AM17: 89786.5 | AN17: 76512 | AO17: =AN17-AM17 -> -13274.5 | AP17: =(AN17-AM17)/AM17 -> -0.14784517 | AQ17: OPEN 15 NOV 2024 | AS17: =A17 -> Yuedpao สาขา Big C อำนาจเจริญ | AT17: =C17 -> 550000 | AU17: =F17 -> 358906.07 | AV17: =AU17/$D$36 -> 12818.074 | AW17: =(AV17*$E$36)+AU17 -> 371724.15 | AX17: =AW17/AT17 -> 0.67586209 | AY17: =(AV17*50%)+AV17 -> 19227.111 | AZ17: =(AY17*$E$36)+AU17 -> 378133.19 | BA17: =AZ17/AT17 -> 0.68751488
A18: Yuedpao สาขา Robinson แม่สอด | B18: =(C18*7)/100+C18 -> 856000 | C18: =_xlfn.XLOOKUP(A18,'Target ปี 2026'!B:B,'Target ปี 2026'!C:C,0,0) -> 800000 | D18: =C18/30 -> 26666.667 | E18: =_xlfn.XLOOKUP(A18,ยอดขายปัจจุบัน!B:B,ยอดขายปัจจุบัน!D:D,0,0) -> 770581 | F18: =E18*100/107 -> 720169.16 | G18: =_xlfn.XLOOKUP(A18,ยอดขายปัจจุบัน!B:B,ยอดขายปัจจุบัน!C:C,0,0) -> 1408 | H18: =E18/G18 -> 547.28764 | I18: 432 | J18: =(H18-I18)/H18 -> 0.21065274 | K18: =(E18-C18)/$E$36 -> -29419 | L18: =F18/C18 -> 0.90021145 | N18: =C18-F18 -> 79830.841 | O18: =N18/$E$36 -> 79830.841 | P18: =SUM(N18/$E$36) -> 79830.841 | Q18: =E18/$D$36 -> 27520.75 | R18: =Q18*22 -> 605456.5 | S18: =R18/C18 -> 0.75682063 | T18: =(C18-F18)*110% -> 87813.925 | U18: =T18/$E$36 -> 87813.925 | V18: =(C18-F18)*120% -> 95797.009 | W18: =SUM(V18/$E$36) -> 95797.009 | X18: =E18/$E$21 -> 0.051085615 | Y18: =E18/$H$36 -> #DIV/0! | Z18: =_xlfn.XLOOKUP(A18,ยอดขายปีที่แล้ว!B:B,ยอดขายปีที่แล้ว!D:D,0,0) -> 0 | AA18: =Z18*100/107 -> 0 | AB18: =F18 -> 720169.16 | AC18: =AB18-AA18 -> 720169.16 | AD18: =(AB18-AA18)/AA18 -> #DIV/0! | AE18: =_xlfn.XLOOKUP(A18,ยอดขายเดือนที่เแล้ว!B:B,ยอดขายเดือนที่เแล้ว!D:D,0,0) -> 734037.5 | AF18: =AE18*100/107 -> 686016.36 | AG18: =F18 -> 720169.16 | AH18: =AG18-AF18 -> 34152.804 | AI18: =(AG18-AF18)/AF18 -> 0.049784241 | AJ18: 139699.5 | AK18: 177658 | AL18: 220097 | AM18: 186551.5 | AN18: 199509.5 | AO18: =AN18-AM18 -> 12958 | AP18: =(AN18-AM18)/AM18 -> 0.069460712 | AQ18: OPEN 01 NOV 2024 | AS18: =A18 -> Yuedpao สาขา Robinson แม่สอด | AT18: =C18 -> 800000 | AU18: =F18 -> 720169.16 | AV18: =AU18/$D$36 -> 25720.327 | AW18: =(AV18*$E$36)+AU18 -> 745889.49 | AX18: =AW18/AT18 -> 0.93236186 | AY18: =(AV18*50%)+AV18 -> 38580.491 | AZ18: =(AY18*$E$36)+AU18 -> 758749.65 | BA18: =AZ18/AT18 -> 0.94843706
A19: Yuedpao สาขา Sermthai Complex มหาสารคาม | B19: =(C19*7)/100+C19 -> 1070000 | C19: =_xlfn.XLOOKUP(A19,'Target ปี 2026'!B:B,'Target ปี 2026'!C:C,0,0) -> 1000000 | D19: =C19/30 -> 33333.333 | E19: =_xlfn.XLOOKUP(A19,ยอดขายปัจจุบัน!B:B,ยอดขายปัจจุบัน!D:D,0,0) -> 780394 | F19: =E19*100/107 -> 729340.19 | G19: =_xlfn.XLOOKUP(A19,ยอดขายปัจจุบัน!B:B,ยอดขายปัจจุบัน!C:C,0,0) -> 1705 | H19: =E19/G19 -> 457.70909 | I19: 433 | J19: =(H19-I19)/H19 -> 0.053984269 | K19: =(E19-C19)/$E$36 -> -219606 | L19: =F19/C19 -> 0.72934019 | N19: =C19-F19 -> 270659.81 | O19: =N19/$E$36 -> 270659.81 | P19: =SUM(N19/$E$36) -> 270659.81 | Q19: =E19/$D$36 -> 27871.214 | R19: =Q19*22 -> 613166.71 | S19: =R19/C19 -> 0.61316671 | T19: =(C19-F19)*110% -> 297725.79 | U19: =T19/$E$36 -> 297725.79 | V19: =(C19-F19)*120% -> 324791.78 | W19: =SUM(V19/$E$36) -> 324791.78 | X19: =E19/$E$21 -> 0.051736167 | Y19: =E19/$H$36 -> #DIV/0! | Z19: =_xlfn.XLOOKUP(A19,ยอดขายปีที่แล้ว!B:B,ยอดขายปีที่แล้ว!D:D,0,0) -> 0 | AA19: =Z19*100/107 -> 0 | AB19: =F19 -> 729340.19 | AC19: =AB19-AA19 -> 729340.19 | AD19: =(AB19-AA19)/AA19 -> #DIV/0! | AE19: =_xlfn.XLOOKUP(A19,ยอดขายเดือนที่เแล้ว!B:B,ยอดขายเดือนที่เแล้ว!D:D,0,0) -> 658331 | AF19: =AE19*100/107 -> 615262.62 | AG19: =F19 -> 729340.19 | AH19: =AG19-AF19 -> 114077.57 | AI19: =(AG19-AF19)/AF19 -> 0.18541281 | AJ19: 133285 | AK19: 200440 | AL19: 207846 | AM19: 172229 | AN19: 210532 | AO19: =AN19-AM19 -> 38303 | AP19: =(AN19-AM19)/AM19 -> 0.22239576 | AQ19: OPEN 20 DEC 2024 | AS19: =A19 -> Yuedpao สาขา Sermthai Complex มหาสารคาม | AT19: =C19 -> 1000000 | AU19: =F19 -> 729340.19 | AV19: =AU19/$D$36 -> 26047.864 | AW19: =(AV19*$E$36)+AU19 -> 755388.05 | AX19: =AW19/AT19 -> 0.75538805 | AY19: =(AV19*50%)+AV19 -> 39071.796 | AZ19: =(AY19*$E$36)+AU19 -> 768411.98 | BA19: =AZ19/AT19 -> 0.76841198
A20: TOTAL SAME STORE | C20: =SUM(C3:C19) -> 14900000 | D20: =SUM(D3:D16) -> 418333.33 | E20: =SUM(E3:E19) -> 15084109 | F20: =SUM(F3:F19) -> 14097298 | G20: =SUM(G3:G16) -> 27254 | H20: =SUM(H3:H19)/16 -> 491.79579 | I20: 423 | J20: =(H20-I20)/H20 -> 0.1398869 | K20: =(E20-C20)/$E$36 -> 184109.25 | L20: =F20/C20 -> 0.94612741 | N20: =SUM(N3:N16) -> 261117.06 | O20: =SUM(O3:O15) -> 321581.08 | P20: =SUM(N20/$E$36) -> 261117.06 | Q20: =SUM(Q3:Q9) -> 229859.42 | R20: =SUM(R3:R9) -> 5056907.2 | S20: =SUM(S3:S9) -> 6.3208232 | T20: =SUM(T3:T9) -> -456514.08 | U20: =SUM(U3:U9) -> -456514.08 | V20: =SUM(V3:V9) -> -498015.36 | W20: =SUM(W3:W9) -> -498015.36 | X20: =E20/$E$20 -> 1 | Y20: =SUM(Y3:Y9) -> #DIV/0! | Z20: =SUM(Z3:Z9) -> 5085239.8 | AA20: =SUM(AA3:AA9) -> 4752560.5 | AB20: =SUM(AB3:AB9) -> 6015012.8 | AC20: =AB20-AA20 -> 1262452.3 | AD20: =(AB20-AA20)/AA20 -> 0.26563624 | AE20: =SUM(AE3:AE9) -> 6767858.2 | AF20: =SUM(AF3:AF9) -> 6325101.1 | AG20: =SUM(AG3:AG9) -> 6015012.8 | AH20: =AG20-AF20 -> -310088.32 | AI20: =(AG20-AF20)/AF20 -> -0.049025037 | AJ20: =SUM(AJ3:AJ9) -> 1331771 | AK20: =SUM(AK3:AK9) -> 1422081.5 | AL20: =SUM(AL3:AL9) -> 1652005 | AM20: =SUM(AM3:AM9) -> 1633048.7 | AN20: =SUM(AN3:AN9) -> 1791342.5 | AO20: =AN20-AM20 -> 158293.8 | AP20: =(AN20-AM20)/AM20 -> 0.096931463 | AS20: ยอดรวม | AT20: =SUM(AT3:AT16) -> 12550000 | AU20: =SUM(AU3:AU16) -> 12288883 | AV20: =AU20/$D$36 -> 438888.68 | AW20: =(AV20*$E$36)+AU20 -> 12727772 | AX20: =AW20/AT20 -> 1.0141651 | AY20: =(AV20*50%)+AV20 -> 658333.01 | AZ20: =(AY20*$E$36)+AU20 -> 12947216 | BA20: =AZ20/AT20 -> 1.0316507
A21: TOTAL ALL STORE | B21: =SUM(B3:B15) -> 12572500 | C21: =SUM(C3:C19) -> 14900000 | D21: =C21/31 -> 480645.16 | E21: =SUM(E3:E19) -> 15084109 | F21: =SUM(F3:F19) -> 14097298 | G21: =SUM(G3:G16) -> 27254 | H21: =SUM(H3:H19)/16 -> 491.79579 | I21: 423 | J21: =(H21-I21)/H21 -> 0.1398869 | K21: =(E21-C21)/$E$36 -> 184109.25 | L21: =F21/C21 -> 0.94612741 | N21: =SUM(N3:N16) -> 261117.06 | O21: =N21/$E$36 -> 261117.06 | P21: =SUM(N21/$E$36) -> 261117.06 | Q21: =E21/$D$36 -> 538718.19 | R21: =Q21*22 -> 11851800 | S21: =R21/C21 -> 0.79542283 | T21: =SUM(T3:T15) -> 353739.19 | U21: =T21/$E$36 -> 353739.19 | V21: =SUM(V3:V15) -> 385897.3 | W21: =SUM(V21/$E$36) -> 385897.3 | X21: =E21/$E$21 -> 1 | Y21: =E21/H36 -> #DIV/0! | Z21: =SUM(Z2:Z20) -> 14126428 | AA21: =SUM(AA3:AA19) -> 8447818 | AB21: =SUM(AB3:AB19) -> 14097298 | AC21: =AB21-AA21 -> 5649480.4 | AD21: =(AB21-AA21)/AA21 -> 0.66875025 | AE21: =SUM(AE3:AE16) -> 13900252 | AF21: =SUM(AF3:AF19) -> 14731173 | AG21: =SUM(AG3:AG19) -> 14097298 | AH21: =AG21-AF21 -> -633875 | AI21: =(AG21-AF21)/AF21 -> -0.043029498 | AJ21: =SUM(AJ3:AJ19) -> 3248828.5 | AK21: =SUM(AK3:AK19) -> 3373702.5 | AL21: =SUM(AL3:AL15) -> 3144658.5 | AM21: =SUM(AM3:AM15) -> 3089725.7 | AN21: =SUM(AN3:AN15) -> 3429310.5 | AO21: =AN21-AM21 -> 339584.8 | AP21: =(AN21-AM21)/AM21 -> 0.10990775 | AW21: =(AW20*7)/100+AW20 -> 13618716
E23: =SUM(E21-C21) -> 184109.25 | F23: =SUM(F21-C21) -> -802701.64 | K23: ขาดอีก | L23: =SUM(L21-100%) -> -0.053872593
C26: =C21-F21 -> 802701.64 | I26: =SUM(I3:I15) -> 5112 | J26: =I26/15 -> 340.8
W28: Yuedpao สาขา Fashion Island
W29: Yuedpao สาขา SIAM SQUARE
W30: Yuedpao สาขา Central Festival เชียงใหม่
W31: Yuedpao สาขา Central อุบลราชธานี
W32: Yuedpao สาขา Central เชียงใหม่แอร์พอร์ต
W33: Yuedpao สาขา The Mall บางกะปิ
D34: แก้ไขตัวเลข | H34: แก้ไขตัวเลข | W34: Yuedpao สาขา จตุจักรโครงการ 28
D35: วันนี้ | E35: วันคงเหลือ | H35: ยอดขายรวมทั้งหมด | W35: Yuedpao สาขา Central เชียงราย
D36: 28 | E36: =29-D36 -> 1 | W36: Yuedpao สาขา จตุจักรโครงการ 22 ริมถนน
W37: Yuedpao สาขา Central รามอินทรา
W38: Yuedpao สาขา Central นครสวรรค์
W39: Yuedpao สาขา จตุจักรโครงการ 6
W40: Yuedpao สาขา BTS สยาม
W41: Yuedpao สาขา BTS หมอชิต
W42: Yuedpao สาขา Robinson บุรีรัมย์
A43: สาขา | C43: TARGET | D43: SALE OUT
A44: Yuedpao สาขา Mega บางนา | C44: =C3 -> 900000 | D44: =E3 -> 982007.5
...

Sheet ALL SHOP
A1: สาขา | B1: TARGET | C1: SALE OUT | D1: SALE OUT | E1: %TARGET | F1: 2024 | G1: 2025 | H1: DIFT
A2: GENG | L2: Group Area | M2: Target | N2: Sale out | O2: % | P2: YoY
A3: Yuedpao สาขา Central ลาดพร้าว | B3: =_xlfn.XLOOKUP(A3,'Target ปี 2026'!B:B,'Target ปี 2026'!C:C,0,0) -> 1800000 | C3: =_xlfn.XLOOKUP(A3,ยอดขายปัจจุบัน!B:B,ยอดขายปัจจุบัน!D:D,0,0) -> 2090030.8 | D3: =C3*100/107 -> 1953299.8 | E3: =D3/B3 -> 1.0851666 | F3: =_xlfn.XLOOKUP(A3,ยอดขายปีที่แล้ว!B:B,ยอดขายปีที่แล้ว!D:D,0,0) -> 1698672 | G3: =_xlfn.XLOOKUP(A3,ยอดขายปัจจุบัน!B:B,ยอดขายปัจจุบัน!D:D,0,0) -> 2090030.8 | H3: =G3-F3 -> 391358.79 | I3: =(G3-F3)/F3 -> 0.23039103 | L3: =A2 -> GENG | M3: =B17 -> 18200000 | N3: =D17 -> 18686242 | O3: =E17 -> 1.0267166 | P3: =H17 -> 4387272.3 | Q3: =I17 -> 0.28110914
A4: Yuedpao สาขา Central ขอนแก่น | B4: =_xlfn.XLOOKUP(A4,'Target ปี 2026'!B:B,'Target ปี 2026'!C:C,0,0) -> 1500000 | C4: =_xlfn.XLOOKUP(A4,ยอดขายปัจจุบัน!B:B,ยอดขายปัจจุบัน!D:D,0,0) -> 1664499.2 | D4: =C4*100/107 -> 1555606.7 | E4: =D4/B4 -> 1.0370711 | F4: =_xlfn.XLOOKUP(A4,ยอดขายปีที่แล้ว!B:B,ยอดขายปีที่แล้ว!D:D,0,0) -> 1420659 | G4: =_xlfn.XLOOKUP(A4,ยอดขายปัจจุบัน!B:B,ยอดขายปัจจุบัน!D:D,0,0) -> 1664499.2 | H4: =G4-F4 -> 243840.16 | I4: =(G4-F4)/F4 -> 0.17163877 | L4: =A19 -> BOOM | M4: =B34 -> 14020000 | N4: =D34 -> 13034645 | O4: =E34 -> 0.92971793 | P4: =H34 -> 2730339.1 | Q4: =I34 -> 0.24341664
A5: Yuedpao สาขา Robinson บ่อวิน | B5: =_xlfn.XLOOKUP(A5,'Target ปี 2026'!B:B,'Target ปี 2026'!C:C,0,0) -> 1400000 | C5: =_xlfn.XLOOKUP(A5,ยอดขายปัจจุบัน!B:B,ยอดขายปัจจุบัน!D:D,0,0) -> 1527520 | D5: =C5*100/107 -> 1427588.8 | E5: =D5/B5 -> 1.0197063 | F5: =_xlfn.XLOOKUP(A5,ยอดขายปีที่แล้ว!B:B,ยอดขายปีที่แล้ว!D:D,0,0) -> 1288663.5 | G5: =_xlfn.XLOOKUP(A5,ยอดขายปัจจุบัน!B:B,ยอดขายปัจจุบัน!D:D,0,0) -> 1527520 | H5: =G5-F5 -> 238856.54 | I5: =(G5-F5)/F5 -> 0.18535215 | L5: =A36 -> BEN | M5: =B51 -> 14450000 | N5: =D51 -> 14797076 | O5: =E51 -> 1.0240191 | P5: =G51 -> 15832872 | Q5: =I51 -> 0.31878371
A6: Yuedpao สาขา Central พระราม 2 | B6: =_xlfn.XLOOKUP(A6,'Target ปี 2026'!B:B,'Target ปี 2026'!C:C,0,0) -> 1500000 | C6: =_xlfn.XLOOKUP(A6,ยอดขายปัจจุบัน!B:B,ยอดขายปัจจุบัน!D:D,0,0) -> 1484213 | D6: =C6*100/107 -> 1387115 | E6: =D6/B6 -> 0.9247433 | F6: =_xlfn.XLOOKUP(A6,ยอดขายปีที่แล้ว!B:B,ยอดขายปีที่แล้ว!D:D,0,0) -> 1401769.2 | G6: =_xlfn.XLOOKUP(A6,ยอดขายปัจจุบัน!B:B,ยอดขายปัจจุบัน!D:D,0,0) -> 1484213 | H6: =G6-F6 -> 82443.8 | I6: =(G6-F6)/F6 -> 0.058814104 | L6: =A53 -> PIM | M6: =B68 -> 11500000 | N6: =D68 -> 11505029 | O6: =E68 -> 1.0004373 | P6: =G68 -> 12310381 | Q6: =I68 -> 0.23791991
A7: Yuedpao สาขา Central พิษณุโลก | B7: =_xlfn.XLOOKUP(A7,'Target ปี 2026'!B:B,'Target ปี 2026'!C:C,0,0) -> 1200000 | C7: =_xlfn.XLOOKUP(A7,ยอดขายปัจจุบัน!B:B,ยอดขายปัจจุบัน!D:D,0,0) -> 1403772 | D7: =C7*100/107 -> 1311936.4 | E7: =D7/B7 -> 1.0932804 | F7: =_xlfn.XLOOKUP(A7,ยอดขายปีที่แล้ว!B:B,ยอดขายปีที่แล้ว!D:D,0,0) -> 1118056.5 | G7: =_xlfn.XLOOKUP(A7,ยอดขายปัจจุบัน!B:B,ยอดขายปัจจุบัน!D:D,0,0) -> 1403772 | H7: =G7-F7 -> 285715.5 | I7: =(G7-F7)/F7 -> 0.25554657 | L7: =A53 -> PIM | M7: =B84 -> 9300000 | N7: =D84 -> 9756024.5 | O7: =E84 -> 1.0490349 | P7: =H84 -> 3455181.8 | Q7: =I84 -> 0.49474488
A8: Yuedpao สาขา Robinson ฉะเชิงเทรา | B8: =_xlfn.XLOOKUP(A8,'Target ปี 2026'!B:B,'Target ปี 2026'!C:C,0,0) -> 1400000 | C8: =_xlfn.XLOOKUP(A8,ยอดขายปัจจุบัน!B:B,ยอดขายปัจจุบัน!D:D,0,0) -> 1199059 | D8: =C8*100/107 -> 1120615.9 | E8: =D8/B8 -> 0.80043992 | F8: =_xlfn.XLOOKUP(A8,ยอดขายปีที่แล้ว!B:B,ยอดขายปีที่แล้ว!D:D,0,0) -> 868644.6 | G8: =_xlfn.XLOOKUP(A8,ยอดขายปัจจุบัน!B:B,ยอดขายปัจจุบัน!D:D,0,0) -> 1199059 | H8: =G8-F8 -> 330414.4 | I8: =(G8-F8)/F8 -> 0.38037927
A9: Yuedpao สาขา Central มหาชัย | B9: =_xlfn.XLOOKUP(A9,'Target ปี 2026'!B:B,'Target ปี 2026'!C:C,0,0) -> 900000 | C9: =_xlfn.XLOOKUP(A9,ยอดขายปัจจุบัน!B:B,ยอดขายปัจจุบัน!D:D,0,0) -> 939354 | D9: =C9*100/107 -> 877900.93 | E9: =D9/B9 -> 0.97544548 | F9: =_xlfn.XLOOKUP(A9,ยอดขายปีที่แล้ว!B:B,ยอดขายปีที่แล้ว!D:D,0,0) -> 818065 | G9: =_xlfn.XLOOKUP(A9,ยอดขายปัจจุบัน!B:B,ยอดขายปัจจุบัน!D:D,0,0) -> 939354 | H9: =G9-F9 -> 121289 | I9: =(G9-F9)/F9 -> 0.14826328 | L9: All group | M9: =SUM(M3:M7) -> 67470000 | N9: =SUM(N3:N7) -> 67779018 | O9: =N9/M9 -> 1.0045801 | P9: =H86 -> 16765975 | Q9: =I86 -> 0.30069413
A10: Yuedpao สาขา Robinson บุรีรัมย์ | B10: =_xlfn.XLOOKUP(A10,'Target ปี 2026'!B:B,'Target ปี 2026'!C:C,0,0) -> 500000 | C10: =_xlfn.XLOOKUP(A10,ยอดขายปัจจุบัน!B:B,ยอดขายปัจจุบัน!D:D,0,0) -> 575938 | D10: =C10*100/107 -> 538259.81 | E10: =D10/B10 -> 1.0765196 | F10: =_xlfn.XLOOKUP(A10,ยอดขายปีที่แล้ว!B:B,ยอดขายปีที่แล้ว!D:D,0,0) -> 365093 | G10: =_xlfn.XLOOKUP(A10,ยอดขายปัจจุบัน!B:B,ยอดขายปัจจุบัน!D:D,0,0) -> 575938 | H10: =G10-F10 -> 210845 | I10: =(G10-F10)/F10 -> 0.57751039
A11: Yuedpao สาขา Central สุราษฎร์ธานี | B11: =_xlfn.XLOOKUP(A11,'Target ปี 2026'!B:B,'Target ปี 2026'!C:C,0,0) -> 1300000 | C11: =_xlfn.XLOOKUP(A11,ยอดขายปัจจุบัน!B:B,ยอดขายปัจจุบัน!D:D,0,0) -> 1549871.5 | D11: =C11*100/107 -> 1448478 | E11: =D11/B11 -> 1.1142139 | F11: =_xlfn.XLOOKUP(A11,ยอดขายปีที่แล้ว!B:B,ยอดขายปีที่แล้ว!D:D,0,0) -> 1262257.5 | G11: =_xlfn.XLOOKUP(A11,ยอดขายปัจจุบัน!B:B,ยอดขายปัจจุบัน!D:D,0,0) -> 1549871.5 | H11: =G11-F11 -> 287614.01 | I11: =(G11-F11)/F11 -> 0.22785684
A12: Yuedpao สาขา Passione Shopping Destination ระยอง | B12: =_xlfn.XLOOKUP(A12,'Target ปี 2026'!B:B,'Target ปี 2026'!C:C,0,0) -> 600000 | C12: =_xlfn.XLOOKUP(A12,ยอดขายปัจจุบัน!B:B,ยอดขายปัจจุบัน!D:D,0,0) -> 719550.5 | D12: =C12*100/107 -> 672477.1 | E12: =D12/B12 -> 1.1207952 | F12: =_xlfn.XLOOKUP(A12,ยอดขายปีที่แล้ว!B:B,ยอดขายปีที่แล้ว!D:D,0,0) -> 554429 | G12: =_xlfn.XLOOKUP(A12,ยอดขายปัจจุบัน!B:B,ยอดขายปัจจุบัน!D:D,0,0) -> 719550.5 | H12: =G12-F12 -> 165121.5 | I12: =(G12-F12)/F12 -> 0.29782262
A13: Yuedpao สาขา Future Park Rangsit (Flagship store) | B13: =_xlfn.XLOOKUP(A13,'Target ปี 2026'!B:B,'Target ปี 2026'!C:C,0,0) -> 1900000 | C13: =_xlfn.XLOOKUP(A13,ยอดขายปัจจุบัน!B:B,ยอดขายปัจจุบัน!D:D,0,0) -> 2127079.4 | D13: =C13*100/107 -> 1987924.7 | E13: =D13/B13 -> 1.0462761 | F13: =_xlfn.XLOOKUP(A13,ยอดขายปีที่แล้ว!B:B,ยอดขายปีที่แล้ว!D:D,0,0) -> 1624899.8 | G13: =_xlfn.XLOOKUP(A13,ยอดขายปัจจุบัน!B:B,ยอดขายปัจจุบัน!D:D,0,0) -> 2127079.4 | H13: =G13-F13 -> 502179.58 | I13: =(G13-F13)/F13 -> 0.30905264
A14: Yuedpao สาขา Seacon Square ศรีนครินทร์ | B14: =_xlfn.XLOOKUP(A14,'Target ปี 2026'!B:B,'Target ปี 2026'!C:C,0,0) -> 1000000 | C14: =_xlfn.XLOOKUP(A14,ยอดขายปัจจุบัน!B:B,ยอดขายปัจจุบัน!D:D,0,0) -> 1204375.5 | D14: =C14*100/107 -> 1125584.6 | E14: =D14/B14 -> 1.1255846 | F14: =_xlfn.XLOOKUP(A14,ยอดขายปีที่แล้ว!B:B,ยอดขายปีที่แล้ว!D:D,0,0) -> 957870 | G14: =_xlfn.XLOOKUP(A14,ยอดขายปัจจุบัน!B:B,ยอดขายปัจจุบัน!D:D,0,0) -> 1204375.5 | H14: =G14-F14 -> 246505.5 | I14: =(G14-F14)/F14 -> 0.25734755
A15: Yuedpao สาขา Central นครสวรรค์ | B15: =_xlfn.XLOOKUP(A15,'Target ปี 2026'!B:B,'Target ปี 2026'!C:C,0,0) -> 1000000 | C15: =_xlfn.XLOOKUP(A15,ยอดขายปัจจุบัน!B:B,ยอดขายปัจจุบัน!D:D,0,0) -> 989396.5 | D15: =C15*100/107 -> 924669.63 | E15: =D15/B15 -> 0.92466963 | F15: =_xlfn.XLOOKUP(A15,ยอดขายปีที่แล้ว!B:B,ยอดขายปีที่แล้ว!D:D,0,0) -> 831565 | G15: =_xlfn.XLOOKUP(A15,ยอดขายปัจจุบัน!B:B,ยอดขายปัจจุบัน!D:D,0,0) -> 989396.5 | H15: =G15-F15 -> 157831.5 | I15: =(G15-F15)/F15 -> 0.18980056
A16: Yuedpao สาขา Central หาดใหญ่ | B16: =_xlfn.XLOOKUP(A16,'Target ปี 2026'!B:B,'Target ปี 2026'!C:C,0,0) -> 2200000 | C16: =_xlfn.XLOOKUP(A16,ยอดขายปัจจุบัน!B:B,ยอดขายปัจจุบัน!D:D,0,0) -> 2519620 | D16: =C16*100/107 -> 2354785 | E16: =D16/B16 -> 1.0703568 | F16: =_xlfn.XLOOKUP(A16,ยอดขายปีที่แล้ว!B:B,ยอดขายปีที่แล้ว!D:D,0,0) -> 1396363 | G16: =_xlfn.XLOOKUP(A16,ยอดขายปัจจุบัน!B:B,ยอดขายปัจจุบัน!D:D,0,0) -> 2519620 | H16: =G16-F16 -> 1123257 | I16: =(G16-F16)/F16 -> 0.80441619
A17: Total | B17: =SUM(B3:B16) -> 18200000 | C17: =_xlfn.XLOOKUP(A17,ยอดขายปัจจุบัน!B:B,ยอดขายปัจจุบัน!D:D,0,0) -> 0 | D17: =SUM(D3:D16) -> 18686242 | E17: =D17/B17 -> 1.0267166 | F17: =SUM(F3:F16) -> 15607007 | G17: =SUM(G3:G16) -> 19994279 | H17: =G17-F17 -> 4387272.3 | I17: =(G17-F17)/F17 -> 0.28110914
C18: =_xlfn.XLOOKUP(A18,ยอดขายปัจจุบัน!B:B,ยอดขายปัจจุบัน!D:D,0,0) -> 0
A19: BOOM | C19: =_xlfn.XLOOKUP(A19,ยอดขายปัจจุบัน!B:B,ยอดขายปัจจุบัน!D:D,0,0) -> 0
A20: Yuedpao สาขา Future Park Rangsit ชั้น 3 | B20: =_xlfn.XLOOKUP(A20,'Target ปี 2026'!B:B,'Target ปี 2026'!C:C,0,0) -> 2200000 | C20: =_xlfn.XLOOKUP(A20,ยอดขายปัจจุบัน!B:B,ยอดขายปัจจุบัน!D:D,0,0) -> 1807232 | D20: =C20*100/107 -> 1689001.9 | E20: =D20/B20 -> 0.76772812 | F20: =_xlfn.XLOOKUP(A20,ยอดขายปีที่แล้ว!B:B,ยอดขายปีที่แล้ว!D:D,0,0) -> 1688582.5 | G20: =_xlfn.XLOOKUP(A20,ยอดขายปัจจุบัน!B:B,ยอดขายปัจจุบัน!D:D,0,0) -> 1807232 | H20: =G20-F20 -> 118649.5 | I20: =(G20-F20)/F20 -> 0.070265741
A21: Yuedpao สาขา Central เวสต์เกต | B21: =_xlfn.XLOOKUP(A21,'Target ปี 2026'!B:B,'Target ปี 2026'!C:C,0,0) -> 2000000 | C21: =_xlfn.XLOOKUP(A21,ยอดขายปัจจุบัน!B:B,ยอดขายปัจจุบัน!D:D,0,0) -> 2022108 | D21: =C21*100/107 -> 1889820.6 | E21: =D21/B21 -> 0.94491028 | F21: =_xlfn.XLOOKUP(A21,ยอดขายปีที่แล้ว!B:B,ยอดขายปีที่แล้ว!D:D,0,0) -> 1825624.5 | G21: =_xlfn.XLOOKUP(A21,ยอดขายปัจจุบัน!B:B,ยอดขายปัจจุบัน!D:D,0,0) -> 2022108 | H21: =G21-F21 -> 196483.5 | I21: =(G21-F21)/F21 -> 0.10762536
A22: Yuedpao สาขา Robinson ภูเก็ต | B22: =_xlfn.XLOOKUP(A22,'Target ปี 2026'!B:B,'Target ปี 2026'!C:C,0,0) -> 0 | C22: =_xlfn.XLOOKUP(A22,ยอดขายปัจจุบัน!B:B,ยอดขายปัจจุบัน!D:D,0,0) -> 0 | D22: =C22*100/107 -> 0 | E22: =D22/B22 -> #DIV/0! | F22: =_xlfn.XLOOKUP(A22,ยอดขายปีที่แล้ว!B:B,ยอดขายปีที่แล้ว!D:D,0,0) -> 0 | G22: =_xlfn.XLOOKUP(A22,ยอดขายปัจจุบัน!B:B,ยอดขายปัจจุบัน!D:D,0,0) -> 0 | H22: =G22-F22 -> 0 | I22: =(G22-F22)/F22 -> #DIV/0!
A23: Yuedpao สาขา Central ภูเก็ต | B23: =_xlfn.XLOOKUP(A23,'Target ปี 2026'!B:B,'Target ปี 2026'!C:C,0,0) -> 1200000 | C23: =_xlfn.XLOOKUP(A23,ยอดขายปัจจุบัน!B:B,ยอดขายปัจจุบัน!D:D,0,0) -> 1363201.5 | D23: =C23*100/107 -> 1274020.1 | E23: =D23/B23 -> 1.0616834 | F23: =_xlfn.XLOOKUP(A23,ยอดขายปีที่แล้ว!B:B,ยอดขายปีที่แล้ว!D:D,0,0) -> 1105513 | G23: =_xlfn.XLOOKUP(A23,ยอดขายปัจจุบัน!B:B,ยอดขายปัจจุบัน!D:D,0,0) -> 1363201.5 | H23: =G23-F23 -> 257688.5 | I23: =(G23-F23)/F23 -> 0.23309405
A24: Yuedpao สาขา The Mall บางแค | B24: =_xlfn.XLOOKUP(A24,'Target ปี 2026'!B:B,'Target ปี 2026'!C:C,0,0) -> 2200000 | C24: =_xlfn.XLOOKUP(A24,ยอดขายปัจจุบัน!B:B,ยอดขายปัจจุบัน!D:D,0,0) -> 1579229.6 | D24: =C24*100/107 -> 1475915.5 | E24: =D24/B24 -> 0.67087067 | F24: =_xlfn.XLOOKUP(A24,ยอดขายปีที่แล้ว!B:B,ยอดขายปีที่แล้ว!D:D,0,0) -> 971482 | G24: =_xlfn.XLOOKUP(A24,ยอดขายปัจจุบัน!B:B,ยอดขายปัจจุบัน!D:D,0,0) -> 1579229.6 | H24: =G24-F24 -> 607747.55 | I24: =(G24-F24)/F24 -> 0.62558807
A25: Yuedpao สาขา Central ระยอง | B25: =_xlfn.XLOOKUP(A25,'Target ปี 2026'!B:B,'Target ปี 2026'!C:C,0,0) -> 1000000 | C25: =_xlfn.XLOOKUP(A25,ยอดขายปัจจุบัน!B:B,ยอดขายปัจจุบัน!D:D,0,0) -> 1286829.5 | D25: =C25*100/107 -> 1202644.4 | E25: =D25/B25 -> 1.2026444 | F25: =_xlfn.XLOOKUP(A25,ยอดขายปีที่แล้ว!B:B,ยอดขายปีที่แล้ว!D:D,0,0) -> 978405 | G25: =_xlfn.XLOOKUP(A25,ยอดขายปัจจุบัน!B:B,ยอดขายปัจจุบัน!D:D,0,0) -> 1286829.5 | H25: =G25-F25 -> 308424.5 | I25: =(G25-F25)/F25 -> 0.31523193
A26: Yuedpao สาขา Robinson ฉลอง ภูเก็ต | B26: =_xlfn.XLOOKUP(A26,'Target ปี 2026'!B:B,'Target ปี 2026'!C:C,0,0) -> 650000 | C26: =_xlfn.XLOOKUP(A26,ยอดขายปัจจุบัน!B:B,ยอดขายปัจจุบัน!D:D,0,0) -> 638815 | D26: =C26*100/107 -> 597023.36 | E26: =D26/B26 -> 0.91849748 | F26: =_xlfn.XLOOKUP(A26,ยอดขายปีที่แล้ว!B:B,ยอดขายปีที่แล้ว!D:D,0,0) -> 368727 | G26: =_xlfn.XLOOKUP(A26,ยอดขายปัจจุบัน!B:B,ยอดขายปัจจุบัน!D:D,0,0) -> 638815 | H26: =G26-F26 -> 270088 | I26: =(G26-F26)/F26 -> 0.73248772
A27: Yuedpao สาขา Robinson ลพบุรี | B27: =_xlfn.XLOOKUP(A27,'Target ปี 2026'!B:B,'Target ปี 2026'!C:C,0,0) -> 950000 | C27: =_xlfn.XLOOKUP(A27,ยอดขายปัจจุบัน!B:B,ยอดขายปัจจุบัน!D:D,0,0) -> 979113.5 | D27: =C27*100/107 -> 915059.35 | E27: =D27/B27 -> 0.96322036 | F27: =_xlfn.XLOOKUP(A27,ยอดขายปีที่แล้ว!B:B,ยอดขายปีที่แล้ว!D:D,0,0) -> 825230.11 | G27: =_xlfn.XLOOKUP(A27,ยอดขายปัจจุบัน!B:B,ยอดขายปัจจุบัน!D:D,0,0) -> 979113.5 | H27: =G27-F27 -> 153883.39 | I27: =(G27-F27)/F27 -> 0.18647331
A28: Yuedpao สาขา Central World | B28: =_xlfn.XLOOKUP(A28,'Target ปี 2026'!B:B,'Target ปี 2026'!C:C,0,0) -> 650000 | C28: =_xlfn.XLOOKUP(A28,ยอดขายปัจจุบัน!B:B,ยอดขายปัจจุบัน!D:D,0,0) -> 669665 | D28: =C28*100/107 -> 625855.14 | E28: =D28/B28 -> 0.96285406 | F28: =_xlfn.XLOOKUP(A28,ยอดขายปีที่แล้ว!B:B,ยอดขายปีที่แล้ว!D:D,0,0) -> 613787 | G28: =_xlfn.XLOOKUP(A28,ยอดขายปัจจุบัน!B:B,ยอดขายปัจจุบัน!D:D,0,0) -> 669665 | H28: =G28-F28 -> 55878 | I28: =(G28-F28)/F28 -> 0.091038096
A29: Yuedpao สาขา Central จันทบุรี | B29: =_xlfn.XLOOKUP(A29,'Target ปี 2026'!B:B,'Target ปี 2026'!C:C,0,0) -> 900000 | C29: =_xlfn.XLOOKUP(A29,ยอดขายปัจจุบัน!B:B,ยอดขายปัจจุบัน!D:D,0,0) -> 814290.5 | D29: =C29*100/107 -> 761019.16 | E29: =D29/B29 -> 0.84557684 | F29: =_xlfn.XLOOKUP(A29,ยอดขายปีที่แล้ว!B:B,ยอดขายปีที่แล้ว!D:D,0,0) -> 947759.5 | G29: =_xlfn.XLOOKUP(A29,ยอดขายปัจจุบัน!B:B,ยอดขายปัจจุบัน!D:D,0,0) -> 814290.5 | H29: =G29-F29 -> -133469 | I29: =(G29-F29)/F29 -> -0.14082581
A30: Yuedpao สาขา Central พัทยา | B30: =_xlfn.XLOOKUP(A30,'Target ปี 2026'!B:B,'Target ปี 2026'!C:C,0,0) -> 600000 | C30: =_xlfn.XLOOKUP(A30,ยอดขายปัจจุบัน!B:B,ยอดขายปัจจุบัน!D:D,0,0) -> 691868 | D30: =C30*100/107 -> 646605.61 | E30: =D30/B30 -> 1.077676 | F30: =_xlfn.XLOOKUP(A30,ยอดขายปีที่แล้ว!B:B,ยอดขายปีที่แล้ว!D:D,0,0) -> 483471 | G30: =_xlfn.XLOOKUP(A30,ยอดขายปัจจุบัน!B:B,ยอดขายปัจจุบัน!D:D,0,0) -> 691868 | H30: =G30-F30 -> 208397 | I30: =(G30-F30)/F30 -> 0.43104343
A31: Yuedpao สาขา Central สมุย | B31: =_xlfn.XLOOKUP(A31,'Target ปี 2026'!B:B,'Target ปี 2026'!C:C,0,0) -> 700000 | C31: =_xlfn.XLOOKUP(A31,ยอดขายปัจจุบัน!B:B,ยอดขายปัจจุบัน!D:D,0,0) -> 765501 | D31: =C31*100/107 -> 715421.5 | E31: =D31/B31 -> 1.0220307 | F31: =_xlfn.XLOOKUP(A31,ยอดขายปีที่แล้ว!B:B,ยอดขายปีที่แล้ว!D:D,0,0) -> 924631.5 | G31: =_xlfn.XLOOKUP(A31,ยอดขายปัจจุบัน!B:B,ยอดขายปัจจุบัน!D:D,0,0) -> 765501 | H31: =G31-F31 -> -159130.5 | I31: =(G31-F31)/F31 -> -0.17210153
... A33: Yuedpao สาขา Big C ยะลา | B33: =_xlfn.XLOOKUP(A33,'Target ปี 2026'!B:B,'Target ปี 2026'!C:C,0,0) -> 500000 | C33: =_xlfn.XLOOKUP(A33,ยอดขายปัจจุบัน!B:B,ยอดขายปัจจุบัน!D:D,0,0) -> 633447 | D33: =C33*100/107 -> 592006.54 | E33: =D33/B33 -> 1.1840131 | F33: =_xlfn.XLOOKUP(A33,ยอดขายปีที่แล้ว!B:B,ยอดขายปีที่แล้ว!D:D,0,0) -> 483518.39 | G33: =_xlfn.XLOOKUP(A33,ยอดขายปัจจุบัน!B:B,ยอดขายปัจจุบัน!D:D,0,0) -> 633447 | H33: =G33-F33 -> 149928.61 | I33: =(G33-F33)/F33 -> 0.3100784
A34: Total | B34: =SUM(B20:B33) -> 14020000 | C34: =_xlfn.XLOOKUP(A34,ยอดขายปัจจุบัน!B:B,ยอดขายปัจจุบัน!D:D,0,0) -> 0 | D34: =SUM(D20:D33) -> 13034645 | E34: =D34/B34 -> 0.92971793 | F34: =SUM(F20:F33) -> 11216732 | G34: =SUM(G20:G33) -> 13947071 | H34: =G34-F34 -> 2730339.1 | I34: =(G34-F34)/F34 -> 0.24341664
C35: =_xlfn.XLOOKUP(A35,ยอดขายปัจจุบัน!B:B,ยอดขายปัจจุบัน!D:D,0,0) -> 0
A36: BEN | C36: =_xlfn.XLOOKUP(A36,ยอดขายปัจจุบัน!B:B,ยอดขายปัจจุบัน!D:D,0,0) -> 0
A37: Yuedpao สาขา Fashion Island | B37: =_xlfn.XLOOKUP(A37,'Target ปี 2026'!B:B,'Target ปี 2026'!C:C,0,0) -> 1800000 | C37: =_xlfn.XLOOKUP(A37,ยอดขายปัจจุบัน!B:B,ยอดขายปัจจุบัน!D:D,0,0) -> 1799497.9 | D37: =C37*100/107 -> 1681773.8 | E37: =D37/B37 -> 0.93431876 | F37: =_xlfn.XLOOKUP(A37,ยอดขายปีที่แล้ว!B:B,ยอดขายปีที่แล้ว!D:D,0,0) -> 1687356.5 | G37: =_xlfn.XLOOKUP(A37,ยอดขายปัจจุบัน!B:B,ยอดขายปัจจุบัน!D:D,0,0) -> 1799497.9 | H37: =G37-F37 -> 112141.43 | I37: =(G37-F37)/F37 -> 0.066459832
