Workbook

Sheet ยอดขายปีที่แล้ว
A1: ยอดขายรายคลัง|สาขา 1/4/2568 - 12/4/2568
A2: # | B2: คลัง|สาขา | C2: จำนวนรายการ | D2: ยอดขาย(บาท) | E2: ยอดขาย(%)
A3: 1 | B3: คลังสินค้า Yuedpao Online | C3: 50699 | D3: 19327544 | E3: 37.74%
A4: 2 | B4: Event Center one | C4: 1813 | D4: 1505280 | E4: 2.94%
A5: 3 | B5: Yuedpao สาขา Central เวสต์เกต | C5: 1783 | D5: 963108.05 | E5: 1.88%
A6: 4 | B6: Yuedpao สาขา Future Park Rangsit ชั้น 3 | C6: 1933 | D6: 910304 | E6: 1.78%
A7: 5 | B7: Yuedpao สาขา Fashion Island | C7: 1710 | D7: 884141 | E7: 1.73%
A8: 6 | B8: Yuedpao สาขา Future Park Rangsit (Flagship store) | C8: 1590 | D8: 833185 | E8: 1.63%
A9: 7 | B9: Yuedpao สาขา Robinson บ่อวิน | C9: 1680 | D9: 806741.5 | E9: 1.58%
A10: 8 | B10: Yuedpao สาขา Central ลาดพร้าว | C10: 1483 | D10: 777166 | E10: 1.52%
A11: 9 | B11: Yuedpao สาขา Central ขอนแก่น | C11: 1596 | D11: 723819 | E11: 1.41%
A12: 10 | B12: Yuedpao สาขา Central พระราม 2 | C12: 1400 | D12: 705838 | E12: 1.38%
A13: 11 | B13: Yuedpao สาขา Central หาดใหญ่ | C13: 1343 | D13: 674949 | E13: 1.32%
A14: 12 | B14: Yuedpao สาขา Central สุราษฎร์ธานี | C14: 1443 | D14: 663704.5 | E14: 1.3%
... A84: 82 | B84: คลังสินค้ารับคืน Yuedpao Online | C84: -549 | D84: -205905.31 | E84: -0.4%
B86: Exported by | C86: janjoncj@gmail.com
B87: Date Time | C87: 12/4/2026 18:57+07:00

Sheet ยอดขายเดือนที่เแล้ว
A1: ยอดขายรายคลัง|สาขา 1/3/2569 - 12/3/2569
A2: # | B2: คลัง|สาขา | C2: จำนวนรายการ | D2: ยอดขาย(บาท) | E2: ยอดขาย(%)
A3: 1 | B3: คลังสินค้า Yuedpao Online | C3: 122412 | D3: 43288871 | E3: 53.28%
A4: 2 | B4: Yuedpao สาขา Future Park Rangsit (Flagship store) | C4: 1902 | D4: 968008.67 | E4: 1.19%
A5: 3 | B5: Yuedpao สาขา Central ลาดพร้าว | C5: 1899 | D5: 964963.5 | E5: 1.19%
A6: 4 | B6: Yuedpao สาขา Central เวสต์เกต | C6: 1757 | D6: 946339.5 | E6: 1.16%
A7: 5 | B7: Yuedpao สาขา Future Park Rangsit ชั้น 3 | C7: 1850 | D7: 927365 | E7: 1.14%
A8: 6 | B8: Yuedpao สาขา Central หาดใหญ่ | C8: 2281 | D8: 864633 | E8: 1.06%
A9: 7 | B9: Event Major รัชโยธิน | C9: 2147 | D9: 863687 | E9: 1.06%
A10: 8 | B10: Yuedpao สาขา Fashion Island | C10: 1571 | D10: 849551 | E10: 1.05%
A11: 9 | B11: Yuedpao สาขา Robinson บ่อวิน | C11: 1665 | D11: 793305 | E11: 0.98%
A12: 10 | B12: Yuedpao สาขา Central อุบลราชธานี | C12: 1588 | D12: 792225.5 | E12: 0.97%
A13: 11 | B13: Yuedpao สาขา Central ขอนแก่น | C13: 1534 | D13: 755866.07 | E13: 0.93%
A14: 12 | B14: Yuedpao สาขา Central ปิ่นเกล้า | C14: 1639 | D14: 744628 | E14: 0.92%
... A99: 97 | B99: คลังสินค้ารับคืน Yuedpao Online | C99: -2838 | D99: -931091.2 | E99: -1.15%
B101: Exported by | C101: janjoncj@gmail.com
B102: Date Time | C102: 12/4/2026 18:59+07:00

Sheet ยอดขายปัจจุบัน
A1: ยอดขายรายคลัง|สาขา 1/4/2569 - 12/4/2569
A2: # | B2: คลัง|สาขา | C2: จำนวนรายการ | D2: ยอดขาย(บาท) | E2: ยอดขาย(%)
A3: 1 | B3: คลังสินค้า Yuedpao Online | C3: 133150 | D3: 45225434 | E3: 48.04%
A4: 2 | B4: Yuedpao สาขา Central เวสต์เกต | C4: 2360 | D4: 1289499 | E4: 1.37%
A5: 3 | B5: Yuedpao สาขา Central หาดใหญ่ | C5: 3546 | D5: 1267900 | E5: 1.35%
A6: 4 | B6: Yuedpao สาขา Future Park Rangsit (Flagship store) | C6: 2341 | D6: 1175755 | E6: 1.25%
A7: 5 | B7: Yuedpao สาขา Future Park Rangsit ชั้น 3 | C7: 2315 | D7: 1165653 | E7: 1.24%
A8: 6 | B8: Yuedpao สาขา Fashion Island | C8: 2269 | D8: 1143050.6 | E8: 1.21%
A9: 7 | B9: Yuedpao สาขา Central ลาดพร้าว | C9: 2303 | D9: 1125942.6 | E9: 1.2%
A10: 8 | B10: Yuedpao สาขา The Mall บางแค | C10: 2143 | D10: 1112666 | E10: 1.18%
A11: 9 | B11: Yuedpao สาขา Central ขอนแก่น | C11: 2156 | D11: 1001652 | E11: 1.06%
A12: 10 | B12: Yuedpao สาขา Central อุบลราชธานี | C12: 1924 | D12: 965406.75 | E12: 1.03%
A13: 11 | B13: Yuedpao สาขา Central ปิ่นเกล้า | C13: 1970 | D13: 933072.5 | E13: 0.99%
A14: 12 | B14: Yuedpao สาขา The Mall งามวงศ์วาน | C14: 1940 | D14: 923136.5 | E14: 0.98%
... A102: 100 | B102: คลังสินค้ารับคืน Yuedpao Online | C102: -3194 | D102: -1067134.5 | E102: -1.13%
B104: Exported by | C104: janjoncj@gmail.com
B105: Date Time | C105: 13/4/2026 11:27+07:00

Sheet Report
B1: TARGET +V7% | C1: TARGET | D1: TARGET | E1: 01-12 APR 2026 | H1: AVE SALE / INV | I1: SALE INV Standard | J1: DIFT | K1: AVE SALE / DAY | L1: % TARGET | M1: Sale Estimate | N1: ขาดอีก ต่อวัน | X1: MIX SALE GROUP AREA | Y1: MIX SALE ALL GROUP | Z1: เปรียบเทียบรายปี | AE1: เปรียบเทียบรายเดือน | AJ1: เปรียบเทียบรายสัปดาห์ | AQ1: REMARK | AS1: SHOP | AT1: SALE OUT ESTIMATE | AY1: SALE OUT ESTIMATE +50%
A2: SHOP | B2: 1 | C2: 1 | D2: TO DAY | E2: ก่อนหัก VAT | F2: หลังหัก VAT | G2: IVN. | N2: คงเหลือ | O2: คงเหลือ/วัน | P2: achieve 100% | Q2: AVL Sale | R2: Estimate | S2: Achieve | T2: คงเหลือ 110 | U2: achieve 110% | V2: คงเหลือ 120 | W2: achieve 120% | Z2: 2023 | AA2: 2024 | AB2: 2025 | AC2: DIFT | AE2: SALE +7% | AF2: MAR'2026 | AG2: APR'2026 | AH2: DIFT | AJ2: 23-29 | AK2: 30-05 | AO2: DIFT | AT2: Target | AU2: ยอดขาย | AV2: ยอดขายเฉลี่ยนต่อวัน | AW2: Sale Estimate | AX2: %Target | AY2: ยอดขายเฉลี่ยนต่อวัน | AZ2: Sale Estimate | BA2: %Target
A3: Yuedpao สาขา Mega บางนา | B3: =(C3*7)/100+C3 -> 1294700 | C3: =_xlfn.XLOOKUP(A3,'Target ปี 2026'!B:B,'Target ปี 2026'!C:C,0,0) -> 1210000 | D3: =C3/30 -> 40333.333 | E3: =_xlfn.XLOOKUP(A3,ยอดขายปัจจุบัน!B:B,ยอดขายปัจจุบัน!D:D,0,0) -> 505586.5 | F3: =E3*100/107 -> 472510.75 | G3: =_xlfn.XLOOKUP(A3,ยอดขายปัจจุบัน!B:B,ยอดขายปัจจุบัน!C:C,0,0) -> 930 | H3: =E3/G3 -> 543.6414 | I3: 450 | J3: =(H3-I3)/H3 -> 0.17224847 | K3: =(E3-C3)/$E$35 -> -37074.395 | L3: =F3/C3 -> 0.39050475 | N3: =C3-F3 -> 737489.25 | O3: =N3/$E$35 -> 38815.224 | P3: =SUM(N3/$E$35) -> 38815.224 | Q3: =E3/$D$35 -> 42132.208 | R3: =Q3*22 -> 926908.58 | S3: =R3/C3 -> 0.76604015 | T3: =(C3-F3)*110% -> 811238.18 | U3: =T3/$E$35 -> 42696.746 | V3: =(C3-F3)*120% -> 884987.1 | W3: =SUM(V3/$E$35) -> 46578.269 | X3: =E3/$E$20 -> 0.065332187 | Y3: =E3/$H$35 -> #DIV/0! | Z3: =_xlfn.XLOOKUP(A3,ยอดขายปีที่แล้ว!B:B,ยอดขายปีที่แล้ว!D:D,0,0) -> 488435 | AA3: =Z3*100/107 -> 456481.31 | AB3: =F3 -> 472510.75 | AC3: =AB3-AA3 -> 16029.439 | AD3: =(AB3-AA3)/AA3 -> 0.035115215 | AE3: =_xlfn.XLOOKUP(A3,ยอดขายเดือนที่เแล้ว!B:B,ยอดขายเดือนที่เแล้ว!D:D,0,0) -> 429198 | AF3: =AE3*100/107 -> 401119.63 | AG3: =F3 -> 472510.75 | AH3: =AG3-AF3 -> 71391.121 | AI3: =(AG3-AF3)/AF3 -> 0.17797963 | AJ3: 236620 | AK3: 265632 | AO3: =AK3-AJ3 -> 29012 | AP3: =(AK3-AJ3)/AJ3 -> 0.12261009 | AS3: =A3 -> Yuedpao สาขา Mega บางนา | AT3: =C3 -> 1210000 | AU3: =F3 -> 472510.75 | AV3: =AU3/$D$35 -> 39375.896 | AW3: =(AV3*$E$35)+AU3 -> 1220652.8 | AX3: =AW3/AT3 -> 1.0088039 | AY3: =(AV3*50%)+AV3 -> 59063.843 | AZ3: =(AY3*$E$35)+AU3 -> 1594723.8 | BA3: =AZ3/AT3 -> 1.3179535
A4: Yuedpao สาขา The Mall โคราช | B4: =(C4*7)/100+C4 -> 1177000 | C4: =_xlfn.XLOOKUP(A4,'Target ปี 2026'!B:B,'Target ปี 2026'!C:C,0,0) -> 1100000 | D4: =C4/30 -> 36666.667 | E4: =_xlfn.XLOOKUP(A4,ยอดขายปัจจุบัน!B:B,ยอดขายปัจจุบัน!D:D,0,0) -> 506978 | F4: =E4*100/107 -> 473811.21 | G4: =_xlfn.XLOOKUP(A4,ยอดขายปัจจุบัน!B:B,ยอดขายปัจจุบัน!C:C,0,0) -> 1044 | H4: =E4/G4 -> 485.61111 | I4: 450 | J4: =(H4-I4)/H4 -> 0.073332571 | K4: =(E4-C4)/$E$35 -> -31211.684 | L4: =F4/C4 -> 0.43073747 | N4: =C4-F4 -> 626188.79 | O4: =N4/$E$35 -> 32957.304 | P4: =SUM(N4/$E$35) -> 32957.304 | Q4: =E4/$D$35 -> 42248.167 | R4: =Q4*22 -> 929459.67 | S4: =R4/C4 -> 0.84496333 | T4: =(C4-F4)*110% -> 688807.66 | U4: =T4/$E$35 -> 36253.035 | V4: =(C4-F4)*120% -> 751426.54 | W4: =SUM(V4/$E$35) -> 39548.765 | X4: =E4/$E$20 -> 0.065511998 | Y4: =E4/$H$35 -> #DIV/0! | Z4: =_xlfn.XLOOKUP(A4,ยอดขายปีที่แล้ว!B:B,ยอดขายปีที่แล้ว!D:D,0,0) -> 305077 | AA4: =Z4*100/107 -> 285118.69 | AB4: =F4 -> 473811.21 | AC4: =AB4-AA4 -> 188692.52 | AD4: =(AB4-AA4)/AA4 -> 0.66180341 | AE4: =_xlfn.XLOOKUP(A4,ยอดขายเดือนที่เแล้ว!B:B,ยอดขายเดือนที่เแล้ว!D:D,0,0) -> 358158.5 | AF4: =AE4*100/107 -> 334727.57 | AG4: =F4 -> 473811.21 | AH4: =AG4-AF4 -> 139083.64 | AI4: =(AG4-AF4)/AF4 -> 0.41551296 | AJ4: 258956 | AK4: 253022 | AO4: =AK4-AJ4 -> -5934 | AP4: =(AK4-AJ4)/AJ4 -> -0.02291509 | AS4: =A4 -> Yuedpao สาขา The Mall โคราช | AT4: =C4 -> 1100000 | AU4: =F4 -> 473811.21 | AV4: =AU4/$D$35 -> 39484.268 | AW4: =(AV4*$E$35)+AU4 -> 1224012.3 | AX4: =AW4/AT4 -> 1.1127385 | AY4: =(AV4*50%)+AV4 -> 59226.402 | AZ4: =(AY4*$E$35)+AU4 -> 1599112.9 | BA4: =AZ4/AT4 -> 1.453739
A5: Yuedpao สาขา SIAM SQUARE | B5: =(C5*7)/100+C5 -> 1177000 | C5: =_xlfn.XLOOKUP(A5,'Target ปี 2026'!B:B,'Target ปี 2026'!C:C,0,0) -> 1100000 | D5: =C5/30 -> 36666.667 | E5: =_xlfn.XLOOKUP(A5,ยอดขายปัจจุบัน!B:B,ยอดขายปัจจุบัน!D:D,0,0) -> 512683.7 | F5: =E5*100/107 -> 479143.64 | G5: =_xlfn.XLOOKUP(A5,ยอดขายปัจจุบัน!B:B,ยอดขายปัจจุบัน!C:C,0,0) -> 985 | H5: =E5/G5 -> 520.49107 | I5: 450 | J5: =(H5-I5)/H5 -> 0.13543185 | K5: =(E5-C5)/$E$35 -> -30911.384 | L5: =F5/C5 -> 0.43558513 | N5: =C5-F5 -> 620856.36 | O5: =N5/$E$35 -> 32676.65 | P5: =SUM(N5/$E$35) -> 32676.65 | Q5: =E5/$D$35 -> 42723.642 | R5: =Q5*22 -> 939920.12 | S5: =R5/C5 -> 0.85447283 | T5: =(C5-F5)*110% -> 682941.99 | U5: =T5/$E$35 -> 35944.315 | V5: =(C5-F5)*120% -> 745027.63 | W5: =SUM(V5/$E$35) -> 39211.98 | X5: =E5/$E$20 -> 0.066249292 | Y5: =E5/$H$35 -> #DIV/0! | Z5: =_xlfn.XLOOKUP(A5,ยอดขายปีที่แล้ว!B:B,ยอดขายปีที่แล้ว!D:D,0,0) -> 422991.2 | AA5: =Z5*100/107 -> 395318.88 | AB5: =F5 -> 479143.64 | AC5: =AB5-AA5 -> 83824.766 | AD5: =(AB5-AA5)/AA5 -> 0.21204342 | AE5: =_xlfn.XLOOKUP(A5,ยอดขายเดือนที่เแล้ว!B:B,ยอดขายเดือนที่เแล้ว!D:D,0,0) -> 434835 | AF5: =AE5*100/107 -> 406387.85 | AG5: =F5 -> 479143.64 | AH5: =AG5-AF5 -> 72755.794 | AI5: =(AG5-AF5)/AF5 -> 0.17903044 | AJ5: 249517.5 | AK5: 282015.5 | AO5: =AK5-AJ5 -> 32498 | AP5: =(AK5-AJ5)/AJ5 -> 0.13024337 | AS5: =A5 -> Yuedpao สาขา SIAM SQUARE | AT5: =C5 -> 1100000 | AU5: =F5 -> 479143.64 | AV5: =AU5/$D$35 -> 39928.637 | AW5: =(AV5*$E$35)+AU5 -> 1237787.7 | AX5: =AW5/AT5 -> 1.1252616 | AY5: =(AV5*50%)+AV5 -> 59892.956 | AZ5: =(AY5*$E$35)+AU5 -> 1617109.8 | BA5: =AZ5/AT5 -> 1.4700998
A6: Yuedpao สาขา Central ระยอง | B6: =(C6*7)/100+C6 -> 1765500 | C6: =_xlfn.XLOOKUP(A6,'Target ปี 2026'!B:B,'Target ปี 2026'!C:C,0,0) -> 1650000 | D6: =C6/30 -> 55000 | E6: =_xlfn.XLOOKUP(A6,ยอดขายปัจจุบัน!B:B,ยอดขายปัจจุบัน!D:D,0,0) -> 679423 | F6: =E6*100/107 -> 634974.77 | G6: =_xlfn.XLOOKUP(A6,ยอดขายปัจจุบัน!B:B,ยอดขายปัจจุบัน!C:C,0,0) -> 1298 | H6: =E6/G6 -> 523.43837 | I6: 450 | J6: =(H6-I6)/H6 -> 0.14029993 | K6: =(E6-C6)/$E$35 -> -51083 | L6: =F6/C6 -> 0.38483319 | N6: =C6-F6 -> 1015025.2 | O6: =N6/$E$35 -> 53422.381 | P6: =SUM(N6/$E$35) -> 53422.381 | Q6: =E6/$D$35 -> 56618.583 | R6: =Q6*22 -> 1245608.8 | S6: =R6/C6 -> 0.75491444 | T6: =(C6-F6)*110% -> 1116527.8 | U6: =T6/$E$35 -> 58764.619 | V6: =(C6-F6)*120% -> 1218030.3 | W6: =SUM(V6/$E$35) -> 64106.857 | X6: =E6/$E$20 -> 0.087795443 | Y6: =E6/$H$35 -> #DIV/0! | Z6: =_xlfn.XLOOKUP(A6,ยอดขายปีที่แล้ว!B:B,ยอดขายปีที่แล้ว!D:D,0,0) -> 520592 | AA6: =Z6*100/107 -> 486534.58 | AB6: =F6 -> 634974.77 | AC6: =AB6-AA6 -> 148440.19 | AD6: =(AB6-AA6)/AA6 -> 0.30509689 | AE6: =_xlfn.XLOOKUP(A6,ยอดขายเดือนที่เแล้ว!B:B,ยอดขายเดือนที่เแล้ว!D:D,0,0) -> 585231 | AF6: =AE6*100/107 -> 546944.86 | AG6: =F6 -> 634974.77 | AH6: =AG6-AF6 -> 88029.907 | AI6: =(AG6-AF6)/AF6 -> 0.16094841 | AJ6: 344415.18 | AK6: 372682 | AO6: =AK6-AJ6 -> 28266.82 | AP6: =(AK6-AJ6)/AJ6 -> 0.082071934 | AS6: =A6 -> Yuedpao สาขา Central ระยอง | AT6: =C6 -> 1650000 | AU6: =F6 -> 634974.77 | AV6: =AU6/$D$35 -> 52914.564 | AW6: =(AV6*$E$35)+AU6 -> 1640351.5 | AX6: =AW6/AT6 -> 0.99415241 | AY6: =(AV6*50%)+AV6 -> 79371.846 | AZ6: =(AY6*$E$35)+AU6 -> 2143039.8 | BA6: =AZ6/AT6 -> 1.298812
A7: Yuedpao สาขา Central โคราช | B7: =(C7*7)/100+C7 -> 765050 | C7: =_xlfn.XLOOKUP(A7,'Target ปี 2026'!B:B,'Target ปี 2026'!C:C,0,0) -> 715000 | D7: =C7/30 -> 23833.333 | E7: =_xlfn.XLOOKUP(A7,ยอดขายปัจจุบัน!B:B,ยอดขายปัจจุบัน!D:D,0,0) -> 293642 | F7: =E7*100/107 -> 274431.78 | G7: =_xlfn.XLOOKUP(A7,ยอดขายปัจจุบัน!B:B,ยอดขายปัจจุบัน!C:C,0,0) -> 668 | H7: =E7/G7 -> 439.58383 | I7: 450 | J7: =(H7-I7)/H7 -> -0.02369552 | K7: =(E7-C7)/$E$35 -> -22176.737 | L7: =F7/C7 -> 0.38382067 | N7: =C7-F7 -> 440568.22 | O7: =N7/$E$35 -> 23187.801 | P7: =SUM(N7/$E$35) -> 23187.801 | Q7: =E7/$D$35 -> 24470.167 | R7: =Q7*22 -> 538343.67 | S7: =R7/C7 -> 0.75292821 | T7: =(C7-F7)*110% -> 484625.05 | U7: =T7/$E$35 -> 25506.581 | V7: =(C7-F7)*120% -> 528681.87 | W7: =SUM(V7/$E$35) -> 27825.362 | X7: =E7/$E$20 -> 0.037944593 | Y7: =E7/$H$35 -> #DIV/0! | Z7: =_xlfn.XLOOKUP(A7,ยอดขายปีที่แล้ว!B:B,ยอดขายปีที่แล้ว!D:D,0,0) -> 182474 | AA7: =Z7*100/107 -> 170536.45 | AB7: =F7 -> 274431.78 | AC7: =AB7-AA7 -> 103895.33 | AD7: =(AB7-AA7)/AA7 -> 0.60922652 | AE7: =_xlfn.XLOOKUP(A7,ยอดขายเดือนที่เแล้ว!B:B,ยอดขายเดือนที่เแล้ว!D:D,0,0) -> 263241 | AF7: =AE7*100/107 -> 246019.63 | AG7: =F7 -> 274431.78 | AH7: =AG7-AF7 -> 28412.15 | AI7: =(AG7-AF7)/AF7 -> 0.11548733 | AJ7: 156645 | AK7: 162014 | AO7: =AK7-AJ7 -> 5369 | AP7: =(AK7-AJ7)/AJ7 -> 0.034274953 | AS7: =A7 -> Yuedpao สาขา Central โคราช | AT7: =C7 -> 715000 | AU7: =F7 -> 274431.78 | AV7: =AU7/$D$35 -> 22869.315 | AW7: =(AV7*$E$35)+AU7 -> 708948.75 | AX7: =AW7/AT7 -> 0.99153672 | AY7: =(AV7*50%)+AV7 -> 34303.972 | AZ7: =(AY7*$E$35)+AU7 -> 926207.24 | BA7: =AZ7/AT7 -> 1.2953947
A8: Yuedpao สาขา Robinson บุรีรัมย์ | B8: =(C8*7)/100+C8 -> 823900 | C8: =_xlfn.XLOOKUP(A8,'Target ปี 2026'!B:B,'Target ปี 2026'!C:C,0,0) -> 770000 | D8: =C8/30 -> 25666.667 | E8: =_xlfn.XLOOKUP(A8,ยอดขายปัจจุบัน!B:B,ยอดขายปัจจุบัน!D:D,0,0) -> 366269 | F8: =E8*100/107 -> 342307.48 | G8: =_xlfn.XLOOKUP(A8,ยอดขายปัจจุบัน!B:B,ยอดขายปัจจุบัน!C:C,0,0) -> 749 | H8: =E8/G8 -> 489.01068 | I8: 330 | J8: =(H8-I8)/H8 -> 0.32516811 | K8: =(E8-C8)/$E$35 -> -21249 | L8: =F8/C8 -> 0.44455516 | N8: =C8-F8 -> 427692.52 | O8: =N8/$E$35 -> 22510.133 | P8: =SUM(N8/$E$35) -> 22510.133 | Q8: =E8/$D$35 -> 30522.417 | R8: =Q8*22 -> 671493.17 | S8: =R8/C8 -> 0.87206905 | T8: =(C8-F8)*110% -> 470461.78 | U8: =T8/$E$35 -> 24761.146 | V8: =(C8-F8)*120% -> 513231.03 | W8: =SUM(V8/$E$35) -> 27012.159 | X8: =E8/$E$20 -> 0.047329497 | Y8: =E8/$H$35 -> #DIV/0! | Z8: =_xlfn.XLOOKUP(A8,ยอดขายปีที่แล้ว!B:B,ยอดขายปีที่แล้ว!D:D,0,0) -> 215765 | AA8: =Z8*100/107 -> 201649.53 | AB8: =F8 -> 342307.48 | AC8: =AB8-AA8 -> 140657.94 | AD8: =(AB8-AA8)/AA8 -> 0.69753667 | AE8: =_xlfn.XLOOKUP(A8,ยอดขายเดือนที่เแล้ว!B:B,ยอดขายเดือนที่เแล้ว!D:D,0,0) -> 264972.5 | AF8: =AE8*100/107 -> 247637.85 | AG8: =F8 -> 342307.48 | AH8: =AG8-AF8 -> 94669.626 | AI8: =(AG8-AF8)/AF8 -> 0.38229062 | AJ8: 151774 | AK8: 188491 | AO8: =AK8-AJ8 -> 36717 | AP8: =(AK8-AJ8)/AJ8 -> 0.24191891 | AS8: =A8 -> Yuedpao สาขา Robinson บุรีรัมย์ | AT8: =C8 -> 770000 | AU8: =F8 -> 342307.48 | AV8: =AU8/$D$35 -> 28525.623 | AW8: =(AV8*$E$35)+AU8 -> 884294.31 | AX8: =AW8/AT8 -> 1.1484342 | AY8: =(AV8*50%)+AV8 -> 42788.435 | AZ8: =(AY8*$E$35)+AU8 -> 1155287.7 | BA8: =AZ8/AT8 -> 1.5003737
A9: Yuedpao สาขา MAYA เชียงใหม่ | B9: =(C9*7)/100+C9 -> 1647800 | C9: =_xlfn.XLOOKUP(A9,'Target ปี 2026'!B:B,'Target ปี 2026'!C:C,0,0) -> 1540000 | D9: =C9/30 -> 51333.333 | E9: =_xlfn.XLOOKUP(A9,ยอดขายปัจจุบัน!B:B,ยอดขายปัจจุบัน!D:D,0,0) -> 608567 | F9: =E9*100/107 -> 568754.21 | G9: =_xlfn.XLOOKUP(A9,ยอดขายปัจจุบัน!B:B,ยอดขายปัจจุบัน!C:C,0,0) -> 1439 | H9: =E9/G9 -> 422.90966 | I9: 450 | J9: =(H9-I9)/H9 -> -0.064057039 | K9: =(E9-C9)/$E$35 -> -49022.789 | L9: =F9/C9 -> 0.36932091 | N9: =C9-F9 -> 971245.79 | O9: =N9/$E$35 -> 51118.2 | P9: =SUM(N9/$E$35) -> 51118.2 | Q9: =E9/$D$35 -> 50713.917 | R9: =Q9*22 -> 1115706.2 | S9: =R9/C9 -> 0.72448452 | T9: =(C9-F9)*110% -> 1068370.4 | U9: =T9/$E$35 -> 56230.02 | V9: =(C9-F9)*120% -> 1165495 | W9: =SUM(V9/$E$35) -> 61341.84 | X9: =E9/$E$20 -> 0.078639389 | Y9: =E9/$H$35 -> #DIV/0! | Z9: =_xlfn.XLOOKUP(A9,ยอดขายปีที่แล้ว!B:B,ยอดขายปีที่แล้ว!D:D,0,0) -> 413123 | AA9: =Z9*100/107 -> 386096.26 | AB9: =F9 -> 568754.21 | AC9: =AB9-AA9 -> 182657.94 | AD9: =(AB9-AA9)/AA9 -> 0.47308913 | AE9: =_xlfn.XLOOKUP(A9,ยอดขายเดือนที่เแล้ว!B:B,ยอดขายเดือนที่เแล้ว!D:D,0,0) -> 528753.3 | AF9: =AE9*100/107 -> 494161.96 | AG9: =F9 -> 568754.21 | AH9: =AG9-AF9 -> 74592.243 | AI9: =(AG9-AF9)/AF9 -> 0.15094695 | AJ9: 320292 | AK9: 315293 | AO9: =AK9-AJ9 -> -4999 | AP9: =(AK9-AJ9)/AJ9 -> -0.015607633 | AS9: =A9 -> Yuedpao สาขา MAYA เชียงใหม่ | AT9: =C9 -> 1540000 | AU9: =F9 -> 568754.21 | AV9: =AU9/$D$35 -> 47396.184 | AW9: =(AV9*$E$35)+AU9 -> 1469281.7 | AX9: =AW9/AT9 -> 0.95407902 | AY9: =(AV9*50%)+AV9 -> 71094.276 | AZ9: =(AY9*$E$35)+AU9 -> 1919545.4 | BA9: =AZ9/AT9 -> 1.2464581
A10: Exchange Store | AS10: Exchange Store
A11: Yuedpao สาขา Future Park Rangsit ชั้น 3 | B11: =(C11*7)/100+C11 -> 2824800 | C11: =_xlfn.XLOOKUP(A11,'Target ปี 2026'!B:B,'Target ปี 2026'!C:C,0,0) -> 2640000 | D11: =C11/30 -> 88000 | E11: =_xlfn.XLOOKUP(A11,ยอดขายปัจจุบัน!B:B,ยอดขายปัจจุบัน!D:D,0,0) -> 1165653 | F11: =E11*100/107 -> 1089395.3 | G11: =_xlfn.XLOOKUP(A11,ยอดขายปัจจุบัน!B:B,ยอดขายปัจจุบัน!C:C,0,0) -> 2315 | H11: =E11/G11 -> 503.52181 | I11: 400 | J11: =(H11-I11)/H11 -> 0.20559549 | K11: =(E11-C11)/$E$35 -> -77597.211 | L11: =F11/C11 -> 0.41264975 | N11: =C11-F11 -> 1550604.7 | O11: =N11/$E$35 -> 81610.772 | P11: =SUM(N11/$E$35) -> 81610.772 | Q11: =E11/$D$35 -> 97137.75 | R11: =Q11*22 -> 2137030.5 | S11: =R11/C11 -> 0.80948125 | T11: =(C11-F11)*110% -> 1705665.1 | U11: =T11/$E$35 -> 89771.849 | V11: =(C11-F11)*120% -> 1860725.6 | W11: =SUM(V11/$E$35) -> 97932.927 | X11: =E11/$E$20 -> 0.15062637 | Y11: =E11/$H$35 -> #DIV/0! | Z11: =_xlfn.XLOOKUP(A11,ยอดขายปีที่แล้ว!B:B,ยอดขายปีที่แล้ว!D:D,0,0) -> 910304 | AA11: =Z11*100/107 -> 850751.4 | AB11: =F11 -> 1089395.3 | AC11: =AB11-AA11 -> 238643.93 | AD11: =(AB11-AA11)/AA11 -> 0.28050959 | AE11: =_xlfn.XLOOKUP(A11,ยอดขายเดือนที่เแล้ว!B:B,ยอดขายเดือนที่เแล้ว!D:D,0,0) -> 927365 | AF11: =AE11*100/107 -> 866696.26 | AG11: =F11 -> 1089395.3 | AH11: =AG11-AF11 -> 222699.07 | AI11: =(AG11-AF11)/AF11 -> 0.25695169 | AJ11: 571608 | AK11: 623851 | AO11: =AK11-AJ11 -> 52243 | AP11: =(AK11-AJ11)/AJ11 -> 0.091396551 | AQ11: REROCATE 16 DEC 2025 | AS11: =A11 -> Yuedpao สาขา Future Park Rangsit ชั้น 3 | AT11: =C11 -> 2640000 | AU11: =F11 -> 1089395.3 | AV11: =AU11/$D$35 -> 90782.944 | AW11: =(AV11*$E$35)+AU11 -> 2814271.3 | AX11: =AW11/AT11 -> 1.0660118 | AY11: =(AV11*50%)+AV11 -> 136174.42 | AZ11: =(AY11*$E$35)+AU11 -> 3676709.2 | BA11: =AZ11/AT11 -> 1.3926929
A12: Yuedpao สาขา Central พัทยา | B12: =(C12*7)/100+C12 -> 1059300 | C12: =_xlfn.XLOOKUP(A12,'Target ปี 2026'!B:B,'Target ปี 2026'!C:C,0,0) -> 990000 | D12: =C12/30 -> 33000 | E12: =_xlfn.XLOOKUP(A12,ยอดขายปัจจุบัน!B:B,ยอดขายปัจจุบัน!D:D,0,0) -> 389084.3 | F12: =E12*100/107 -> 363630.19 | G12: =_xlfn.XLOOKUP(A12,ยอดขายปัจจุบัน!B:B,ยอดขายปัจจุบัน!C:C,0,0) -> 718 | H12: =E12/G12 -> 541.90014 | I12: 401 | J12: =(H12-I12)/H12 -> 0.26001126 | K12: =(E12-C12)/$E$35 -> -31627.142 | L12: =F12/C12 -> 0.36730322 | N12: =C12-F12 -> 626369.81 | O12: =N12/$E$35 -> 32966.832 | P12: =SUM(N12/$E$35) -> 32966.832 | Q12: =E12/$D$35 -> 32423.692 | R12: =Q12*22 -> 713321.22 | S12: =R12/C12 -> 0.72052648 | T12: =(C12-F12)*110% -> 689006.79 | U12: =T12/$E$35 -> 36263.515 | V12: =(C12-F12)*120% -> 751643.78 | W12: =SUM(V12/$E$35) -> 39560.199 | X12: =E12/$E$20 -> 0.050277704 | Y12: =E12/$H$35 -> #DIV/0! | Z12: =_xlfn.XLOOKUP(A12,ยอดขายปีที่แล้ว!B:B,ยอดขายปีที่แล้ว!D:D,0,0) -> 298610 | AA12: =Z12*100/107 -> 279074.77 | AB12: =F12 -> 363630.19 | AC12: =AB12-AA12 -> 84555.421 | AD12: =(AB12-AA12)/AA12 -> 0.30298483 | AE12: =_xlfn.XLOOKUP(A12,ยอดขายเดือนที่เแล้ว!B:B,ยอดขายเดือนที่เแล้ว!D:D,0,0) -> 315310 | AF12: =AE12*100/107 -> 294682.24 | AG12: =F12 -> 363630.19 | AH12: =AG12-AF12 -> 68947.944 | AI12: =(AG12-AF12)/AF12 -> 0.23397387 | AJ12: 191844 | AK12: 209694 | AO12: =AK12-AJ12 -> 17850 | AP12: =(AK12-AJ12)/AJ12 -> 0.093044349 | AQ12: REROCATE 05 FEB 2024 | AS12: =A12 -> Yuedpao สาขา Central พัทยา | AT12: =C12 -> 990000 | AU12: =F12 -> 363630.19 | AV12: =AU12/$D$35 -> 30302.516 | AW12: =(AV12*$E$35)+AU12 -> 939377.98 | AX12: =AW12/AT12 -> 0.94886665 | AY12: =(AV12*50%)+AV12 -> 45453.773 | AZ12: =(AY12*$E$35)+AU12 -> 1227251.9 | BA12: =AZ12/AT12 -> 1.2396484
A13: Yuedpao สาขา Central ปิ่นเกล้า | B13: =(C13*7)/100+C13 -> 2236300 | C13: =_xlfn.XLOOKUP(A13,'Target ปี 2026'!B:B,'Target ปี 2026'!C:C,0,0) -> 2090000 | D13: =C13/30 -> 69666.667 | E13: =_xlfn.XLOOKUP(A13,ยอดขายปัจจุบัน!B:B,ยอดขายปัจจุบัน!D:D,0,0) -> 933072.5 | F13: =E13*100/107 -> 872030.37 | G13: =_xlfn.XLOOKUP(A13,ยอดขายปัจจุบัน!B:B,ยอดขายปัจจุบัน!C:C,0,0) -> 1970 | H13: =E13/G13 -> 473.64086 | I13: 450 | J13: =(H13-I13)/H13 -> 0.049913056 | K13: =(E13-C13)/$E$35 -> -60890.921 | L13: =F13/C13 -> 0.41723941 | N13: =C13-F13 -> 1217969.6 | O13: =N13/$E$35 -> 64103.665 | P13: =SUM(N13/$E$35) -> 64103.665 | Q13: =E13/$D$35 -> 77756.042 | R13: =Q13*22 -> 1710632.9 | S13: =R13/C13 -> 0.81848465 | T13: =(C13-F13)*110% -> 1339766.6 | U13: =T13/$E$35 -> 70514.031 | V13: =(C13-F13)*120% -> 1461563.6 | W13: =SUM(V13/$E$35) -> 76924.397 | X13: =E13/$E$20 -> 0.12057218 | Y13: =E13/$H$35 -> #DIV/0! | Z13: =_xlfn.XLOOKUP(A13,ยอดขายปีที่แล้ว!B:B,ยอดขายปีที่แล้ว!D:D,0,0) -> 394333 | AA13: =Z13*100/107 -> 368535.51 | AB13: =F13 -> 872030.37 | AC13: =AB13-AA13 -> 503494.86 | AD13: =(AB13-AA13)/AA13 -> 1.3662045 | AE13: =_xlfn.XLOOKUP(A13,ยอดขายเดือนที่เแล้ว!B:B,ยอดขายเดือนที่เแล้ว!D:D,0,0) -> 744628 | AF13: =AE13*100/107 -> 695914.02 | AG13: =F13 -> 872030.37 | AH13: =AG13-AF13 -> 176116.36 | AI13: =(AG13-AF13)/AF13 -> 0.253072 | AJ13: 425156 | AK13: 450960.5 | AO13: =AK13-AJ13 -> 25804.5 | AP13: =(AK13-AJ13)/AJ13 -> 0.060694192 | AQ13: REROCATE 01 DEC 2024 | AS13: =A13 -> Yuedpao สาขา Central ปิ่นเกล้า | AT13: =C13 -> 2090000 | AU13: =F13 -> 872030.37 | AV13: =AU13/$D$35 -> 72669.198 | AW13: =(AV13*$E$35)+AU13 -> 2252745.1 | AX13: =AW13/AT13 -> 1.0778685 | AY13: =(AV13*50%)+AV13 -> 109003.8 | AZ13: =(AY13*$E$35)+AU13 -> 2943102.5 | BA13: =AZ13/AT13 -> 1.408183
A14: Yuedpao สาขา I am China Town | B14: =(C14*7)/100+C14 -> 470800 | C14: =_xlfn.XLOOKUP(A14,'Target ปี 2026'!B:B,'Target ปี 2026'!C:C,0,0) -> 440000 | D14: =C14/30 -> 14666.667 | E14: =_xlfn.XLOOKUP(A14,ยอดขายปัจจุบัน!B:B,ยอดขายปัจจุบัน!D:D,0,0) -> 131864 | F14: =E14*100/107 -> 123237.38 | G14: =_xlfn.XLOOKUP(A14,ยอดขายปัจจุบัน!B:B,ยอดขายปัจจุบัน!C:C,0,0) -> 287 | H14: =E14/G14 -> 459.45645 | I14: 430 | J14: =(H14-I14)/H14 -> 0.064111509 | K14: =(E14-C14)/$E$35 -> -16217.684 | L14: =F14/C14 -> 0.28008496 | N14: =C14-F14 -> 316762.62 | O14: =N14/$E$35 -> 16671.717 | P14: =SUM(N14/$E$35) -> 16671.717 | Q14: =E14/$D$35 -> 10988.667 | R14: =Q14*22 -> 241750.67 | S14: =R14/C14 -> 0.54943333 | T14: =(C14-F14)*110% -> 348438.88 | U14: =T14/$E$35 -> 18338.888 | V14: =(C14-F14)*120% -> 380115.14 | W14: =SUM(V14/$E$35) -> 20006.06 | X14: =E14/$E$20 -> 0.017039544 | Y14: =E14/$H$35 -> #DIV/0! | Z14: =_xlfn.XLOOKUP(A14,ยอดขายปีที่แล้ว!B:B,ยอดขายปีที่แล้ว!D:D,0,0) -> 0 | AA14: =Z14*100/107 -> 0 | AB14: =F14 -> 123237.38 | AC14: =AB14-AA14 -> 123237.38 | AD14: =(AB14-AA14)/AA14 -> #DIV/0! | AE14: =_xlfn.XLOOKUP(A14,ยอดขายเดือนที่เแล้ว!B:B,ยอดขายเดือนที่เแล้ว!D:D,0,0) -> 151402 | AF14: =AE14*100/107 -> 141497.2 | AG14: =F14 -> 123237.38 | AH14: =AG14-AF14 -> -18259.813 | AI14: =(AG14-AF14)/AF14 -> -0.12904717 | AJ14: 67841 | AK14: 79507 | AO14: =AK14-AJ14 -> 11666 | AP14: =(AK14-AJ14)/AJ14 -> 0.17196091 | AQ14: OPEN 01 JUN 2024 | AS14: =A14 -> Yuedpao สาขา I am China Town | AT14: =C14 -> 440000 | AU14: =F14 -> 123237.38 | AV14: =AU14/$D$35 -> 10269.782 | AW14: =(AV14*$E$35)+AU14 -> 318363.24 | AX14: =AW14/AT14 -> 0.72355282 | AY14: =(AV14*50%)+AV14 -> 15404.673 | AZ14: =(AY14*$E$35)+AU14 -> 415926.17 | BA14: =AZ14/AT14 -> 0.94528675
A15: Yuedpao สาขา Robinson ชลบุรี | B15: =(C15*7)/100+C15 -> 1177000 | C15: =_xlfn.XLOOKUP(A15,'Target ปี 2026'!B:B,'Target ปี 2026'!C:C,0,0) -> 1100000 | D15: =C15/30 -> 36666.667 | E15: =_xlfn.XLOOKUP(A15,ยอดขายปัจจุบัน!B:B,ยอดขายปัจจุบัน!D:D,0,0) -> 553114.61 | F15: =E15*100/107 -> 516929.54 | G15: =_xlfn.XLOOKUP(A15,ยอดขายปัจจุบัน!B:B,ยอดขายปัจจุบัน!C:C,0,0) -> 1272 | H15: =E15/G15 -> 434.83853 | I15: 430 | J15: =(H15-I15)/H15 -> 0.011127188 | K15: =(E15-C15)/$E$35 -> -28783.442 | L15: =F15/C15 -> 0.46993595 | N15: =C15-F15 -> 583070.46 | O15: =N15/$E$35 -> 30687.919 | P15: =SUM(N15/$E$35) -> 30687.919 | Q15: =E15/$D$35 -> 46092.884 | R15: =Q15*22 -> 1014043.5 | S15: =R15/C15 -> 0.92185768 | T15: =(C15-F15)*110% -> 641377.5 | U15: =T15/$E$35 -> 33756.711 | V15: =(C15-F15)*120% -> 699684.55 | W15: =SUM(V15/$E$35) -> 36825.503 | X15: =E15/$E$20 -> 0.071473798 | Y15: =E15/$H$35 -> #DIV/0! | Z15: =_xlfn.XLOOKUP(A15,ยอดขายปีที่แล้ว!B:B,ยอดขายปีที่แล้ว!D:D,0,0) -> 0 | AA15: =Z15*100/107 -> 0 | AB15: =F15 -> 516929.54 | AC15: =AB15-AA15 -> 516929.54 | AD15: =(AB15-AA15)/AA15 -> #DIV/0! | AE15: =_xlfn.XLOOKUP(A15,ยอดขายเดือนที่เแล้ว!B:B,ยอดขายเดือนที่เแล้ว!D:D,0,0) -> 411312 | AF15: =AE15*100/107 -> 384403.74 | AG15: =F15 -> 516929.54 | AH15: =AG15-AF15 -> 132525.8 | AI15: =(AG15-AF15)/AF15 -> 0.3447568 | AJ15: 264448 | AK15: 304246.61 | AO15: =AK15-AJ15 -> 39798.61 | AP15: =(AK15-AJ15)/AJ15 -> 0.15049692 | AQ15: OPEN 01 AUN 2024 | AS15: =A15 -> Yuedpao สาขา Robinson ชลบุรี | AT15: =C15 -> 1100000 | AU15: =F15 -> 516929.54 | AV15: =AU15/$D$35 -> 43077.462 | AW15: =(AV15*$E$35)+AU15 -> 1335401.3 | AX15: =AW15/AT15 -> 1.2140012 | AY15: =(AV15*50%)+AV15 -> 64616.193 | AZ15: =(AY15*$E$35)+AU15 -> 1744637.2 | BA15: =AZ15/AT15 -> 1.5860338
A16: Yuedpao สาขา Big C อำนาจเจริญ | B16: =(C16*7)/100+C16 -> 588500 | C16: =_xlfn.XLOOKUP(A16,'Target ปี 2026'!B:B,'Target ปี 2026'!C:C,0,0) -> 550000 | D16: =C16/30 -> 18333.333 | E16: =_xlfn.XLOOKUP(A16,ยอดขายปัจจุบัน!B:B,ยอดขายปัจจุบัน!D:D,0,0) -> 220050 | F16: =E16*100/107 -> 205654.21 | G16: =_xlfn.XLOOKUP(A16,ยอดขายปัจจุบัน!B:B,ยอดขายปัจจุบัน!C:C,0,0) -> 433 | H16: =E16/G16 -> 508.19861 | I16: 431 | J16: =(H16-I16)/H16 -> 0.15190638 | K16: =(E16-C16)/$E$35 -> -17365.789 | L16: =F16/C16 -> 0.37391674 | N16: =C16-F16 -> 344345.79 | O16: =N16/$E$35 -> 18123.463 | P16: =SUM(N16/$E$35) -> 18123.463 | Q16: =E16/$D$35 -> 18337.5 | R16: =Q16*22 -> 403425 | S16: =R16/C16 -> 0.7335 | T16: =(C16-F16)*110% -> 378780.37 | U16: =T16/$E$35 -> 19935.809 | V16: =(C16-F16)*120% -> 413214.95 | W16: =SUM(V16/$E$35) -> 21748.155 | X16: =E16/$E$20 -> 0.028434992 | Y16: =E16/$H$35 -> #DIV/0! | Z16: =_xlfn.XLOOKUP(A16,ยอดขายปีที่แล้ว!B:B,ยอดขายปีที่แล้ว!D:D,0,0) -> 0 | AA16: =Z16*100/107 -> 0 | AB16: =F16 -> 205654.21 | AC16: =AB16-AA16 -> 205654.21 | AD16: =(AB16-AA16)/AA16 -> #DIV/0! | AE16: =_xlfn.XLOOKUP(A16,ยอดขายเดือนที่เแล้ว!B:B,ยอดขายเดือนที่เแล้ว!D:D,0,0) -> 141136 | AF16: =AE16*100/107 -> 131902.8 | AG16: =F16 -> 205654.21 | AH16: =AG16-AF16 -> 73751.402 | AI16: =(AG16-AF16)/AF16 -> 0.55913445 | AJ16: 88927 | AK16: 105013 | AO16: =AK16-AJ16 -> 16086 | AP16: =(AK16-AJ16)/AJ16 -> 0.18088994 | AQ16: OPEN 15 NOV 2024 | AS16: =A16 -> Yuedpao สาขา Big C อำนาจเจริญ | AT16: =C16 -> 550000 | AU16: =F16 -> 205654.21 | AV16: =AU16/$D$35 -> 17137.85 | AW16: =(AV16*$E$35)+AU16 -> 531273.36 | AX16: =AW16/AT16 -> 0.96595157 | AY16: =(AV16*50%)+AV16 -> 25706.776 | AZ16: =(AY16*$E$35)+AU16 -> 694082.94 | BA16: =AZ16/AT16 -> 1.261969
A17: Yuedpao สาขา Robinson แม่สอด | B17: =(C17*7)/100+C17 -> 1118150 | C17: =_xlfn.XLOOKUP(A17,'Target ปี 2026'!B:B,'Target ปี 2026'!C:C,0,0) -> 1045000 | D17: =C17/30 -> 34833.333 | E17: =_xlfn.XLOOKUP(A17,ยอดขายปัจจุบัน!B:B,ยอดขายปัจจุบัน!D:D,0,0) -> 465863 | F17: =E17*100/107 -> 435385.98 | G17: =_xlfn.XLOOKUP(A17,ยอดขายปัจจุบัน!B:B,ยอดขายปัจจุบัน!C:C,0,0) -> 930 | H17: =E17/G17 -> 500.92796 | I17: 432 | J17: =(H17-I17)/H17 -> 0.13760054 | K17: =(E17-C17)/$E$35 -> -30480.895 | L17: =F17/C17 -> 0.4166373 | N17: =C17-F17 -> 609614.02 | O17: =N17/$E$35 -> 32084.948 | P17: =SUM(N17/$E$35) -> 32084.948 | Q17: =E17/$D$35 -> 38821.917 | R17: =Q17*22 -> 854082.17 | S17: =R17/C17 -> 0.81730351 | T17: =(C17-F17)*110% -> 670575.42 | U17: =T17/$E$35 -> 35293.443 | V17: =(C17-F17)*120% -> 731536.82 | W17: =SUM(V17/$E$35) -> 38501.938 | X17: =E17/$E$20 -> 0.060199093 | Y17: =E17/$H$35 -> #DIV/0! | Z17: =_xlfn.XLOOKUP(A17,ยอดขายปีที่แล้ว!B:B,ยอดขายปีที่แล้ว!D:D,0,0) -> 0 | AA17: =Z17*100/107 -> 0 | AB17: =F17 -> 435385.98 | AC17: =AB17-AA17 -> 435385.98 | AD17: =(AB17-AA17)/AA17 -> #DIV/0! | AE17: =_xlfn.XLOOKUP(A17,ยอดขายเดือนที่เแล้ว!B:B,ยอดขายเดือนที่เแล้ว!D:D,0,0) -> 398842 | AF17: =AE17*100/107 -> 372749.53 | AG17: =F17 -> 435385.98 | AH17: =AG17-AF17 -> 62636.449 | AI17: =(AG17-AF17)/AF17 -> 0.16803897 | AJ17: 229403 | AK17: 240917 | AO17: =AK17-AJ17 -> 11514 | AP17: =(AK17-AJ17)/AJ17 -> 0.050191148 | AQ17: OPEN 01 NOV 2024 | AS17: =A17 -> Yuedpao สาขา Robinson แม่สอด | AT17: =C17 -> 1045000 | AU17: =F17 -> 435385.98 | AV17: =AU17/$D$35 -> 36282.165 | AW17: =(AV17*$E$35)+AU17 -> 1124747.1 | AX17: =AW17/AT17 -> 1.076313 | AY17: =(AV17*50%)+AV17 -> 54423.248 | AZ17: =(AY17*$E$35)+AU17 -> 1469427.7 | BA17: =AZ17/AT17 -> 1.4061509
A18: Yuedpao สาขา Sermthai Complex มหาสารคาม | B18: =(C18*7)/100+C18 -> 1000450 | C18: =_xlfn.XLOOKUP(A18,'Target ปี 2026'!B:B,'Target ปี 2026'!C:C,0,0) -> 935000 | D18: =C18/30 -> 31166.667 | E18: =_xlfn.XLOOKUP(A18,ยอดขายปัจจุบัน!B:B,ยอดขายปัจจุบัน!D:D,0,0) -> 406854 | F18: =E18*100/107 -> 380237.38 | G18: =_xlfn.XLOOKUP(A18,ยอดขายปัจจุบัน!B:B,ยอดขายปัจจุบัน!C:C,0,0) -> 889 | H18: =E18/G18 -> 457.65354 | I18: 433 | J18: =(H18-I18)/H18 -> 0.053869447 | K18: =(E18-C18)/$E$35 -> -27797.158 | L18: =F18/C18 -> 0.406671 | N18: =C18-F18 -> 554762.62 | O18: =N18/$E$35 -> 29198.032 | P18: =SUM(N18/$E$35) -> 29198.032 | Q18: =E18/$D$35 -> 33904.5 | R18: =Q18*22 -> 745899 | S18: =R18/C18 -> 0.79775294 | T18: =(C18-F18)*110% -> 610238.88 | U18: =T18/$E$35 -> 32117.836 | V18: =(C18-F18)*120% -> 665715.14 | W18: =SUM(V18/$E$35) -> 35037.639 | X18: =E18/$E$20 -> 0.052573915 | Y18: =E18/$H$35 -> #DIV/0! | Z18: =_xlfn.XLOOKUP(A18,ยอดขายปีที่แล้ว!B:B,ยอดขายปีที่แล้ว!D:D,0,0) -> 0 | AA18: =Z18*100/107 -> 0 | AB18: =F18 -> 380237.38 | AC18: =AB18-AA18 -> 380237.38 | AD18: =(AB18-AA18)/AA18 -> #DIV/0! | AE18: =_xlfn.XLOOKUP(A18,ยอดขายเดือนที่เแล้ว!B:B,ยอดขายเดือนที่เแล้ว!D:D,0,0) -> 313511 | AF18: =AE18*100/107 -> 293000.93 | AG18: =F18 -> 380237.38 | AH18: =AG18-AF18 -> 87236.449 | AI18: =(AG18-AF18)/AF18 -> 0.29773437 | AJ18: 203008 | AK18: 212591 | AO18: =AK18-AJ18 -> 9583 | AP18: =(AK18-AJ18)/AJ18 -> 0.047205036 | AQ18: OPEN 20 DEC 2024 | AS18: =A18 -> Yuedpao สาขา Sermthai Complex มหาสารคาม | AT18: =C18 -> 935000 | AU18: =F18 -> 380237.38 | AV18: =AU18/$D$35 -> 31686.449 | AW18: =(AV18*$E$35)+AU18 -> 982279.91 | AX18: =AW18/AT18 -> 1.0505667 | AY18: =(AV18*50%)+AV18 -> 47529.673 | AZ18: =(AY18*$E$35)+AU18 -> 1283301.2 | BA18: =AZ18/AT18 -> 1.3725146
A19: TOTAL SAME STORE | C19: =SUM(C3:C18) -> 17875000 | D19: =SUM(D3:D18) -> 595833.33 | E19: =SUM(E3:E18) -> 7738704.6 | F19: =SUM(F3:F18) -> 7232434.2 | G19: =SUM(G3:G18) -> 15927 | H19: 427 | I19: 423 | J19: =(H19-I19)/H19 -> 0.0093676815 | K19: =(E19-C19)/$E$35 -> -533489.23 | L19: =F19/C19 -> 0.4046117 | N19: =SUM(N3:N15) -> 9133843.4 | O19: =SUM(O3:O14) -> 450040.68 | P19: =SUM(N19/$E$35) -> 480728.6 | Q19: =SUM(Q3:Q9) -> 289429.1 | R19: =SUM(R3:R9) -> 6367440.2 | S19: =SUM(S3:S9) -> 5.5698725 | T19: =SUM(T3:T9) -> 5322972.8 | U19: =SUM(U3:U9) -> 280156.46 | V19: =SUM(V3:V9) -> 5806879.4 | W19: =SUM(W3:W9) -> 305625.23 | X19: =E19/$E$19 -> 1 | Y19: =SUM(Y3:Y9) -> #DIV/0! | Z19: =SUM(Z3:Z9) -> 2548457.2 | AA19: =SUM(AA3:AA9) -> 2381735.7 | AB19: =SUM(AB3:AB9) -> 3245933.8 | AC19: =AB19-AA19 -> 864198.13 | AD19: =(AB19-AA19)/AA19 -> 0.36284384 | AE19: =SUM(AE3:AE9) -> 2864389.3 | AF19: =SUM(AF3:AF9) -> 2676999.3 | AG19: =SUM(AG3:AG9) -> 3245933.8 | AH19: =AG19-AF19 -> 568934.49 | AI19: =(AG19-AF19)/AF19 -> 0.21252694 | AJ19: =SUM(AJ3:AJ9) -> 1718219.7 | AK19: =SUM(AK3:AK9) -> 1839149.5 | AL19: =SUM(AL3:AL9) -> 0 | AM19: =SUM(AM3:AM9) -> 0 | AN19: =SUM(AN3:AN9) -> 0 | AO19: =AK19-AJ19 -> 120929.82 | AP19: =(AK19-AJ19)/AJ19 -> 0.070380884 | AS19: ยอดรวม | AT19: =SUM(AT3:AT18) -> 17875000 | AU19: =SUM(AU3:AU18) -> 7232434.2 | AV19: =AU19/$D$35 -> 602702.85 | AW19: =(AV19*$E$35)+AU19 -> 18683788 | AX19: =AW19/AT19 -> 1.0452469 | AY19: =(AV19*50%)+AV19 -> 904054.28 | AZ19: =(AY19*$E$35)+AU19 -> 24409465 | BA19: =AZ19/AT19 -> 1.3655645
A20: TOTAL ALL STORE | B20: =SUM(B3:B14) -> 15242150 | C20: =SUM(C3:C18) -> 17875000 | D20: =SUM(D3:D18) -> 595833.33 | E20: =SUM(E3:E18) -> 7738704.6 | F20: =SUM(F3:F18) -> 7232434.2 | G20: =SUM(G3:G18) -> 15927 | H20: 427 | I20: 423 | J20: =(H20-I20)/H20 -> 0.0093676815 | K20: =(E20-C20)/$E$35 -> -533489.23 | L20: =F20/C20 -> 0.4046117 | N20: =SUM(N3:N15) -> 9133843.4 | O20: =N20/$E$35 -> 480728.6 | P20: =SUM(N20/$E$35) -> 480728.6 | Q20: =E20/$D$35 -> 644892.05 | R20: =Q20*22 -> 14187625 | S20: =R20/C20 -> 0.79371329 | T20: =SUM(T3:T14) -> 9405850.2 | U20: =T20/$E$35 -> 495044.75 | V20: =SUM(V3:V14) -> 10260927 | W20: =SUM(V20/$E$35) -> 540048.81 | X20: =E20/$E$20 -> 1 | Y20: =E20/H35 -> #DIV/0! | Z20: =SUM(Z2:Z19) -> 6702184.4 | AA20: =SUM(AA3:AA18) -> 3880097.4 | AB20: =SUM(AB3:AB18) -> 7232434.2 | AC20: =SUM(AC3:AC18) -> 3352336.8 | AD20: =(AB20-AA20)/AA20 -> 0.86398265 | AE20: =SUM(AE3:AE18) -> 6267895.3 | AF20: =SUM(AF3:AF18) -> 5857846.1 | AG20: =SUM(AG3:AG18) -> 7232434.2 | AH20: =SUM(AH3:AH18) -> 1374588.1 | AI20: =(AG20-AF20)/AF20 -> 0.23465761 | AJ20: =SUM(AJ3:AJ18) -> 3760454.7 | AK20: =SUM(AK3:AK18) -> 4065929.6 | AL20: =SUM(AL3:AL18) -> 0 | AM20: =SUM(AM3:AM18) -> 0 | AN20: =SUM(AN3:AN18) -> 0 | AO20: =AK20-AJ20 -> 305474.93 | AP20: =(AK20-AJ20)/AJ20 -> 0.081233509 | AW20: =(AW19*7)/100+AW19 -> 19991654
E22: =SUM(E20-C20) -> -10136295 | F22: =SUM(F20-C20) -> -10642566 | K22: ขาดอีก | L22: =SUM(L20-100%) -> -0.5953883
C25: =C20-F20 -> 10642566 | I25: =SUM(I3:I14) -> 4711 | J25: =I25/15 -> 314.06667
W27: Yuedpao สาขา Fashion Island
W28: Yuedpao สาขา SIAM SQUARE
W29: Yuedpao สาขา Central Festival เชียงใหม่
W30: Yuedpao สาขา Central อุบลราชธานี
W31: Yuedpao สาขา Central เชียงใหม่แอร์พอร์ต
W32: Yuedpao สาขา The Mall บางกะปิ
D33: แก้ไขตัวเลข | H33: แก้ไขตัวเลข | W33: Yuedpao สาขา จตุจักรโครงการ 28
D34: วันนี้ | E34: วันคงเหลือ | H34: ยอดขายรวมทั้งหมด | W34: Yuedpao สาขา Central เชียงราย
D35: 12 | E35: =31-D35 -> 19 | W35: Yuedpao สาขา จตุจักรโครงการ 22 ริมถนน
W36: Yuedpao สาขา Central รามอินทรา
W37: Yuedpao สาขา Central นครสวรรค์
W38: Yuedpao สาขา จตุจักรโครงการ 6
W39: Yuedpao สาขา BTS สยาม
W40: Yuedpao สาขา BTS หมอชิต
W41: Yuedpao สาขา Robinson บุรีรัมย์
A42: สาขา | C42: TARGET | D42: SALE OUT
A43: Yuedpao สาขา Mega บางนา | C43: =C3 -> 1210000 | D43: =E3 -> 505586.5
A44: Yuedpao สาขา The Mall โคราช | C44: =C4 -> 1100000 | D44: =E4 -> 506978
...

Sheet Target ปี 2026
A1: NO | B1: SHOP | C1: TARGET APR 2026
A2: 1 | B2: Yuedpao สาขา Central หาดใหญ่ | C2: 2970000
A3: 2 | B3: Yuedpao สาขา Future Park Rangsit (Flagship store) | C3: 2640000
A4: 3 | B4: Yuedpao สาขา Future Park Rangsit ชั้น 3 | C4: 2640000
A5: 4 | B5: Yuedpao สาขา Central ลาดพร้าว | C5: 2530000
A6: 5 | B6: Yuedpao สาขา Central เวสต์เกต | C6: 2585000
A7: 6 | B7: Yuedpao สาขา Fashion Island | C7: 2310000
A8: 7 | B8: Yuedpao สาขา Central ขอนแก่น | C8: 2090000
A9: 8 | B9: Yuedpao สาขา Central อุบลราชธานี | C9: 2090000
A10: 9 | B10: Yuedpao สาขา Central ปิ่นเกล้า | C10: 2090000
A11: 10 | B11: Yuedpao สาขา The Mall บางแค | C11: 2420000
A12: 11 | B12: Yuedpao สาขา Robinson บ่อวิน | C12: 2035000
A13: 12 | B13: Yuedpao สาขา The Mall งามวงศ์วาน | C13: 1980000
... A84: 83 | B84: Yuedpao สาขา Robinson กาญจนบุรี | C84: 1320000
B85: Yuedpao สาขา อยุธยา City Park | C85: 1210000
